Workbook
Name Angebotsnummer: Übersicht!$B$5
Name Anlage: Übersicht!$B$4
Name Auslöse: VK!$F$34
Name Bearbeiter: Übersicht!$E$5
Name Datum: Übersicht!$D$5
Name Doku: VK!$F$11
Name EKo: VK!$F$13
Name El: VK!$F$21
Name Flüge: VK!$G$37
Name Gesamtpreis: Übersicht!$Q$40
Name Gewinn: VK!$O$32
Name Hotel: VK!$F$35
Name Inb: VK!$F$15
Name KM_Pauschale: VK!$F$36
Name Kunde: Übersicht!$B$3
Name MGKZ: VK!$O$31
Name MKo: VK!$F$10
Name Mo: VK!$F$19
Name Pl: VK!$F$17
Name Projektnachlass: VK!$O$35
Name Revision: VK!$B$38
Name Sicherheit: VK!$J$36
Name SicherheitAngebot: VK!$P$33
Name Sw: VK!$F$14
Name TF: VK!$F$20
Name Verhandlungsspielraum: VK!$O$33
Name Zuschläge_IBN: VK!$F$31

Sheet Übersicht
B2: Preisübersicht | H2: Anlage detailliert | S2: Inbetriebnahme beim Kunden detailliert
B3: Dräxlmeier Satu Mare | E3: Hr. Eglseder | AV3: Projektnachlass:
B4: Automatic Production Line for Wire Processing | AV4: =Projektnachlass -> 0.11114475
B5: A07616000A | D5: 45825 | E5: Schötz/Radlbeck | G5: Arbeitszeiten im Haus | S5: Arbeitszeiten vor Ort | Z5: Reisezeiten | AG5: Auslösen, Hotel, Anfahrt, Flüge...
G6: =G8*G7 -> 0 | H6: =H8*H7 -> 244600 | I6: =I8*I7 -> 66976 | J6: =J8*J7 -> 107835 | K6: =K8*K7 -> 173985 | L6: =L8*L7 -> 84870 | M6: =M8*M7 -> 178924 | N6: =SUM(N12:N31) -> 216300 | O6: =SUM(O12,O29,O44,O61,O78,O95,O112,O129,O146,O163,O180,O197,O214,O231,O248,O265,O282,O299,O316,O333,O350,O367,O384,O401,O418,O435,O452,O469,O486,O503) -> 653510 | S6: =S8*S7 -> 4400 | T6: =T8*T7 -> 0 | U6: =U8*U7 -> 0 | V6: =V8*V7 -> 17850 | W6: =W8*W7 -> 11480 | X6: =X8*X7 -> 18040 | Z6: =Z8*Z7 -> 1760 | AA6: =AA8*AA7 -> 0 | AB6: =AB8*AB7 -> 0 | AC6: =AC8*AC7 -> 2520 | AD6: =AD8*AD7 -> 2624 | AE6: =AE8*AE7 -> 3936 | AG6: =AG8*AG7 -> 4212 | AH6: =AH8*AH7 -> 7000 | AI6: =AI8*AI7 -> 0 | AJ6: =SUM(AJ12:AJ31) -> 3500 | AK6: =SUM(AK12:AK31) -> 0 | AL6: =SUM(AL12:AL31) -> 3000 | AM6: =SUM(AM12:AM31) -> 0 | AN6: =SUM(AN12:AN31) -> 0 | AP6: =SUM(AP12:AP31) -> 15652.5
G7: =Pl*(1+Gewinn)*(1+SicherheitAngebot) -> 110 | H7: =MKo*(1+Gewinn)*(1+SicherheitAngebot) -> 100 | I7: =EKo*(1+Gewinn)*(1+SicherheitAngebot) -> 92 | J7: =Sw*(1+Gewinn)*(1+SicherheitAngebot) -> 105 | K7: =Inb*(1+Gewinn)*(1+SicherheitAngebot) -> 105 | L7: =El*(1+Gewinn)*(1+SicherheitAngebot) -> 82 | M7: =Mo*(1+Gewinn)*(1+SicherheitAngebot) -> 82 | N7: =TF*(1+Gewinn)*(1+SicherheitAngebot) -> 85 | O7: MGKZ | S7: =Pl*(1+Gewinn)*(1+SicherheitAngebot) -> 110 | T7: =MKo*(1+Gewinn)*(1+SicherheitAngebot) -> 100 | U7: =Inb*(1+Gewinn)*(1+SicherheitAngebot) -> 105 | V7: =Inb*(1+Gewinn)*(1+SicherheitAngebot) -> 105 | W7: =El*(1+Gewinn)*(1+SicherheitAngebot) -> 82 | X7: =Mo*(1+Gewinn)*(1+SicherheitAngebot) -> 82 | Z7: =Pl*(1+Gewinn)*(1+SicherheitAngebot) -> 110 | AA7: =MKo*(1+Gewinn)*(1+SicherheitAngebot) -> 100 | AB7: =Inb*(1+Gewinn)*(1+SicherheitAngebot) -> 105 | AC7: =Inb*(1+Gewinn)*(1+SicherheitAngebot) -> 105 | AD7: =El*(1+Gewinn)*(1+SicherheitAngebot) -> 82 | AE7: =Mo*(1+Gewinn)*(1+SicherheitAngebot) -> 82 | AG7: =Auslöse*(1+Gewinn)*(1+SicherheitAngebot) -> 52 | AH7: =Hotel*(1+Gewinn)*(1+SicherheitAngebot) -> 100 | AI7: =KM_Pauschale*(1+Gewinn)*(1+SicherheitAngebot) -> 0.6 | AJ7: Flüge | AK7: Taxi | AL7: Leihauto | AM7: Bus/Zug/F | AN7: Sonstiges | AP7: =Zuschläge_IBN -> 0.25
G8: =SUM(G12:G31) -> 0 | H8: =SUM(H12:H31) -> 2446 | I8: =SUM(I12:I31) -> 728 | J8: =SUM(J12:J31) -> 1027 | K8: =SUM(K12:K31) -> 1657 | L8: =SUM(L12:L31) -> 1035 | M8: =SUM(M12:M31) -> 2182 | N8: =N6/N7 -> 2544.7059 | O8: =MGKZ -> 0.1 | S8: =S33 -> 40 | T8: =T33 -> 0 | U8: =U33 -> 0 | V8: =V33 -> 170 | W8: =W33 -> 140 | X8: =X33 -> 220 | Z8: =Z33 -> 16 | AA8: =AA33 -> 0 | AB8: =AB33 -> 0 | AC8: =AC33 -> 24 | AD8: =AD33 -> 32 | AE8: =AE33 -> 48 | AG8: =SUM(AG12:AG31) -> 81 | AH8: =SUM(AH12:AH31) -> 70 | AI8: =SUM(AI12:AI31) -> 0
B10: Benennung | F10: Stück | G10: Pl | H10: MKo | I10: EKo | J10: Sw | K10: Inb | L10: El | M10: Mo | N10: TF | O10: KT | Q10: Summe | R10: + | S10: Pl | T10: MKo | U10: EKo | V10: Inb | W10: El | X10: Mo | Z10: Pl | AA10: MKo | AB10: EKo | AC10: Inb | AD10: El | AE10: Mo | AG10: Auslöse | AH10: Hotel | AI10: Anfahrt-km | AJ10: Flugkosten | AK10: Taxi | AL10: Leihauto | AM10: Bus/Zug... | AN10: Sonstiges | AP10: Zuschläge | AR10: IBN | AS10: = | AT10: Angebot | AV10: Summe % | AW10: + | AX10: IBN % | AY10: = | AZ10: Angebot %
B12: 1 | C12: Automatic Production Line | F12: 1 | G12: =F12*'1'!I$8 -> 0 | H12: =F12*'1'!J$8 -> 2126 | I12: =F12*'1'!K$8 -> 653 | J12: =F12*'1'!L$8 -> 922 | K12: =F12*'1'!M$8 -> 1522 | L12: =F12*'1'!N$8 -> 955 | M12: =F12*'1'!O$8 -> 1977 | N12: =F12*'1'!R$6 -> 207000 | O12: =F12*'1'!S$6 -> 653510 | Q12: ='1'!U$2 -> 1630230 | S12: =F12*'1'!W$8 -> 40 | T12: =F12*'1'!X$8 -> 0 | U12: =F12*'1'!Y$8 -> 0 | V12: =F12*'1'!Z$8 -> 170 | W12: =F12*'1'!AA$8 -> 140 | X12: =F12*'1'!AB$8 -> 220 | Z12: =F12*'1'!AD$8 -> 16 | AA12: =F12*'1'!AE$8 -> 0 | AB12: =F12*'1'!AF$8 -> 0 | AC12: =F12*'1'!AG$8 -> 24 | AD12: =F12*'1'!AH$8 -> 32 | AE12: =F12*'1'!AI$8 -> 48 | AG12: =F12*'1'!AK$8 -> 81 | AH12: =F12*'1'!AL$8 -> 70 | AI12: =F12*'1'!AM$8 -> 0 | AJ12: =F12*'1'!AN$6 -> 3500 | AK12: =F12*'1'!AO$6 -> 0 | AL12: =F12*'1'!AP$6 -> 3000 | AM12: =F12*'1'!AQ$6 -> 0 | AN12: =F12*'1'!AR$6 -> 0 | AP12: =F12*'1'!AT$6 -> 15652.5 | AR12: ='1'!AV$2 -> 95974.5 | AT12: =Q12+AR12 -> 1726204.5 | AV12: ='1'!AZ$2 -> 1449038.5 | AX12: ='1'!BB$2 -> 85307.439 | AZ12: =AV12+AX12 -> 1534345.9
B13: 2 | C13: Additional Training in Straubing | F13: 1 | G13: =F13*'2'!I$8 -> 0 | H13: =F13*'2'!J$8 -> 0 | I13: =F13*'2'!K$8 -> 0 | J13: =F13*'2'!L$8 -> 0 | K13: =F13*'2'!M$8 -> 0 | L13: =F13*'2'!N$8 -> 0 | M13: =F13*'2'!O$8 -> 0 | N13: =F13*'2'!R$6 -> 0 | O13: =F13*'2'!S$6 -> 0 | Q13: ='2'!U$2 -> 0 | S13: =F13*'2'!W$8 -> 0 | T13: =F13*'2'!X$8 -> 0 | U13: =F13*'2'!Y$8 -> 0 | V13: =F13*'2'!Z$8 -> 0 | W13: =F13*'2'!AA$8 -> 0 | X13: =F13*'2'!AB$8 -> 0 | Z13: =F13*'2'!AD$8 -> 0 | AA13: =F13*'2'!AE$8 -> 0 | AB13: =F13*'2'!AF$8 -> 0 | AC13: =F13*'2'!AG$8 -> 0 | AD13: =F13*'2'!AH$8 -> 0 | AE13: =F13*'2'!AI$8 -> 0 | AG13: =F13*'2'!AK$8 -> 0 | AH13: =F13*'2'!AL$8 -> 0 | AI13: =F13*'2'!AM$8 -> 0 | AJ13: =F13*'2'!AN$6 -> 0 | AK13: =F13*'2'!AO$6 -> 0 | AL13: =F13*'2'!AP$6 -> 0 | AM13: =F13*'2'!AQ$6 -> 0 | AN13: =F13*'2'!AR$6 -> 0 | AP13: =F13*'2'!AT$6 -> 0 | AR13: ='2'!AV$2 -> 0 | AT13: =Q13+AR13 -> 0 | AV13: ='2'!AZ$2 -> 0 | AX13: ='2'!BB$2 -> 0 | AZ13: =AV13+AX13 -> 0
B14: 3 | F14: 1 | G14: =F14*'3'!I$8 -> 0 | H14: =F14*'3'!J$8 -> 0 | I14: =F14*'3'!K$8 -> 0 | J14: =F14*'3'!L$8 -> 0 | K14: =F14*'3'!M$8 -> 0 | L14: =F14*'3'!N$8 -> 0 | M14: =F14*'3'!O$8 -> 0 | N14: =F14*'3'!R$6 -> 0 | O14: =F14*'3'!S$6 -> 0 | Q14: ='3'!U$2 -> 0 | S14: =F14*'3'!W$8 -> 0 | T14: =F14*'3'!X$8 -> 0 | U14: =F14*'3'!Y$8 -> 0 | V14: =F14*'3'!Z$8 -> 0 | W14: =F14*'3'!AA$8 -> 0 | X14: =F14*'3'!AB$8 -> 0 | Z14: =F14*'3'!AD$8 -> 0 | AA14: =F14*'3'!AE$8 -> 0 | AB14: =F14*'3'!AF$8 -> 0 | AC14: =F14*'3'!AG$8 -> 0 | AD14: =F14*'3'!AH$8 -> 0 | AE14: =F14*'3'!AI$8 -> 0 | AG14: =F14*'3'!AK$8 -> 0 | AH14: =F14*'3'!AL$8 -> 0 | AI14: =F14*'3'!AM$8 -> 0 | AJ14: =F14*'3'!AN$6 -> 0 | AK14: =F14*'3'!AO$6 -> 0 | AL14: =F14*'3'!AP$6 -> 0 | AM14: =F14*'3'!AQ$6 -> 0 | AN14: =F14*'3'!AR$6 -> 0 | AP14: =F14*'3'!AT$6 -> 0 | AR14: ='3'!AV$2 -> 0 | AT14: =Q14+AR14 -> 0 | AV14: ='3'!AZ$2 -> 0 | AX14: ='3'!BB$2 -> 0 | AZ14: =AV14+AX14 -> 0
B15: 4 | C15: Option 1: Insert Shrink Sleeve 1 | F15: 1 | G15: =F15*'4'!I$8 -> 0 | H15: =F15*'4'!J$8 -> 240 | I15: =F15*'4'!K$8 -> 50 | J15: =F15*'4'!L$8 -> 85 | K15: =F15*'4'!M$8 -> 95 | L15: =F15*'4'!N$8 -> 40 | M15: =F15*'4'!O$8 -> 125 | N15: =F15*'4'!R$6 -> 6800 | O15: =F15*'4'!S$6 -> 10450 | Q15: ='4'!U$2 -> 78280 | S15: =F15*'4'!W$8 -> 0 | T15: =F15*'4'!X$8 -> 0 | U15: =F15*'4'!Y$8 -> 0 | V15: =F15*'4'!Z$8 -> 0 | W15: =F15*'4'!AA$8 -> 0 | X15: =F15*'4'!AB$8 -> 0 | Z15: =F15*'4'!AD$8 -> 0 | AA15: =F15*'4'!AE$8 -> 0 | AB15: =F15*'4'!AF$8 -> 0 | AC15: =F15*'4'!AG$8 -> 0 | AD15: =F15*'4'!AH$8 -> 0 | AE15: =F15*'4'!AI$8 -> 0 | AG15: =F15*'4'!AK$8 -> 0 | AH15: =F15*'4'!AL$8 -> 0 | AI15: =F15*'4'!AM$8 -> 0 | AJ15: =F15*'4'!AN$6 -> 0 | AK15: =F15*'4'!AO$6 -> 0 | AL15: =F15*'4'!AP$6 -> 0 | AM15: =F15*'4'!AQ$6 -> 0 | AN15: =F15*'4'!AR$6 -> 0 | AP15: =F15*'4'!AT$6 -> 0 | AR15: ='4'!AV$2 -> 0 | AT15: =Q15+AR15 -> 78280 | AV15: ='4'!AZ$2 -> 69579.589 | AX15: ='4'!BB$2 -> 0 | AZ15: =AV15+AX15 -> 69579.589
B16: 5 | C16: Option 2: Electrical Testing | F16: 0 | G16: =F16*'5'!I$8 -> 0 | H16: =F16*'5'!J$8 -> 0 | I16: =F16*'5'!K$8 -> 0 | J16: =F16*'5'!L$8 -> 0 | K16: =F16*'5'!M$8 -> 0 | L16: =F16*'5'!N$8 -> 0 | M16: =F16*'5'!O$8 -> 0 | N16: =F16*'5'!R$6 -> 0 | O16: =F16*'5'!S$6 -> 0 | Q16: ='5'!U$2 -> 0 | S16: =F16*'5'!W$8 -> 0 | T16: =F16*'5'!X$8 -> 0 | U16: =F16*'5'!Y$8 -> 0 | V16: =F16*'5'!Z$8 -> 0 | W16: =F16*'5'!AA$8 -> 0 | X16: =F16*'5'!AB$8 -> 0 | Z16: =F16*'5'!AD$8 -> 0 | AA16: =F16*'5'!AE$8 -> 0 | AB16: =F16*'5'!AF$8 -> 0 | AC16: =F16*'5'!AG$8 -> 0 | AD16: =F16*'5'!AH$8 -> 0 | AE16: =F16*'5'!AI$8 -> 0 | AG16: =F16*'5'!AK$8 -> 0 | AH16: =F16*'5'!AL$8 -> 0 | AI16: =F16*'5'!AM$8 -> 0 | AJ16: =F16*'5'!AN$6 -> 0 | AK16: =F16*'5'!AO$6 -> 0 | AL16: =F16*'5'!AP$6 -> 0 | AM16: =F16*'5'!AQ$6 -> 0 | AN16: =F16*'5'!AR$6 -> 0 | AP16: =F16*'5'!AT$6 -> 0 | AR16: ='5'!AV$2 -> 0 | AT16: =Q16+AR16 -> 0 | AV16: ='5'!AZ$2 -> 0 | AX16: ='5'!BB$2 -> 0 | AZ16: =AV16+AX16 -> 0
B17: 6 | C17: Option 3: Labeling | F17: 1 | G17: =F17*'6'!I$8 -> 0 | H17: =F17*'6'!J$8 -> 80 | I17: =F17*'6'!K$8 -> 25 | J17: =F17*'6'!L$8 -> 20 | K17: =F17*'6'!M$8 -> 40 | L17: =F17*'6'!N$8 -> 40 | M17: =F17*'6'!O$8 -> 80 | N17: =F17*'6'!R$6 -> 2500 | O17: =F17*'6'!S$6 -> 26400 | Q17: ='6'!U$2 -> 55340 | S17: =F17*'6'!W$8 -> 0 | T17: =F17*'6'!X$8 -> 0 | U17: =F17*'6'!Y$8 -> 0 | V17: =F17*'6'!Z$8 -> 0 | W17: =F17*'6'!AA$8 -> 0 | X17: =F17*'6'!AB$8 -> 0 | Z17: =F17*'6'!AD$8 -> 0 | AA17: =F17*'6'!AE$8 -> 0 | AB17: =F17*'6'!AF$8 -> 0 | AC17: =F17*'6'!AG$8 -> 0 | AD17: =F17*'6'!AH$8 -> 0 | AE17: =F17*'6'!AI$8 -> 0 | AG17: =F17*'6'!AK$8 -> 0 | AH17: =F17*'6'!AL$8 -> 0 | AI17: =F17*'6'!AM$8 -> 0 | AJ17: =F17*'6'!AN$6 -> 0 | AK17: =F17*'6'!AO$6 -> 0 | AL17: =F17*'6'!AP$6 -> 0 | AM17: =F17*'6'!AQ$6 -> 0 | AN17: =F17*'6'!AR$6 -> 0 | AP17: =F17*'6'!AT$6 -> 0 | AR17: ='6'!AV$2 -> 0 | AT17: =Q17+AR17 -> 55340 | AV17: ='6'!AZ$2 -> 49189.25 | AX17: ='6'!BB$2 -> 0 | AZ17: =AV17+AX17 -> 49189.25
B18: 7 | C18: Modul 07 leer | F18: 1 | G18: =F18*'7'!I$8 -> 0 | H18: =F18*'7'!J$8 -> 0 | I18: =F18*'7'!K$8 -> 0 | J18: =F18*'7'!L$8 -> 0 | K18: =F18*'7'!M$8 -> 0 | L18: =F18*'7'!N$8 -> 0 | M18: =F18*'7'!O$8 -> 0 | N18: =F18*'7'!R$6 -> 0 | O18: =F18*'7'!S$6 -> 0 | Q18: ='7'!U$2 -> 0 | S18: =F18*'7'!W$8 -> 0 | T18: =F18*'7'!X$8 -> 0 | U18: =F18*'7'!Y$8 -> 0 | V18: =F18*'7'!Z$8 -> 0 | W18: =F18*'7'!AA$8 -> 0 | X18: =F18*'7'!AB$8 -> 0 | Z18: =F18*'7'!AD$8 -> 0 | AA18: =F18*'7'!AE$8 -> 0 | AB18: =F18*'7'!AF$8 -> 0 | AC18: =F18*'7'!AG$8 -> 0 | AD18: =F18*'7'!AH$8 -> 0 | AE18: =F18*'7'!AI$8 -> 0 | AG18: =F18*'7'!AK$8 -> 0 | AH18: =F18*'7'!AL$8 -> 0 | AI18: =F18*'7'!AM$8 -> 0 | AJ18: =F18*'7'!AN$6 -> 0 | AK18: =F18*'7'!AO$6 -> 0 | AL18: =F18*'7'!AP$6 -> 0 | AM18: =F18*'7'!AQ$6 -> 0 | AN18: =F18*'7'!AR$6 -> 0 | AP18: =F18*'7'!AT$6 -> 0 | AR18: ='7'!AV$2 -> 0 | AT18: =Q18+AR18 -> 0 | AV18: ='7'!AZ$2 -> 0 | AX18: ='7'!BB$2 -> 0 | AZ18: =AV18+AX18 -> 0
B19: 8 | C19: Modul 08 leer | F19: 1 | G19: =F19*'8'!I$8 -> 0 | H19: =F19*'8'!J$8 -> 0 | I19: =F19*'8'!K$8 -> 0 | J19: =F19*'8'!L$8 -> 0 | K19: =F19*'8'!M$8 -> 0 | L19: =F19*'8'!N$8 -> 0 | M19: =F19*'8'!O$8 -> 0 | N19: =F19*'8'!R$6 -> 0 | O19: =F19*'8'!S$6 -> 0 | Q19: ='8'!U$2 -> 0 | S19: =F19*'8'!W$8 -> 0 | T19: =F19*'8'!X$8 -> 0 | U19: =F19*'8'!Y$8 -> 0 | V19: =F19*'8'!Z$8 -> 0 | W19: =F19*'8'!AA$8 -> 0 | X19: =F19*'8'!AB$8 -> 0 | Z19: =F19*'8'!AD$8 -> 0 | AA19: =F19*'8'!AE$8 -> 0 | AB19: =F19*'8'!AF$8 -> 0 | AC19: =F19*'8'!AG$8 -> 0 | AD19: =F19*'8'!AH$8 -> 0 | AE19: =F19*'8'!AI$8 -> 0 | AG19: =F19*'8'!AK$8 -> 0 | AH19: =F19*'8'!AL$8 -> 0 | AI19: =F19*'8'!AM$8 -> 0 | AJ19: =F19*'8'!AN$6 -> 0 | AK19: =F19*'8'!AO$6 -> 0 | AL19: =F19*'8'!AP$6 -> 0 | AM19: =F19*'8'!AQ$6 -> 0 | AN19: =F19*'8'!AR$6 -> 0 | AP19: =F19*'8'!AT$6 -> 0 | AR19: ='8'!AV$2 -> 0 | AT19: =Q19+AR19 -> 0 | AV19: ='8'!AZ$2 -> 0 | AX19: ='8'!BB$2 -> 0 | AZ19: =AV19+AX19 -> 0
B20: 9 | C20: Modul 09 leer | F20: 1 | G20: =F20*'9'!I$8 -> 0 | H20: =F20*'9'!J$8 -> 0 | I20: =F20*'9'!K$8 -> 0 | J20: =F20*'9'!L$8 -> 0 | K20: =F20*'9'!M$8 -> 0 | L20: =F20*'9'!N$8 -> 0 | M20: =F20*'9'!O$8 -> 0 | N20: =F20*'9'!R$6 -> 0 | O20: =F20*'9'!S$6 -> 0 | Q20: ='9'!U$2 -> 0 | S20: =F20*'9'!W$8 -> 0 | T20: =F20*'9'!X$8 -> 0 | U20: =F20*'9'!Y$8 -> 0 | V20: =F20*'9'!Z$8 -> 0 | W20: =F20*'9'!AA$8 -> 0 | X20: =F20*'9'!AB$8 -> 0 | Z20: =F20*'9'!AD$8 -> 0 | AA20: =F20*'9'!AE$8 -> 0 | AB20: =F20*'9'!AF$8 -> 0 | AC20: =F20*'9'!AG$8 -> 0 | AD20: =F20*'9'!AH$8 -> 0 | AE20: =F20*'9'!AI$8 -> 0 | AG20: =F20*'9'!AK$8 -> 0 | AH20: =F20*'9'!AL$8 -> 0 | AI20: =F20*'9'!AM$8 -> 0 | AJ20: =F20*'9'!AN$6 -> 0 | AK20: =F20*'9'!AO$6 -> 0 | AL20: =F20*'9'!AP$6 -> 0 | AM20: =F20*'9'!AQ$6 -> 0 | AN20: =F20*'9'!AR$6 -> 0 | AP20: =F20*'9'!AT$6 -> 0 | AR20: ='9'!AV$2 -> 0 | AT20: =Q20+AR20 -> 0 | AV20: ='9'!AZ$2 -> 0 | AX20: ='9'!BB$2 -> 0 | AZ20: =AV20+AX20 -> 0
B21: 10 | C21: Changeover Part for 1 Type | F21: 0 | G21: =F21*'10'!I$8 -> 0 | H21: =F21*'10'!J$8 -> 0 | I21: =F21*'10'!K$8 -> 0 | J21: =F21*'10'!L$8 -> 0 | K21: =F21*'10'!M$8 -> 0 | L21: =F21*'10'!N$8 -> 0 | M21: =F21*'10'!O$8 -> 0 | N21: =F21*'10'!R$6 -> 0 | O21: =F21*'10'!S$6 -> 0 | Q21: ='10'!U$2 -> 0 | S21: =F21*'10'!W$8 -> 0 | T21: =F21*'10'!X$8 -> 0 | U21: =F21*'10'!Y$8 -> 0 | V21: =F21*'10'!Z$8 -> 0 | W21: =F21*'10'!AA$8 -> 0 | X21: =F21*'10'!AB$8 -> 0 | Z21: =F21*'10'!AD$8 -> 0 | AA21: =F21*'10'!AE$8 -> 0 | AB21: =F21*'10'!AF$8 -> 0 | AC21: =F21*'10'!AG$8 -> 0 | AD21: =F21*'10'!AH$8 -> 0 | AE21: =F21*'10'!AI$8 -> 0 | AG21: =F21*'10'!AK$8 -> 0 | AH21: =F21*'10'!AL$8 -> 0 | AI21: =F21*'10'!AM$8 -> 0 | AJ21: =F21*'10'!AN$6 -> 0 | AK21: =F21*'10'!AO$6 -> 0 | AL21: =F21*'10'!AP$6 -> 0 | AM21: =F21*'10'!AQ$6 -> 0 | AN21: =F21*'10'!AR$6 -> 0 | AP21: =F21*'10'!AT$6 -> 0 | AR21: ='10'!AV$2 -> 0 | AT21: =Q21+AR21 -> 0 | AV21: ='10'!AZ$2 -> 0 | AX21: ='10'!BB$2 -> 0 | AZ21: =AV21+AX21 -> 0
B22: 11 | C22: Modul 11 leer | F22: 1 | G22: =F22*'11'!I$8 -> 0 | H22: =F22*'11'!J$8 -> 0 | I22: =F22*'11'!K$8 -> 0 | J22: =F22*'11'!L$8 -> 0 | K22: =F22*'11'!M$8 -> 0 | L22: =F22*'11'!N$8 -> 0 | M22: =F22*'11'!O$8 -> 0 | N22: =F22*'11'!R$6 -> 0 | O22: =F22*'11'!S$6 -> 0 | Q22: ='11'!U$2 -> 0 | S22: =F22*'11'!W$8 -> 0 | T22: =F22*'11'!X$8 -> 0 | U22: =F22*'11'!Y$8 -> 0 | V22: =F22*'11'!Z$8 -> 0 | W22: =F22*'11'!AA$8 -> 0 | X22: =F22*'11'!AB$8 -> 0 | Z22: =F22*'11'!AD$8 -> 0 | AA22: =F22*'11'!AE$8 -> 0 | AB22: =F22*'11'!AF$8 -> 0 | AC22: =F22*'11'!AG$8 -> 0 | AD22: =F22*'11'!AH$8 -> 0 | AE22: =F22*'11'!AI$8 -> 0 | AG22: =F22*'11'!AK$8 -> 0 | AH22: =F22*'11'!AL$8 -> 0 | AI22: =F22*'11'!AM$8 -> 0 | AJ22: =F22*'11'!AN$6 -> 0 | AK22: =F22*'11'!AO$6 -> 0 | AL22: =F22*'11'!AP$6 -> 0 | AM22: =F22*'11'!AQ$6 -> 0 | AN22: =F22*'11'!AR$6 -> 0 | AP22: =F22*'11'!AT$6 -> 0 | AR22: ='11'!AV$2 -> 0 | AT22: =Q22+AR22 -> 0 | AV22: ='11'!AZ$2 -> 0 | AX22: ='11'!BB$2 -> 0 | AZ22: =AV22+AX22 -> 0
B23: 12 | C23: Modul 12 leer | F23: 1 | G23: =F23*'12'!I$8 -> 0 | H23: =F23*'12'!J$8 -> 0 | I23: =F23*'12'!K$8 -> 0 | J23: =F23*'12'!L$8 -> 0 | K23: =F23*'12'!M$8 -> 0 | L23: =F23*'12'!N$8 -> 0 | M23: =F23*'12'!O$8 -> 0 | N23: =F23*'12'!R$6 -> 0 | O23: =F23*'12'!S$6 -> 0 | Q23: ='12'!U$2 -> 0 | S23: =F23*'12'!W$8 -> 0 | T23: =F23*'12'!X$8 -> 0 | U23: =F23*'12'!Y$8 -> 0 | V23: =F23*'12'!Z$8 -> 0 | W23: =F23*'12'!AA$8 -> 0 | X23: =F23*'12'!AB$8 -> 0 | Z23: =F23*'12'!AD$8 -> 0 | AA23: =F23*'12'!AE$8 -> 0 | AB23: =F23*'12'!AF$8 -> 0 | AC23: =F23*'12'!AG$8 -> 0 | AD23: =F23*'12'!AH$8 -> 0 | AE23: =F23*'12'!AI$8 -> 0 | AG23: =F23*'12'!AK$8 -> 0 | AH23: =F23*'12'!AL$8 -> 0 | AI23: =F23*'12'!AM$8 -> 0 | AJ23: =F23*'12'!AN$6 -> 0 | AK23: =F23*'12'!AO$6 -> 0 | AL23: =F23*'12'!AP$6 -> 0 | AM23: =F23*'12'!AQ$6 -> 0 | AN23: =F23*'12'!AR$6 -> 0 | AP23: =F23*'12'!AT$6 -> 0 | AR23: ='12'!AV$2 -> 0 | AT23: =Q23+AR23 -> 0 | AV23: ='12'!AZ$2 -> 0 | AX23: ='12'!BB$2 -> 0 | AZ23: =AV23+AX23 -> 0
B24: 13 | C24: Modul 13 leer | F24: 1 | G24: =F24*'13'!I$8 -> 0 | H24: =F24*'13'!J$8 -> 0 | I24: =F24*'13'!K$8 -> 0 | J24: =F24*'13'!L$8 -> 0 | K24: =F24*'13'!M$8 -> 0 | L24: =F24*'13'!N$8 -> 0 | M24: =F24*'13'!O$8 -> 0 | N24: =F24*'13'!R$6 -> 0 | O24: =F24*'13'!S$6 -> 0 | Q24: ='13'!U$2 -> 0 | S24: =F24*'13'!W$8 -> 0 | T24: =F24*'13'!X$8 -> 0 | U24: =F24*'13'!Y$8 -> 0 | V24: =F24*'13'!Z$8 -> 0 | W24: =F24*'13'!AA$8 -> 0 | X24: =F24*'13'!AB$8 -> 0 | Z24: =F24*'13'!AD$8 -> 0 | AA24: =F24*'13'!AE$8 -> 0 | AB24: =F24*'13'!AF$8 -> 0 | AC24: =F24*'13'!AG$8 -> 0 | AD24: =F24*'13'!AH$8 -> 0 | AE24: =F24*'13'!AI$8 -> 0 | AG24: =F24*'13'!AK$8 -> 0 | AH24: =F24*'13'!AL$8 -> 0 | AI24: =F24*'13'!AM$8 -> 0 | AJ24: =F24*'13'!AN$6 -> 0 | AK24: =F24*'13'!AO$6 -> 0 | AL24: =F24*'13'!AP$6 -> 0 | AM24: =F24*'13'!AQ$6 -> 0 | AN24: =F24*'13'!AR$6 -> 0 | AP24: =F24*'13'!AT$6 -> 0 | AR24: ='13'!AV$2 -> 0 | AT24: =Q24+AR24 -> 0 | AV24: ='13'!AZ$2 -> 0 | AX24: ='13'!BB$2 -> 0 | AZ24: =AV24+AX24 -> 0
B25: 14 | C25: Modul 14 leer | F25: 1 | G25: =F25*'14'!I$8 -> 0 | H25: =F25*'14'!J$8 -> 0 | I25: =F25*'14'!K$8 -> 0 | J25: =F25*'14'!L$8 -> 0 | K25: =F25*'14'!M$8 -> 0 | L25: =F25*'14'!N$8 -> 0 | M25: =F25*'14'!O$8 -> 0 | N25: =F25*'14'!R$6 -> 0 | O25: =F25*'14'!S$6 -> 0 | Q25: ='14'!U$2 -> 0 | S25: =F25*'14'!W$8 -> 0 | T25: =F25*'14'!X$8 -> 0 | U25: =F25*'14'!Y$8 -> 0 | V25: =F25*'14'!Z$8 -> 0 | W25: =F25*'14'!AA$8 -> 0 | X25: =F25*'14'!AB$8 -> 0 | Z25: =F25*'14'!AD$8 -> 0 | AA25: =F25*'14'!AE$8 -> 0 | AB25: =F25*'14'!AF$8 -> 0 | AC25: =F25*'14'!AG$8 -> 0 | AD25: =F25*'14'!AH$8 -> 0 | AE25: =F25*'14'!AI$8 -> 0 | AG25: =F25*'14'!AK$8 -> 0 | AH25: =F25*'14'!AL$8 -> 0 | AI25: =F25*'14'!AM$8 -> 0 | AJ25: =F25*'14'!AN$6 -> 0 | AK25: =F25*'14'!AO$6 -> 0 | AL25: =F25*'14'!AP$6 -> 0 | AM25: =F25*'14'!AQ$6 -> 0 | AN25: =F25*'14'!AR$6 -> 0 | AP25: =F25*'14'!AT$6 -> 0 | AR25: ='14'!AV$2 -> 0 | AT25: =Q25+AR25 -> 0 | AV25: ='14'!AZ$2 -> 0 | AX25: ='14'!BB$2 -> 0 | AZ25: =AV25+AX25 -> 0
B26: 15 | C26: Modul 15 leer | F26: 1 | G26: =F26*'15'!I$8 -> 0 | H26: =F26*'15'!J$8 -> 0 | I26: =F26*'15'!K$8 -> 0 | J26: =F26*'15'!L$8 -> 0 | K26: =F26*'15'!M$8 -> 0 | L26: =F26*'15'!N$8 -> 0 | M26: =F26*'15'!O$8 -> 0 | N26: =F26*'15'!R$6 -> 0 | O26: =F26*'15'!S$6 -> 0 | Q26: ='15'!U$2 -> 0 | S26: =F26*'15'!W$8 -> 0 | T26: =F26*'15'!X$8 -> 0 | U26: =F26*'15'!Y$8 -> 0 | V26: =F26*'15'!Z$8 -> 0 | W26: =F26*'15'!AA$8 -> 0 | X26: =F26*'15'!AB$8 -> 0 | Z26: =F26*'15'!AD$8 -> 0 | AA26: =F26*'15'!AE$8 -> 0 | AB26: =F26*'15'!AF$8 -> 0 | AC26: =F26*'15'!AG$8 -> 0 | AD26: =F26*'15'!AH$8 -> 0 | AE26: =F26*'15'!AI$8 -> 0 | AG26: =F26*'15'!AK$8 -> 0 | AH26: =F26*'15'!AL$8 -> 0 | AI26: =F26*'15'!AM$8 -> 0 | AJ26: =F26*'15'!AN$6 -> 0 | AK26: =F26*'15'!AO$6 -> 0 | AL26: =F26*'15'!AP$6 -> 0 | AM26: =F26*'15'!AQ$6 -> 0 | AN26: =F26*'15'!AR$6 -> 0 | AP26: =F26*'15'!AT$6 -> 0 | AR26: ='15'!AV$2 -> 0 | AT26: =Q26+AR26 -> 0 | AV26: ='15'!AZ$2 -> 0 | AX26: ='15'!BB$2 -> 0 | AZ26: =AV26+AX26 -> 0
B27: 16 | C27: Modul 16 leer | F27: 1 | G27: =F27*'16'!I$8 -> 0 | H27: =F27*'16'!J$8 -> 0 | I27: =F27*'16'!K$8 -> 0 | J27: =F27*'16'!L$8 -> 0 | K27: =F27*'16'!M$8 -> 0 | L27: =F27*'16'!N$8 -> 0 | M27: =F27*'16'!O$8 -> 0 | N27: =F27*'16'!R$6 -> 0 | O27: =F27*'16'!S$6 -> 0 | Q27: ='16'!U$2 -> 0 | S27: =F27*'16'!W$8 -> 0 | T27: =F27*'16'!X$8 -> 0 | U27: =F27*'16'!Y$8 -> 0 | V27: =F27*'16'!Z$8 -> 0 | W27: =F27*'16'!AA$8 -> 0 | X27: =F27*'16'!AB$8 -> 0 | Z27: =F27*'16'!AD$8 -> 0 | AA27: =F27*'16'!AE$8 -> 0 | AB27: =F27*'16'!AF$8 -> 0 | AC27: =F27*'16'!AG$8 -> 0 | AD27: =F27*'16'!AH$8 -> 0 | AE27: =F27*'16'!AI$8 -> 0 | AG27: =F27*'16'!AK$8 -> 0 | AH27: =F27*'16'!AL$8 -> 0 | AI27: =F27*'16'!AM$8 -> 0 | AJ27: =F27*'16'!AN$6 -> 0 | AK27: =F27*'16'!AO$6 -> 0 | AL27: =F27*'16'!AP$6 -> 0 | AM27: =F27*'16'!AQ$6 -> 0 | AN27: =F27*'16'!AR$6 -> 0 | AP27: =F27*'16'!AT$6 -> 0 | AR27: ='16'!AV$2 -> 0 | AT27: =Q27+AR27 -> 0 | AV27: ='16'!AZ$2 -> 0 | AX27: ='16'!BB$2 -> 0 | AZ27: =AV27+AX27 -> 0
B28: 17 | C28: Modul 17 leer | F28: 1 | G28: =F28*'17'!I$8 -> 0 | H28: =F28*'17'!J$8 -> 0 | I28: =F28*'17'!K$8 -> 0 | J28: =F28*'17'!L$8 -> 0 | K28: =F28*'17'!M$8 -> 0 | L28: =F28*'17'!N$8 -> 0 | M28: =F28*'17'!O$8 -> 0 | N28: =F28*'17'!R$6 -> 0 | O28: =F28*'17'!S$6 -> 0 | Q28: ='17'!U$2 -> 0 | S28: =F28*'17'!W$8 -> 0 | T28: =F28*'17'!X$8 -> 0 | U28: =F28*'17'!Y$8 -> 0 | V28: =F28*'17'!Z$8 -> 0 | W28: =F28*'17'!AA$8 -> 0 | X28: =F28*'17'!AB$8 -> 0 | Z28: =F28*'17'!AD$8 -> 0 | AA28: =F28*'17'!AE$8 -> 0 | AB28: =F28*'17'!AF$8 -> 0 | AC28: =F28*'17'!AG$8 -> 0 | AD28: =F28*'17'!AH$8 -> 0 | AE28: =F28*'17'!AI$8 -> 0 | AG28: =F28*'17'!AK$8 -> 0 | AH28: =F28*'17'!AL$8 -> 0 | AI28: =F28*'17'!AM$8 -> 0 | AJ28: =F28*'17'!AN$6 -> 0 | AK28: =F28*'17'!AO$6 -> 0 | AL28: =F28*'17'!AP$6 -> 0 | AM28: =F28*'17'!AQ$6 -> 0 | AN28: =F28*'17'!AR$6 -> 0 | AP28: =F28*'17'!AT$6 -> 0 | AR28: ='17'!AV$2 -> 0 | AT28: =Q28+AR28 -> 0 | AV28: ='17'!AZ$2 -> 0 | AX28: ='17'!BB$2 -> 0 | AZ28: =AV28+AX28 -> 0
B29: 18 | C29: Modul 18 leer | F29: 1 | G29: =F29*'18'!I$8 -> 0 | H29: =F29*'18'!J$8 -> 0 | I29: =F29*'18'!K$8 -> 0 | J29: =F29*'18'!L$8 -> 0 | K29: =F29*'18'!M$8 -> 0 | L29: =F29*'18'!N$8 -> 0 | M29: =F29*'18'!O$8 -> 0 | N29: =F29*'18'!R$6 -> 0 | O29: =F29*'18'!S$6 -> 0 | Q29: ='18'!U$2 -> 0 | S29: =F29*'18'!W$8 -> 0 | T29: =F29*'18'!X$8 -> 0 | U29: =F29*'18'!Y$8 -> 0 | V29: =F29*'18'!Z$8 -> 0 | W29: =F29*'18'!AA$8 -> 0 | X29: =F29*'18'!AB$8 -> 0 | Z29: =F29*'18'!AD$8 -> 0 | AA29: =F29*'18'!AE$8 -> 0 | AB29: =F29*'18'!AF$8 -> 0 | AC29: =F29*'18'!AG$8 -> 0 | AD29: =F29*'18'!AH$8 -> 0 | AE29: =F29*'18'!AI$8 -> 0 | AG29: =F29*'18'!AK$8 -> 0 | AH29: =F29*'18'!AL$8 -> 0 | AI29: =F29*'18'!AM$8 -> 0 | AJ29: =F29*'18'!AN$6 -> 0 | AK29: =F29*'18'!AO$6 -> 0 | AL29: =F29*'18'!AP$6 -> 0 | AM29: =F29*'18'!AQ$6 -> 0 | AN29: =F29*'18'!AR$6 -> 0 | AP29: =F29*'18'!AT$6 -> 0 | AR29: ='18'!AV$2 -> 0 | AT29: =Q29+AR29 -> 0 | AV29: ='18'!AZ$2 -> 0 | AX29: ='18'!BB$2 -> 0 | AZ29: =AV29+AX29 -> 0
B30: 19 | C30: Modul 19 leer | F30: 1 | G30: =F30*'19'!I$8 -> 0 | H30: =F30*'19'!J$8 -> 0 | I30: =F30*'19'!K$8 -> 0 | J30: =F30*'19'!L$8 -> 0 | K30: =F30*'19'!M$8 -> 0 | L30: =F30*'19'!N$8 -> 0 | M30: =F30*'19'!O$8 -> 0 | N30: =F30*'19'!R$6 -> 0 | O30: =F30*'19'!S$6 -> 0 | Q30: ='19'!U$2 -> 0 | S30: =F30*'19'!W$8 -> 0 | T30: =F30*'19'!X$8 -> 0 | U30: =F30*'19'!Y$8 -> 0 | V30: =F30*'19'!Z$8 -> 0 | W30: =F30*'19'!AA$8 -> 0 | X30: =F30*'19'!AB$8 -> 0 | Z30: =F30*'19'!AD$8 -> 0 | AA30: =F30*'19'!AE$8 -> 0 | AB30: =F30*'19'!AF$8 -> 0 | AC30: =F30*'19'!AG$8 -> 0 | AD30: =F30*'19'!AH$8 -> 0 | AE30: =F30*'19'!AI$8 -> 0 | AG30: =F30*'19'!AK$8 -> 0 | AH30: =F30*'19'!AL$8 -> 0 | AI30: =F30*'19'!AM$8 -> 0 | AJ30: =F30*'19'!AN$6 -> 0 | AK30: =F30*'19'!AO$6 -> 0 | AL30: =F30*'19'!AP$6 -> 0 | AM30: =F30*'19'!AQ$6 -> 0 | AN30: =F30*'19'!AR$6 -> 0 | AP30: =F30*'19'!AT$6 -> 0 | AR30: ='19'!AV$2 -> 0 | AT30: =Q30+AR30 -> 0 | AV30: ='19'!AZ$2 -> 0 | AX30: ='19'!BB$2 -> 0 | AZ30: =AV30+AX30 -> 0
B31: 20 | C31: Modul 20 leer | F31: 1 | G31: =F31*'20'!I$8 -> 0 | H31: =F31*'20'!J$8 -> 0 | I31: =F31*'20'!K$8 -> 0 | J31: =F31*'20'!L$8 -> 0 | K31: =F31*'20'!M$8 -> 0 | L31: =F31*'20'!N$8 -> 0 | M31: =F31*'20'!O$8 -> 0 | N31: =F31*'20'!R$6 -> 0 | O31: =F31*'20'!S$6 -> 0 | Q31: ='20'!U$2 -> 0 | S31: =F31*'20'!W$8 -> 0 | T31: =F31*'20'!X$8 -> 0 | U31: =F31*'20'!Y$8 -> 0 | V31: =F31*'20'!Z$8 -> 0 | W31: =F31*'20'!AA$8 -> 0 | X31: =F31*'20'!AB$8 -> 0 | Z31: =F31*'20'!AD$8 -> 0 | AA31: =F31*'20'!AE$8 -> 0 | AB31: =F31*'20'!AF$8 -> 0 | AC31: =F31*'20'!AG$8 -> 0 | AD31: =F31*'20'!AH$8 -> 0 | AE31: =F31*'20'!AI$8 -> 0 | AG31: =F31*'20'!AK$8 -> 0 | AH31: =F31*'20'!AL$8 -> 0 | AI31: =F31*'20'!AM$8 -> 0 | AJ31: =F31*'20'!AN$6 -> 0 | AK31: =F31*'20'!AO$6 -> 0 | AL31: =F31*'20'!AP$6 -> 0 | AM31: =F31*'20'!AQ$6 -> 0 | AN31: =F31*'20'!AR$6 -> 0 | AP31: =F31*'20'!AT$6 -> 0 | AR31: ='20'!AV$2 -> 0 | AT31: =Q31+AR31 -> 0 | AV31: ='20'!AZ$2 -> 0 | AX31: ='20'!BB$2 -> 0 | AZ31: =AV31+AX31 -> 0
F33: Zwischensummen | G33: =SUM(G12:G31) -> 0 | H33: =SUM(H12:H31) -> 2446 | I33: =SUM(I12:I31) -> 728 | J33: =SUM(J12:J31) -> 1027 | K33: =SUM(K12:K31) -> 1657 | L33: =SUM(L12:L31) -> 1035 | M33: =SUM(M12:M31) -> 2182 | N33: =SUM(N12:N31) -> 216300 | O33: =SUM(O12:O31) -> 690360 | Q33: =SUM(Q12:Q31) -> 1763850 | R33: + | S33: =SUM(S12:S31) -> 40 | T33: =SUM(T12:T31) -> 0 | U33: =SUM(U12:U31) -> 0 | V33: =SUM(V12:V31) -> 170 | W33: =SUM(W12:W31) -> 140 | X33: =SUM(X12:X31) -> 220 | Z33: =SUM(Z12:Z31) -> 16 | AA33: =SUM(AA12:AA31) -> 0 | AB33: =SUM(AB12:AB31) -> 0 | AC33: =SUM(AC12:AC31) -> 24 | AD33: =SUM(AD12:AD31) -> 32 | AE33: =SUM(AE12:AE31) -> 48 | AG33: =SUM(AG12:AG31) -> 81 | AH33: =SUM(AH12:AH31) -> 70 | AI33: =SUM(AI12:AI31) -> 0 | AJ33: =AJ6 -> 3500 | AK33: =AK6 -> 0 | AL33: =AL6 -> 3000 | AM33: =AM6 -> 0 | AN33: =AN6 -> 0 | AP33: =AP6 -> 15652.5 | AR33: =SUM(AR12:AR31) -> 95974.5 | AS33: = | AT33: =SUM(AT12:AT31) -> 1859824.5 | AV33: =SUM(AV12:AV32) -> 1567807.3 | AW33: + | AX33: =SUM(AX12:AX31) -> 85307.439 | AY33: = | AZ33: =SUM(AZ12:AZ31) -> 1653114.8
B34: Allgemeine Projektkosten:
B35: Pl | C35: Projektmanagement/Projektleitung im Haus | F35: 1 | G35: =Allg!J9 -> 550 | H35: =Allg!L9 -> 100 | J35: =Allg!N9 -> 100 | AT35: =Allg!$R9 -> 81000 | AZ35: =Allg!$T9 -> 71997.276
B36: Dok | C36: Dokumentation | F36: 1 | G36: =Allg!K21 -> 0 | H36: =Allg!L21 -> 80 | I36: =Allg!M21 -> 50 | J36: =Allg!N21 -> 80 | N36: Auswärts | O36: =Allg!P21 -> 0 | AT36: =Allg!$R21 -> 21000 | AZ36: =Allg!$T21 -> 18665.96
B37: Vp | C37: Verpackung | F37: 1 | AT37: =Allg!$R33 -> 2000 | AZ37: =Allg!$T33 -> 1777.7105
B38: Vs | C38: Versand | F38: 1 | AT38: =Allg!$R45 -> 5000 | AZ38: =Allg!$T45 -> 4444.2763
E40: Gesamtsummen | AT40: =AT33+SUM(AT35:AT38) -> 1968824.5 | AZ40: =AZ33+SUM(AZ35:AZ38) -> 1750000
AR42: =1995000-109000-11000-23000-88000 -> 1764000

Sheet VK
C2: Vorkalkulation
B3: =Kunde -> Dräxlmeier Satu Mare | D3: =Übersicht!E3 -> Hr. Eglseder
B4: =Anlage -> Automatic Production Line for Wire Processing
B5: =Angebotsnummer -> A07616000A | C5: =Datum -> 45825 | D5: =Bearbeiter -> Schötz/Radlbeck
B7: Kostenstelle | F7: Stundensatz | I7: Vorgaben
F8: o.Gew. | G8: brutto | I8: Std. VK | K8: Summe
B9: Konstruktion Mechanik
B10: Konstruktion (+ IBN-Kunde) | C10: 10 | E10: auswärts: | F10: 100 | G10: =MKo*(1+Gewinn)*(1+Sicherheit) -> 88.885525 | I10: =Übersicht!$H$33+Übersicht!$H$35+Übersicht!$H$36+Übersicht!$T$33 -> 2626 | J10: =F10*I10 -> 262600 | K10: =J10 -> 262600 | L10: =IF(K$33<>0,J10/K$33,0) -> 0.13337908
B11: Dokumentation | C11: 1-000555, 20 | E11: =Allg!P21/(1+SicherheitAngebot)/(1+Gewinn) -> 0 | F11: 100 | G11: =Doku*(1+Gewinn)*(1+Sicherheit) -> 88.885525 | I11: =Übersicht!$G$36 -> 0 | J11: =F11*I11 -> 0 | K11: =J11+E11 -> 0 | L11: =IF(K$33<>0,K11/K$33,0) -> 0
B12: Konstruktion Elektrik
B13: E-Konstruktion | C13: 170 | F13: 92 | G13: =EKo*(1+Gewinn)*(1+Sicherheit) -> 81.774683 | I13: =Übersicht!$I$33+Übersicht!I36 -> 778 | J13: =F13*I13 -> 71576 | K13: =J13+J14+J15 -> 372296 | L13: =IF(K$33<>0,J13/K$33,0) -> 0.036354688
B14: Software | C14: 180 | F14: 105 | G14: =Sw*(1+Gewinn)*(1+Sicherheit) -> 93.329802 | I14: =Übersicht!$J$33+Übersicht!$J$35+Übersicht!$J$36 -> 1207 | J14: =F14*I14 -> 126735 | L14: =IF(K$33<>0,J14/K$33,0) -> 0.064370897
B15: Inbetriebnahme im Haus | C15: 190 | F15: 105 | G15: =Inb*(1+Gewinn)*(1+Sicherheit) -> 93.329802 | I15: =Übersicht!$K$33 -> 1657 | J15: =F15*I15 -> 173985 | L15: =IF(K$33<>0,J15/K$33,0) -> 0.088369989
B16: Projektmanagement
B17: Projektleitung (Pl) | C17: 270 | F17: 110 | G17: =Pl*(1+Gewinn)*(1+Sicherheit) -> 97.774078 | I17: =Übersicht!$G$35+Übersicht!$G$33 -> 550 | J17: =F17*I17 -> 60500 | K17: =F17*I17 -> 60500 | L17: =IF(K$33<>0,J17/K$33,0) -> 0.030728996 | X17: tt
B18: Fertigung
B19: Montage | C19: 110 | F19: 82 | G19: =Mo*(1+Gewinn)*(1+Sicherheit) -> 72.886131 | I19: =Übersicht!$M$33 -> 2182 | J19: =F19*I19 -> 178924 | K19: =J19+J20+J21 -> 480094 | L19: =IF(K$33<>0,J19/K$33,0) -> 0.090878593
B20: Teilefertigung | C20: 50 | F20: 85 | G20: =TF*(1+Gewinn)*(1+Sicherheit) -> 75.552697 | I20: =Übersicht!$N$8 -> 2544.7059 | J20: =F20*I20 -> 216300 | L20: =IF(K$33<>0,J20/K$33,0) -> 0.10986251
B21: Elektrik | C21: 230 | F21: 82 | G21: =El*(1+Gewinn)*(1+Sicherheit) -> 72.886131 | I21: =Übersicht!$L$33 -> 1035 | J21: =F21*I21 -> 84870 | L21: =IF(K$33<>0,J21/K$33,0) -> 0.04310694
B22: Materialkosten | I22: MGKZ | J22: kalkuliert | K22: inkl. MGKZ
B23: Kaufteile | C23: *KT | I23: =MGKZ -> 0.1 | J23: =Übersicht!$O$33/(1+SicherheitAngebot)/(1+Gewinn)/(1+MGKZ) -> 627600 | K23: =J23*(1+$I$23) -> 690360 | L23: =IF(K$33<>0,K23/K$33,0) -> 0.35064578
B24: Versandkosten | C24: 1-000537 | I24: 0 | J24: =(Übersicht!$AT$37+Übersicht!$AT$38)/(1+SicherheitAngebot)/(1+Gewinn) -> 7000 | K24: =J24*(1+$I$24) -> 7000 | L24: =IF(K$33<>0,J24/K$33,0) -> 0.003555421
B25: Inbetriebnahme Kunde | I25: Std.VK | J25: Betrag in €
B26: Projektleitung (Pl) | C26: 390 | F26: =Pl -> 110 | G26: =Pl*(1+Gewinn)*(1+Sicherheit) -> 97.774078 | I26: =Übersicht!$S$33 -> 40 | J26: =F26*I26 -> 4400 | K26: =SUM(J26:J32) -> 95974.5 | L26: =IF(K$33<>0,K26/K$33,0) -> 0.048747108
B27: Software (+ E-Konstruktion) | C27: 200 | F27: =Inb -> 105 | G27: =Inb*(1+Gewinn)*(1+Sicherheit) -> 93.329802 | I27: =Übersicht!$V$33+Übersicht!$U$33 -> 170 | J27: =F27*I27 -> 17850
B28: Montage | C28: 150 | F28: =Mo -> 82 | G28: =Mo*(1+Gewinn)*(1+Sicherheit) -> 72.886131 | I28: =Übersicht!$X$33 -> 220 | J28: =F28*I28 -> 18040
B29: Elektrik | C29: 260 | F29: =El -> 82 | G29: =El*(1+Gewinn)*(1+Sicherheit) -> 72.886131 | I29: =Übersicht!$W$33 -> 140 | J29: =F29*I29 -> 11480
B30: Reisekosten (Zeiten) | C30: 340,350,360,370(MK),380 + PL + EKo | J30: =SUM(Übersicht!Z6:AE6)/(1+Gewinn)/(1+SicherheitAngebot) -> 10840
B31: Hotel, Auslöse, sonstiges (Zuschläge) | C31: 1-000006,7,8,9,10,11,13, 1-00921 | F31: 0.25 | J31: =(SUM(Übersicht!AG6:AN6)+Übersicht!AP6-Übersicht!AJ6)/(1+Gewinn)/(1+SicherheitAngebot) -> 29864.5 | N31: MGKZ | O31: 0.1 | P31: Sicherheit
B32: Flüge | C32: 1-000012 | J32: =Übersicht!AJ6/(1+Gewinn)/(1+SicherheitAngebot) -> 3500 | N32: Gewinn | O32: 0 | P32: Angebotskalkulation
C33: Grundlage Kunden-IBN | I33: Kalkuliert inkl. Nachträge | K33: =SUM(K9:K32) -> 1968824.5 | N33: Verhandlungsspielraum | O33: 0 | P33: =1/(1-O33)-1 -> 0
C34: Auslöse pro Tag | F34: 52 | G34: =Auslöse*(1+Gewinn)*(1+Sicherheit) -> 46.220473 | I34: Gewinn | J34: =Gewinn -> 0 | K34: =K33*J34 -> 0
C35: Hotel pro Tag | F35: 100 | G35: =Hotel*(1+Gewinn)*(1+Sicherheit) -> 88.885525 | I35: Angebotspreis mit Gewinn | K35: =K33+K34 -> 1968824.5 | N35: Projektnachlass | O35: =IF(O37<>0,1-(O37/(K35*(1+P33))),O36) -> 0.11114475 | P35: =IF(O35<>0,(1+P33)*(1-O35)-1,"-") -> -0.11114475
C36: Kilometerpauschale Firmen-PKW | F36: 0.6 | G36: =KM_Pauschale*(1+Gewinn)*(1+Sicherheit) -> 0.53331315 | I36: Sicherheit | J36: =IF(O35<>0,(1+P33)*(1-O35)-1,P33) -> -0.11114475 | K36: =K35*J36 -> -218824.5 | N36: Verhandlungsnachlass | P36: Sicherheit nach
I37: Angebotspreis final | K37: =K35+K36 -> 1750000 | N37: oder gewünschter Zielpreis | O37: 1750000 | P37: Verhandlung
B38: MS-F_Rev.:8 / 06.03.25 / S. Schnurrenberger | I38: Angebotspreis Abgabe | K38: =Übersicht!AT40 -> 1968824.5

Sheet TP
B2: Terminübersicht | N2: =Anlage -> Automatic Production Line for Wire Processing
B3: =Kunde -> Dräxlmeier Satu Mare | E3: =Übersicht!E3 -> Hr. Eglseder
B4: =Anlage -> Automatic Production Line for Wire Processing
B5: =Angebotsnummer -> A07616000A | D5: =Datum -> 45825 | E5: =Bearbeiter -> Schötz/Radlbeck | N5: 2024 | CJ5: 2025 | GK5: 2026
N6: Februar | W6: März | AF6: April | AO6: Mai | AY6: Juni | BH6: Juli | BO6: August | BX6: September | CG6: Oktober | CJ6: Januar | CT6: Februar | DB6: März | DJ6: April | DT6: Mai | EB6: Juni | EJ6: Juli | ET6: August | FB6: September | FK6: Oktober | FT6: November | GB6: Dezember | GK6: Januar | GT6: Februar | HB6: März | HK6: April | HT6: Mai | IB6: Juni | IK6: Juli | IT6: August | JB6: September | JK6: Oktober | JT6: November | KB6: Dezember
G7: Vorgaben | M7: KW | N7: 5 | P7: 6 | R7: 7 | T7: 8 | V7: 9 | X7: 10 | Z7: 11 | AB7: 12 | AD7: 13 | AF7: 14 | AH7: 15 | AJ7: 16 | AL7: 17 | AN7: 18 | AP7: 19 | AR7: 20 | AT7: 21 | AV7: 22 | AX7: 23 | AZ7: 24 | BB7: 25 | BD7: 26 | BF7: 27 | BH7: 28 | BJ7: 29 | BL7: 30 | BN7: 31 | BP7: 32 | BR7: 33 | BT7: 34 | BV7: 35 | BX7: 36 | BZ7: 37 | CB7: 38 | CD7: 39 | CF7: 40 | CH7: 41 | CJ7: 1 | CL7: =CJ7+1 -> 2 | CN7: =CL7+1 -> 3 | CP7: =CN7+1 -> 4 | CR7: =CP7+1 -> 5 | CT7: =CR7+1 -> 6 | CV7: =CT7+1 -> 7 | CX7: =CV7+1 -> 8 | CZ7: =CX7+1 -> 9 | DB7: =CZ7+1 -> 10 | DD7: =DB7+1 -> 11 | DF7: =DD7+1 -> 12 | DH7: =DF7+1 -> 13 | DJ7: =DH7+1 -> 14 | DL7: =DJ7+1 -> 15 | DN7: =DL7+1 -> 16 | DP7: =DN7+1 -> 17 | DR7: =DP7+1 -> 18 | DT7: =DR7+1 -> 19 | DV7: =DT7+1 -> 20 | DX7: =DV7+1 -> 21 | DZ7: =DX7+1 -> 22 | EB7: =DZ7+1 -> 23 | ED7: =EB7+1 -> 24 | EF7: =ED7+1 -> 25 | EH7: =EF7+1 -> 26 | EJ7: =EH7+1 -> 27 | EL7: =EJ7+1 -> 28 | EN7: =EL7+1 -> 29 | EP7: =EN7+1 -> 30 | ER7: =EP7+1 -> 31 | ET7: =ER7+1 -> 32 | EV7: =ET7+1 -> 33 | EX7: =EV7+1 -> 34 | EZ7: =EX7+1 -> 35 | FB7: =EZ7+1 -> 36 | FD7: =FB7+1 -> 37 | FF7: =FD7+1 -> 38 | FH7: =FF7+1 -> 39 | FJ7: =FH7+1 -> 40 | FL7: =FJ7+1 -> 41 | FN7: =FL7+1 -> 42 | FP7: =FN7+1 -> 43 | FR7: =FP7+1 -> 44 | FT7: =FR7+1 -> 45 | FV7: =FT7+1 -> 46 | FX7: =FV7+1 -> 47 | FZ7: =FX7+1 -> 48 | GB7: =FZ7+1 -> 49 | GD7: =GB7+1 -> 50 | GF7: =GD7+1 -> 51 | GH7: =GF7+1 -> 52 | GJ7: 1 | GL7: =GJ7+1 -> 2 | GN7: =GL7+1 -> 3 | GP7: =GN7+1 -> 4 | GR7: =GP7+1 -> 5 | GT7: =GR7+1 -> 6 | GV7: =GT7+1 -> 7 | GX7: =GV7+1 -> 8 | GZ7: =GX7+1 -> 9 | HB7: =GZ7+1 -> 10 | HD7: =HB7+1 -> 11 | HF7: =HD7+1 -> 12 | HH7: =HF7+1 -> 13 | HJ7: =HH7+1 -> 14 | HL7: =HJ7+1 -> 15 | HN7: =HL7+1 -> 16 | HP7: =HN7+1 -> 17 | HR7: =HP7+1 -> 18 | HT7: =HR7+1 -> 19 | HV7: =HT7+1 -> 20 | HX7: =HV7+1 -> 21 | HZ7: =HX7+1 -> 22 | IB7: =HZ7+1 -> 23 | ID7: =IB7+1 -> 24 | IF7: =ID7+1 -> 25 | IH7: =IF7+1 -> 26 | IJ7: =IH7+1 -> 27 | IL7: =IJ7+1 -> 28 | IN7: =IL7+1 -> 29 | IP7: =IN7+1 -> 30 | IR7: =IP7+1 -> 31 | IT7: =IR7+1 -> 32 | IV7: =IT7+1 -> 33 | IX7: =IV7+1 -> 34 | IZ7: =IX7+1 -> 35 | JB7: =IZ7+1 -> 36 | JD7: =JB7+1 -> 37 | JF7: =JD7+1 -> 38 | JH7: =JF7+1 -> 39 | JJ7: =JH7+1 -> 40 | JL7: =JJ7+1 -> 41 | JN7: =JL7+1 -> 42 | JP7: =JN7+1 -> 43 | JR7: =JP7+1 -> 44 | JT7: =JR7+1 -> 45 | JV7: =JT7+1 -> 46 | JX7: =JV7+1 -> 47 | JZ7: =JX7+1 -> 48 | KB7: =JZ7+1 -> 49 | KD7: =KB7+1 -> 50 | KF7: =KD7+1 -> 51 | KH7: =KF7+1 -> 52 | KJ7: =KH7+1 -> 53
B9: Projektmanagement | G9: =Übersicht!$G$35 -> 550
B10: Mechanik-Konstruktion | G10: =VK!$I$10 -> 2626
B11: Elektro-Konstruktion | G11: =VK!$I$13 -> 778
B12: Kaufteile/Beistellungen | G12: =VK!$J$23 -> 627600
B13: Teilefertigung | G13: =VK!$J$20 -> 216300
B14: Montage | G14: =VK!$I$19 -> 2182
B15: Elektik | G15: =VK!$I$21 -> 1035
B16: Software | G16: =VK!$I$14 -> 1207
B17: Inbetriebnahme im Haus | G17: =VK!$I$15 -> 1657
B18: Verpacken/Verladen/Transport | G18: =Übersicht!Q$38 -> 0
B19: Wiederaufbau und Inbetriebnahme | G19: Sw | H19: =Übersicht!V33 -> 170 | I19: Mo | J19: =Übersicht!X33 -> 220 | K19: El | L19: =Übersicht!W33 -> 140
D21: MKo
D22: EKo TF Kaufteile (o. MGZ)
D23: SW Mo El
D24: Inb im Haus

Sheet AP+
B2: Projektvorgabewerte zur Eingabe in AP+
B3: =Kunde -> Dräxlmeier Satu Mare | D3: =Übersicht!E3 -> Hr. Eglseder
B4: =Anlage -> Automatic Production Line for Wire Processing
B5: =Angebotsnummer -> A07616000A | C5: =Datum -> 45825 | D5: =Bearbeiter -> Schötz/Radlbeck
E6: Eingabewerte | L6: Eingabewerte
B7: M-Konstruktion + IBN-Kunde | D7: 10 | E7: =Übersicht!$H$33+Übersicht!$H$35+Übersicht!$H$36+Übersicht!$T$33 -> 2626 | F7: =Übersicht!$T$33 -> 0 | J7: Kaufteile | K7: *KT | L7: =VK!J23 -> 627600
B9: Dokumentation | D9: 20 | E9: =Übersicht!$G$36 -> 0 | J9: Auslösen | K9: 1-000006 | L9: =Übersicht!$AG$6/(1+Gewinn)/(1+SicherheitAngebot) -> 4212
B11: Teilefertigung std : min | D11: 50 | E11: =Übersicht!$N$8 -> 2544.7059 | F11: =ROUNDDOWN(E11,0) -> 2544 | G11: : | H11: =(E11-F11)*60 -> 42.352941 | J11: Übernachtung / Hotel | K11: 1-000007 | L11: =Übersicht!$AH$6/(1+Gewinn)/(1+SicherheitAngebot) -> 7000
B13: Montage im Haus | D13: 110 | E13: =Übersicht!$M$33 -> 2182 | J13: Kilometer Firmen-PKW | K13: 1-000008 | L13: =Übersicht!$AI$6/(1+Gewinn)/(1+SicherheitAngebot) -> 0
B15: Montage IBN-Kunde | D15: 150 | E15: =Übersicht!$X$33 -> 220 | J15: Taxi | K15: 1-000009 | L15: =Übersicht!$AK$6/(1+Gewinn)/(1+SicherheitAngebot) -> 0
B17: E-Konstruktion | D17: 170 | E17: =Übersicht!$I$33+Übersicht!$I$36 -> 778 | J17: Leihauto | K17: 1-000010 | L17: =Übersicht!$AL$6/(1+Gewinn)/(1+SicherheitAngebot) -> 3000
B19: Software | D19: 180 | E19: =Übersicht!$J$33+Übersicht!$J$35+Übersicht!$J$36 -> 1207 | J19: Bus/Zug/Fähre | K19: 1-000011 | L19: =Übersicht!$AM$6/(1+Gewinn)/(1+SicherheitAngebot) -> 0
B21: Software-IBN + Schulung im Haus | D21: 190 | E21: =Übersicht!$K$33 -> 1657 | J21: Flüge | K21: 1-000012 | L21: =Übersicht!$AJ$6/(1+Gewinn)/(1+SicherheitAngebot) -> 3500
B23: Software IBN-Kunde + E-Konstruktion | D23: 200 | E23: =Übersicht!$V$33+Übersicht!$U$33 -> 170 | F23: =Übersicht!$U$33 -> 0 | J23: Sonstiges | K23: 1-000013 | L23: =Übersicht!$AN$6/(1+Gewinn)/(1+SicherheitAngebot) -> 0
B25: Elektrik im Haus | D25: 230 | E25: =Übersicht!$L$33 -> 1035 | J25: Zuschläge 25% Arbeits+Reisezeiten | K25: 1-001921 | L25: =Übersicht!$AP$6/(1+Gewinn)/(1+SicherheitAngebot) -> 15652.5
B27: Elektro-Monteur IBN-Kunde | D27: 260 | E27: =Übersicht!$W$33 -> 140 | J27: Versandkosten (Verpackung und Transport) | K27: 1-000537 | L27: =VK!J24 -> 7000
B29: Projektleiter intern | D29: 270 | E29: =Übersicht!$G$35+Übersicht!$G$33 -> 550 | J29: Dokumentation auswärts | K29: 1-000555 | L29: =Allg!$P$21/(1+Gewinn)/(1+SicherheitAngebot) -> 0
B31: Montage Reisezeiten | D31: 340 | E31: =Übersicht!$AE$33 -> 48 | J31: Kalkuliert Netto | L31: =VK!K33 -> 1968824.5
B33: Software Reisezeiten + E-Konstruktion | D33: 350 | E33: =Übersicht!$AB$33+Übersicht!$AC$33 -> 24 | F33: =Übersicht!$AB$33 -> 0 | J33: Gewinn | L33: =Gewinn -> 0
B35: Elektro Monteur Reisezeiten | D35: 360 | E35: =Übersicht!$AD$33 -> 32 | J35: Sicherheit | L35: =Sicherheit -> -0.11114475
B37: M-Konstruktion Reisezeit | D37: 370 | E37: =Übersicht!$AA$33 -> 0 | J37: Projektnachlass Verhandlung | L37: =Projektnachlass -> 0.11114475
B39: Projektleiter Reisezeiten | D39: 380 | E39: =Übersicht!$Z$33 -> 16 | J39: Angebotspreis Abgabe | L39: =VK!K38 -> 1968824.5
B41: Projektleiter IBN-Kunde | D41: 390 | E41: =Übersicht!$S$33 -> 40 | J41: Angebotspreis final | L41: =VK!K37 -> 1750000
J44: Hinweis zu Zuschlägen 25% 1-001921:
B45: =Revision -> MS-F_Rev.:8 / 06.03.25 / S. Schnurrenberger | J45: tauchen in der Nachkalkulation bei den aufgelaufenene Kosten nicht auf!

Sheet Allg
B2: Allgemeine Projektkosten: Projektmanagement - Dokumentation - Verpackung - Versand
B3: =Kunde -> Dräxlmeier Satu Mare | E3: =Übersicht!E3 -> Hr. Eglseder
B4: =Anlage -> Automatic Production Line for Wire Processing | T4: Projektnachlass:
B5: =Angebotsnummer -> A07616000A | D5: =Datum -> 45825 | E5: =Bearbeiter -> Schötz/Radlbeck | T5: =Projektnachlass -> 0.11114475
B7: Pos | C7: Bezeichnung | G7: Bemerkung | I7: Stück | J7: Pl | K7: Doku | L7: MKo | M7: EKo | N7: Sw | O7: KT netto | P7: KT | R7: Summe | T7: Summe
B9: 1 | C9: =Übersicht!C35 -> Projektmanagement/Projektleitung im Haus | I9: =Übersicht!F35 -> 1 | J9: =I9*SUM(J10:J19) -> 550 | L9: =I9*SUM(L10:L19) -> 100 | N9: =I9*SUM(N10:N19) -> 100 | R9: =(J9*Pl+L9*MKo+N9*Sw)*(1+Gewinn)*(1+SicherheitAngebot) -> 81000 | T9: =IF(I$9>0,R9/(1+SicherheitAngebot)*(1+Sicherheit),0) -> 71997.276
C10: Pauschal | J10: 550 | L10: 100 | N10: 100 | R10: =(J10*Pl+L10*MKo+N10*Sw)*(1+Gewinn)*(1+SicherheitAngebot) -> 81000 | T10: =IF(I$9>0,R10/(1+SicherheitAngebot)*(1+Sicherheit),0) -> 71997.276
C11: Kickoff, FMEA, Statusberichte | R11: =(J11*Pl+L11*MKo+N11*Sw)*(1+Gewinn)*(1+SicherheitAngebot) -> 0 | T11: =IF(I$9>0,R11/(1+SicherheitAngebot)*(1+Sicherheit),0) -> 0
C12: Anlagenbesichtigung durch Kunde | R12: =(J12*Pl+L12*MKo+N12*Sw)*(1+Gewinn)*(1+SicherheitAngebot) -> 0 | T12: =IF(I$9>0,R12/(1+SicherheitAngebot)*(1+Sicherheit),0) -> 0
C13: Vorabnahme | R13: =(J13*Pl+L13*MKo+N13*Sw)*(1+Gewinn)*(1+SicherheitAngebot) -> 0 | T13: =IF(I$9>0,R13/(1+SicherheitAngebot)*(1+Sicherheit),0) -> 0
C14: Fotos-Film erstellen | R14: =(J14*Pl+L14*MKo+N14*Sw)*(1+Gewinn)*(1+SicherheitAngebot) -> 0 | T14: =IF(I$9>0,R14/(1+SicherheitAngebot)*(1+Sicherheit),0) -> 0
C15: Versand | R15: =(J15*Pl+L15*MKo+N15*Sw)*(1+Gewinn)*(1+SicherheitAngebot) -> 0 | T15: =IF(I$9>0,R15/(1+SicherheitAngebot)*(1+Sicherheit),0) -> 0
C16: Planung IBN Kunde | R16: =(J16*Pl+L16*MKo+N16*Sw)*(1+Gewinn)*(1+SicherheitAngebot) -> 0 | T16: =IF(I$9>0,R16/(1+SicherheitAngebot)*(1+Sicherheit),0) -> 0
C17: Optimierungen | R17: =(J17*Pl+L17*MKo+N17*Sw)*(1+Gewinn)*(1+SicherheitAngebot) -> 0 | T17: =IF(I$9>0,R17/(1+SicherheitAngebot)*(1+Sicherheit),0) -> 0
C18: Endabnahme - Review | R18: =(J18*Pl+L18*MKo+N18*Sw)*(1+Gewinn)*(1+SicherheitAngebot) -> 0 | T18: =IF(I$9>0,R18/(1+SicherheitAngebot)*(1+Sicherheit),0) -> 0
R19: =(J19*Pl+L19*MKo+N19*Sw)*(1+Gewinn)*(1+SicherheitAngebot) -> 0 | T19: =IF(I$9>0,R19/(1+SicherheitAngebot)*(1+Sicherheit),0) -> 0
B21: 2 | C21: =Übersicht!C36 -> Dokumentation | I21: =Übersicht!F36 -> 1 | K21: =I21*SUM(K22:K31) -> 0 | L21: =I21*SUM(L22:L31) -> 80 | M21: =I21*SUM(M22:M31) -> 50 | N21: =I21*SUM(N22:N31) -> 80 | O21: =I21*SUM(O22:O31) -> 0 | P21: =O21*(1+Gewinn)*(1+SicherheitAngebot) -> 0 | R21: =(K21*Doku+L21*MKo+M21*EKo+N21*Sw)*(1+Gewinn)*(1+SicherheitAngebot)+P21 -> 21000 | T21: =IF(I$21>0,R21/(1+SicherheitAngebot)*(1+Sicherheit),0) -> 18665.96
C22: Pauschal | L22: 80 | M22: 50 | N22: 80 | P22: =O22*(1+Gewinn)*(1+SicherheitAngebot) -> 0 | R22: =(K22*Doku+L22*MKo+M22*EKo+N22*Sw)*(1+Gewinn)*(1+SicherheitAngebot)+P22 -> 21000 | T22: =IF(I$21>0,R22/(1+SicherheitAngebot)*(1+Sicherheit),0) -> 18665.96
C23: Zeichnungen, Stücklisten ausdrucken | G23: Dokumentation | P23: =O23*(1+Gewinn)*(1+SicherheitAngebot) -> 0 | R23: =(K23*Doku+L23*MKo+M23*EKo+N23*Sw)*(1+Gewinn)*(1+SicherheitAngebot)+P23 -> 0 | T23: =IF(I$21>0,R23/(1+SicherheitAngebot)*(1+Sicherheit),0) -> 0
C24: CD, Ordner erstellen | G24: Dokumentation | P24: =O24*(1+Gewinn)*(1+SicherheitAngebot) -> 0 | R24: =(K24*Doku+L24*MKo+M24*EKo+N24*Sw)*(1+Gewinn)*(1+SicherheitAngebot)+P24 -> 0 | T24: =IF(I$21>0,R24/(1+SicherheitAngebot)*(1+Sicherheit),0) -> 0
C25: Bedienfunktionen, Geräteeinstellungen | G25: Software | P25: =O25*(1+Gewinn)*(1+SicherheitAngebot) -> 0 | R25: =(K25*Doku+L25*MKo+M25*EKo+N25*Sw)*(1+Gewinn)*(1+SicherheitAngebot)+P25 -> 0 | T25: =IF(I$21>0,R25/(1+SicherheitAngebot)*(1+Sicherheit),0) -> 0
C26: Betriebsanleitung | G26: Software | P26: =O26*(1+Gewinn)*(1+SicherheitAngebot) -> 0 | R26: =(K26*Doku+L26*MKo+M26*EKo+N26*Sw)*(1+Gewinn)*(1+SicherheitAngebot)+P26 -> 0 | T26: =IF(I$21>0,R26/(1+SicherheitAngebot)*(1+Sicherheit),0) -> 0
C27: Eplan und Stückliste drucken, Ablage am Server | G27: E-Konstruktion | P27: =O27*(1+Gewinn)*(1+SicherheitAngebot) -> 0 | R27: =(K27*Doku+L27*MKo+M27*EKo+N27*Sw)*(1+Gewinn)*(1+SicherheitAngebot)+P27 -> 0 | T27: =IF(I$21>0,R27/(1+SicherheitAngebot)*(1+Sicherheit),0) -> 0
C28: Risikoanalyse, Wartungspläne | G28: M-Konstruktion | P28: =O28*(1+Gewinn)*(1+SicherheitAngebot) -> 0 | R28: =(K28*Doku+L28*MKo+M28*EKo+N28*Sw)*(1+Gewinn)*(1+SicherheitAngebot)+P28 -> 0 | T28: =IF(I$21>0,R28/(1+SicherheitAngebot)*(1+Sicherheit),0) -> 0
C29: Übersetzungskosten | P29: =O29*(1+Gewinn)*(1+SicherheitAngebot) -> 0 | R29: =(K29*Doku+L29*MKo+M29*EKo+N29*Sw)*(1+Gewinn)*(1+SicherheitAngebot)+P29 -> 0 | T29: =IF(I$21>0,R29/(1+SicherheitAngebot)*(1+Sicherheit),0) -> 0
P30: =O30*(1+Gewinn)*(1+SicherheitAngebot) -> 0 | R30: =(K30*Doku+L30*MKo+M30*EKo+N30*Sw)*(1+Gewinn)*(1+SicherheitAngebot)+P30 -> 0 | T30: =IF(I$21>0,R30/(1+SicherheitAngebot)*(1+Sicherheit),0) -> 0
P31: =O31*(1+Gewinn)*(1+SicherheitAngebot) -> 0 | R31: =(K31*Doku+L31*MKo+M31*EKo+N31*Sw)*(1+Gewinn)*(1+SicherheitAngebot)+P31 -> 0 | T31: =IF(I$21>0,R31/(1+SicherheitAngebot)*(1+Sicherheit),0) -> 0
B33: 3 | C33: =Übersicht!C37 -> Verpackung | I33: =Übersicht!F37 -> 1 | O33: =I33*SUM(O34:O43) -> 2000 | R33: =O33*(1+Gewinn)*(1+SicherheitAngebot) -> 2000 | T33: =IF(I$33>0,R33/(1+SicherheitAngebot)*(1+Sicherheit),0) -> 1777.7105
C34: Pauschal | O34: 2000 | R34: =O34*(1+Gewinn)*(1+SicherheitAngebot) -> 2000 | T34: =IF(I$33>0,R34/(1+SicherheitAngebot)*(1+Sicherheit),0) -> 1777.7105
C35: Kiste mit seem. Verpackung 280x240x290cm Tara 600kg | G35: Stand 2020: 862€ | R35: =O35*(1+Gewinn)*(1+SicherheitAngebot) -> 0 | T35: =IF(I$33>0,R35/(1+SicherheitAngebot)*(1+Sicherheit),0) -> 0
C36: Kiste mit seem. Verpackung350x240x285cm Tara 900kg | G36: Stand 2020: 1.260€ | R36: =O36*(1+Gewinn)*(1+SicherheitAngebot) -> 0 | T36: =IF(I$33>0,R36/(1+SicherheitAngebot)*(1+Sicherheit),0) -> 0
C37: Kiste mit seem. Verpackung 410x240x290cm Tara 1000kg | G37: Stand 2020: 1.434€ | R37: =O37*(1+Gewinn)*(1+SicherheitAngebot) -> 0 | T37: =IF(I$33>0,R37/(1+SicherheitAngebot)*(1+Sicherheit),0) -> 0
C38: Frachtkosten für Anlieferung 2-3 Kisten | G38: Stand 2020: 500€ | R38: =O38*(1+Gewinn)*(1+SicherheitAngebot) -> 0 | T38: =IF(I$33>0,R38/(1+SicherheitAngebot)*(1+Sicherheit),0) -> 0
C39: HDEV5 SL 16 nach ChP (5645) 6 Kisten + Frachtkostenp.750,-- | G39: Stand 2020: 10.006€ #5645 | R39: =O39*(1+Gewinn)*(1+SicherheitAngebot) -> 0 | T39: =IF(I$33>0,R39/(1+SicherheitAngebot)*(1+Sicherheit),0) -> 0
C40: Kiste mit seem. Verpackung270x235x290cm Tara 750kg | G40: Stand 2020: 1.049€ #5814 | R40: =O40*(1+Gewinn)*(1+SicherheitAngebot) -> 0 | T40: =IF(I$33>0,R40/(1+SicherheitAngebot)*(1+Sicherheit),0) -> 0
C41: Kiste mit seem. Verpackung430x240x285cm Tara 1050kg | G41: Stand 2020: 1.470€ #5903 | R41: =O41*(1+Gewinn)*(1+SicherheitAngebot) -> 0 | T41: =IF(I$33>0,R41/(1+SicherheitAngebot)*(1+Sicherheit),0) -> 0
C42: Verpackungsmaterial (Holzbalken, Folie, ...) | G42: Stand 2020: 300€ | R42: =O42*(1+Gewinn)*(1+SicherheitAngebot) -> 0 | T42: =IF(I$33>0,R42/(1+SicherheitAngebot)*(1+Sicherheit),0) -> 0
R43: =O43*(1+Gewinn)*(1+SicherheitAngebot) -> 0 | T43: =IF(I$33>0,R43/(1+SicherheitAngebot)*(1+Sicherheit),0) -> 0
B45: 4 | C45: =Übersicht!C38 -> Versand | I45: =Übersicht!F38 -> 1 | O45: =I45*SUM(O46:O55) -> 5000 | R45: =O45*(1+Gewinn)*(1+SicherheitAngebot) -> 5000 | T45: =IF(I$45>0,R45/(1+SicherheitAngebot)*(1+Sicherheit),0) -> 4444.2763
C46: Pauschal | R46: =O46*(1+Gewinn)*(1+SicherheitAngebot) -> 0 | T46: =IF(I$45>0,R46/(1+SicherheitAngebot)*(1+Sicherheit),0) -> 0
...

Sheet 1
B2: M01 | C2: =Übersicht!C12 -> Automatic Production Line | G2: Modulkalkulation | H2: =Übersicht!F12 -> 1 | U2: =U8*$H2 -> 1630230 | V2: + | AV2: =AV8*$H2 -> 95974.5 | AW2: = | AX2: =AX8*$H2 -> 1726204.5 | AZ2: =AZ8*$H2 -> 1449038.5 | BA2: + | BB2: =BB8*$H2 -> 85307.439 | BC2: = | BD2: =BD8*$H2 -> 1534345.9
B3: =Kunde -> Dräxlmeier Satu Mare | E3: =Übersicht!E3 -> Hr. Eglseder | G3: =Revision -> MS-F_Rev.:8 / 06.03.25 / S. Schnurrenberger | AZ3: Projektnachlass:
B4: =Anlage -> Automatic Production Line for Wire Processing | AZ4: =Projektnachlass -> 0.11114475
B5: =Angebotsnummer -> A07616000A | D5: =Datum -> 45825 | E5: =Bearbeiter -> Schötz/Radlbeck | I5: Arbeitszeiten im Haus | W5: Arbeitszeiten vor Ort | AD5: Reisezeiten | AK5: Auslösen, Hotel, Anfahrt, Flüge...
C6: Bemerkung bzw. Layout/Bild | I6: =I8*I7 -> 0 | J6: =J8*J7 -> 212600 | K6: =K8*K7 -> 60076 | L6: =L8*L7 -> 96810 | M6: =M8*M7 -> 159810 | N6: =N8*N7 -> 78310 | O6: =O8*O7 -> 162114 | P6: Summen in € | R6: =SUM(R12,R29,R46,R63,R80,R97,R114,R131,R148,R165,R182,R199,R216,R233,R250,R267,R284,R301,R318,R335,R352,R369,R386,R403,R420,R437,R454,R471,R488,R505) -> 207000 | S6: =SUM(S12,S29,S46,S63,S80,S97,S114,S131,S148,S165,S182,S199,S216,S233,S250,S267,S284,S301,S318,S335,S352,S369,S386,S403,S420,S437,S454,S471,S488,S505) -> 653510 | W6: =W8*W7 -> 4400 | X6: =X8*X7 -> 0 | Y6: =Y8*Y7 -> 0 | Z6: =Z8*Z7 -> 17850 | AA6: =AA8*AA7 -> 11480 | AB6: =AB8*AB7 -> 18040 | AD6: =AD8*AD7 -> 1760 | AE6: =AE8*AE7 -> 0 | AF6: =AF8*AF7 -> 0 | AG6: =AG8*AG7 -> 2520 | AH6: =AH8*AH7 -> 2624 | AI6: =AI8*AI7 -> 3936 | AK6: =AK8*AK7 -> 4212 | AL6: =AL8*AL7 -> 7000 | AM6: =AM8*AM7 -> 0 | AN6: =SUM(AN12,AN29,AN46,AN63,AN80,AN97,AN114,AN131,AN148,AN165,AN182,AN199,AN216,AN233,AN250,AN267,AN284,AN301,AN318,AN335,AN352,AN369,AN386,AN403,AN420,AN437,AN454,AN471,AN488,AN505) -> 3500 | AO6: =SUM(AO12,AO29,AO46,AO63,AO80,AO97,AO114,AO131,AO148,AO165,AO182,AO199,AO216,AO233,AO250,AO267,AO284,AO301,AO318,AO335,AO352,AO369,AO386,AO403,AO420,AO437,AO454,AO471,AO488,AO505) -> 0 | AP6: =SUM(AP12,AP29,AP46,AP63,AP80,AP97,AP114,AP131,AP148,AP165,AP182,AP199,AP216,AP233,AP250,AP267,AP284,AP301,AP318,AP335,AP352,AP369,AP386,AP403,AP420,AP437,AP454,AP471,AP488,AP505) -> 3000 | AQ6: =SUM(AQ12,AQ29,AQ46,AQ63,AQ80,AQ97,AQ114,AQ131,AQ148,AQ165,AQ182,AQ199,AQ216,AQ233,AQ250,AQ267,AQ284,AQ301,AQ318,AQ335,AQ352,AQ369,AQ386,AQ403,AQ420,AQ437,AQ454,AQ471,AQ488,AQ505) -> 0 | AR6: =SUM(AR12,AR29,AR46,AR63,AR80,AR97,AR114,AR131,AR148,AR165,AR182,AR199,AR216,AR233,AR250,AR267,AR284,AR301,AR318,AR335,AR352,AR369,AR386,AR403,AR420,AR437,AR454,AR471,AR488,AR505) -> 0 | AT6: =SUM(AT12,AT29,AT46,AT63,AT80,AT97,AT114,AT131,AT148,AT165,AT182,AT199,AT216,AT233,AT250,AT267,AT284,AT301,AT318,AT335,AT352,AT369,AT386,AT403,AT420,AT437,AT454,AT471,AT488,AT505) -> 15652.5
I7: =Pl*(1+Gewinn)*(1+SicherheitAngebot) -> 110 | J7: =MKo*(1+Gewinn)*(1+SicherheitAngebot) -> 100 | K7: =EKo*(1+Gewinn)*(1+SicherheitAngebot) -> 92 | L7: =Sw*(1+Gewinn)*(1+SicherheitAngebot) -> 105 | M7: =Inb*(1+Gewinn)*(1+SicherheitAngebot) -> 105 | N7: =El*(1+Gewinn)*(1+SicherheitAngebot) -> 82 | O7: =Mo*(1+Gewinn)*(1+SicherheitAngebot) -> 82 | P7: Gewinn | Q7: =Gewinn -> 0 | R7: =TF*(1+Gewinn)*(1+SicherheitAngebot) -> 85 | S7: MGKZ | U7: Einzelpreis | W7: =Pl*(1+Gewinn)*(1+SicherheitAngebot) -> 110 | X7: =MKo*(1+Gewinn)*(1+SicherheitAngebot) -> 100 | Y7: =Inb*(1+Gewinn)*(1+SicherheitAngebot) -> 105 | Z7: =Inb*(1+Gewinn)*(1+SicherheitAngebot) -> 105 | AA7: =El*(1+Gewinn)*(1+SicherheitAngebot) -> 82 | AB7: =Mo*(1+Gewinn)*(1+SicherheitAngebot) -> 82 | AD7: =Pl*(1+Gewinn)*(1+SicherheitAngebot) -> 110 | AE7: =MKo*(1+Gewinn)*(1+SicherheitAngebot) -> 100 | AF7: =Inb*(1+Gewinn)*(1+SicherheitAngebot) -> 105 | AG7: =Inb*(1+Gewinn)*(1+SicherheitAngebot) -> 105 | AH7: =El*(1+Gewinn)*(1+SicherheitAngebot) -> 82 | AI7: =Mo*(1+Gewinn)*(1+SicherheitAngebot) -> 82 | AK7: =Auslöse*(1+Gewinn)*(1+SicherheitAngebot) -> 52 | AL7: =Hotel*(1+Gewinn)*(1+SicherheitAngebot) -> 100 | AM7: =KM_Pauschale*(1+Gewinn)*(1+SicherheitAngebot) -> 0.6 | AN7: Flüge | AO7: Taxi | AP7: Leihauto | AQ7: Bus/Zug/F | AR7: Sonstiges | AT7: =Zuschläge_IBN -> 0.25 | AV7: Einzelpreis | AX7: Einzelpreis | AZ7: Einzelpreis | BB7: Einzelpreis | BD7: Einzelpreis
I8: =SUM(I12,I29,I46,I63,I80,I97,I114,I131,I148,I165,I182,I199,I216,I233,I250,I267,I284,I301,I318,I335,I352,I369,I386,I403,I420,I437,I454,I471,I488,I505) -> 0 | J8: =SUM(J12,J29,J46,J63,J80,J97,J114,J131,J148,J165,J182,J199,J216,J233,J250,J267,J284,J301,J318,J335,J352,J369,J386,J403,J420,J437,J454,J471,J488,J505) -> 2126 | K8: =SUM(K12,K29,K46,K63,K80,K97,K114,K131,K148,K165,K182,K199,K216,K233,K250,K267,K284,K301,K318,K335,K352,K369,K386,K403,K420,K437,K454,K471,K488,K505) -> 653 | L8: =SUM(L12,L29,L46,L63,L80,L97,L114,L131,L148,L165,L182,L199,L216,L233,L250,L267,L284,L301,L318,L335,L352,L369,L386,L403,L420,L437,L454,L471,L488,L505) -> 922 | M8: =SUM(M12,M29,M46,M63,M80,M97,M114,M131,M148,M165,M182,M199,M216,M233,M250,M267,M284,M301,M318,M335,M352,M369,M386,M403,M420,M437,M454,M471,M488,M505) -> 1522 | N8: =SUM(N12,N29,N46,N63,N80,N97,N114,N131,N148,N165,N182,N199,N216,N233,N250,N267,N284,N301,N318,N335,N352,N369,N386,N403,N420,N437,N454,N471,N488,N505) -> 955 | O8: =SUM(O12,O29,O46,O63,O80,O97,O114,O131,O148,O165,O182,O199,O216,O233,O250,O267,O284,O301,O318,O335,O352,O369,O386,O403,O420,O437,O454,O471,O488,O505) -> 1977 | P8: Sicherheit | Q8: =SicherheitAngebot -> 0 | R8: =R6/R7 -> 2435.2941 | S8: =MGKZ -> 0.1 | U8: =SUM(U12,U29,U46,U63,U80,U97,U114,U131,U148,U165,U182,U199,U216,U233,U250,U267,U284,U301,U318,U335,U352,U369,U386,U403,U420,U437,U454,U471,U488,U505) -> 1630230 | V8: + | W8: =SUM(W12,W29,W46,W63,W80,W97,W114,W131,W148,W165,W182,W199,W216,W233,W250,W267,W284,W301,W318,W335,W352,W369,W386,W403,W420,W437,W454,W471,W488,W505) -> 40 | X8: =SUM(X12,X29,X46,X63,X80,X97,X114,X131,X148,X165,X182,X199,X216,X233,X250,X267,X284,X301,X318,X335,X352,X369,X386,X403,X420,X437,X454,X471,X488,X505) -> 0 | Y8: =SUM(Y12,Y29,Y46,Y63,Y80,Y97,Y114,Y131,Y148,Y165,Y182,Y199,Y216,Y233,Y250,Y267,Y284,Y301,Y318,Y335,Y352,Y369,Y386,Y403,Y420,Y437,Y454,Y471,Y488,Y505) -> 0 | Z8: =SUM(Z12,Z29,Z46,Z63,Z80,Z97,Z114,Z131,Z148,Z165,Z182,Z199,Z216,Z233,Z250,Z267,Z284,Z301,Z318,Z335,Z352,Z369,Z386,Z403,Z420,Z437,Z454,Z471,Z488,Z505) -> 170 | AA8: =SUM(AA12,AA29,AA46,AA63,AA80,AA97,AA114,AA131,AA148,AA165,AA182,AA199,AA216,AA233,AA250,AA267,AA284,AA301,AA318,AA335,AA352,AA369,AA386,AA403,AA420,AA437,AA454,AA471,AA488,AA505) -> 140 | AB8: =SUM(AB12,AB29,AB46,AB63,AB80,AB97,AB114,AB131,AB148,AB165,AB182,AB199,AB216,AB233,AB250,AB267,AB284,AB301,AB318,AB335,AB352,AB369,AB386,AB403,AB420,AB437,AB454,AB471,AB488,AB505) -> 220 | AD8: =SUM(AD12,AD29,AD46,AD63,AD80,AD97,AD114,AD131,AD148,AD165,AD182,AD199,AD216,AD233,AD250,AD267,AD284,AD301,AD318,AD335,AD352,AD369,AD386,AD403,AD420,AD437,AD454,AD471,AD488,AD505) -> 16 | AE8: =SUM(AE12,AE29,AE46,AE63,AE80,AE97,AE114,AE131,AE148,AE165,AE182,AE199,AE216,AE233,AE250,AE267,AE284,AE301,AE318,AE335,AE352,AE369,AE386,AE403,AE420,AE437,AE454,AE471,AE488,AE505) -> 0 | AF8: =SUM(AF12,AF29,AF46,AF63,AF80,AF97,AF114,AF131,AF148,AF165,AF182,AF199,AF216,AF233,AF250,AF267,AF284,AF301,AF318,AF335,AF352,AF369,AF386,AF403,AF420,AF437,AF454,AF471,AF488,AF505) -> 0 | AG8: =SUM(AG12,AG29,AG46,AG63,AG80,AG97,AG114,AG131,AG148,AG165,AG182,AG199,AG216,AG233,AG250,AG267,AG284,AG301,AG318,AG335,AG352,AG369,AG386,AG403,AG420,AG437,AG454,AG471,AG488,AG505) -> 24 | AH8: =SUM(AH12,AH29,AH46,AH63,AH80,AH97,AH114,AH131,AH148,AH165,AH182,AH199,AH216,AH233,AH250,AH267,AH284,AH301,AH318,AH335,AH352,AH369,AH386,AH403,AH420,AH437,AH454,AH471,AH488,AH505) -> 32 | AI8: =SUM(AI12,AI29,AI46,AI63,AI80,AI97,AI114,AI131,AI148,AI165,AI182,AI199,AI216,AI233,AI250,AI267,AI284,AI301,AI318,AI335,AI352,AI369,AI386,AI403,AI420,AI437,AI454,AI471,AI488,AI505) -> 48 | AK8: =SUM(AK12,AK29,AK46,AK63,AK80,AK97,AK114,AK131,AK148,AK165,AK182,AK199,AK216,AK233,AK250,AK267,AK284,AK301,AK318,AK335,AK352,AK369,AK386,AK403,AK420,AK437,AK454,AK471,AK488,AK505) -> 81 | AL8: =SUM(AL12,AL29,AL46,AL63,AL80,AL97,AL114,AL131,AL148,AL165,AL182,AL199,AL216,AL233,AL250,AL267,AL284,AL301,AL318,AL335,AL352,AL369,AL386,AL403,AL420,AL437,AL454,AL471,AL488,AL505) -> 70 | AM8: =SUM(AM12,AM29,AM46,AM63,AM80,AM97,AM114,AM131,AM148,AM165,AM182,AM199,AM216,AM233,AM250,AM267,AM284,AM301,AM318,AM335,AM352,AM369,AM386,AM403,AM420,AM437,AM454,AM471,AM488,AM505) -> 0 | AV8: =SUM(AV12,AV29,AV46,AV63,AV80,AV97,AV114,AV131,AV148,AV165,AV182,AV199,AV216,AV233,AV250,AV267,AV284,AV301,AV318,AV335,AV352,AV369,AV386,AV403,AV420,AV437,AV454,AV471,AV488,AV505) -> 95974.5 | AW8: = | AX8: =SUM(AX12,AX29,AX46,AX63,AX80,AX97,AX114,AX131,AX148,AX165,AX182,AX199,AX216,AX233,AX250,AX267,AX284,AX301,AX318,AX335,AX352,AX369,AX386,AX403,AX420,AX437,AX454,AX471,AX488,AX505) -> 1726204.5 | AZ8: =SUM(AZ12,AZ29,AZ46,AZ63,AZ80,AZ97,AZ114,AZ131,AZ148,AZ165,AZ182,AZ199,AZ216,AZ233,AZ250,AZ267,AZ284,AZ301,AZ318,AZ335,AZ352,AZ369,AZ386,AZ403,AZ420,AZ437,AZ454,AZ471,AZ488,AZ505) -> 1449038.5 | BA8: + | BB8: =SUM(BB12,BB29,BB46,BB63,BB80,BB97,BB114,BB131,BB148,BB165,BB182,BB199,BB216,BB233,BB250,BB267,BB284,BB301,BB318,BB335,BB352,BB369,BB386,BB403,BB420,BB437,BB454,BB471,BB488,BB505) -> 85307.439 | BC8: = | BD8: =SUM(BD12,BD29,BD46,BD63,BD80,BD97,BD114,BD131,BD148,BD165,BD182,BD199,BD216,BD233,BD250,BD267,BD284,BD301,BD318,BD335,BD352,BD369,BD386,BD403,BD420,BD437,BD454,BD471,BD488,BD505) -> 1534345.9
B10: Pos | C10: Bezeichnung | G10: Bemerkung | H10: Stück | I10: Pl | J10: MK | K10: EKo | L10: Sw | M10: Inb | N10: El | O10: Mo | P10: TF netto | Q10: KT netto | R10: TF | S10: KT | U10: Summe | W10: Pl | X10: MKo | Y10: EKo | Z10: Inb | AA10: El | AB10: Mo | AD10: Pl | AE10: MKo | AF10: EKo | AG10: Inb | AH10: El | AI10: Mo | AK10: Auslöse | AL10: Hotel | AM10: Anfahrt-km | AN10: Flugkosten | AO10: Taxi | AP10: Leihauto | AQ10: Bus/Zug... | AR10: Sonstiges | AT10: Zuschläge | AV10: IBN | AX10: Angebot | AZ10: Summe % | BB10: IBN % | BD10: Angebot %
B12: 1 | C12: Cutting Cable | H12: 1 | I12: =$H12*SUM(I13:I27) -> 0 | J12: =$H12*SUM(J13:J27) -> 286 | K12: =$H12*SUM(K13:K27) -> 76 | L12: =$H12*SUM(L13:L27) -> 108 | M12: =$H12*SUM(M13:M27) -> 130 | N12: =$H12*SUM(N13:N27) -> 67 | O12: =$H12*SUM(O13:O27) -> 160 | P12: =$H12*SUM(P13:P27) -> 11900 | Q12: =$H12*SUM(Q13:Q27) -> 53000 | R12: =P12*(1+Gewinn)*(1+SicherheitAngebot) -> 11900 | S12: =Q12*(1+MGKZ)*(1+Gewinn)*(1+SicherheitAngebot) -> 58300 | U12: =I12*$I$7+J12*$J$7+K12*$K$7+L12*$L$7+M12*$M$7+N12*$N$7+O12*$O$7+R12+S12 -> 149396 | W12: =$H12*SUM(W13:W27) -> 0 | X12: =$H12*SUM(X13:X27) -> 0 | Y12: =$H12*SUM(Y13:Y27) -> 0 | Z12: =$H12*SUM(Z13:Z27) -> 0 | AA12: =$H12*SUM(AA13:AA27) -> 0 | AB12: =$H12*SUM(AB13:AB27) -> 0 | AD12: =$H12*SUM(AD13:AD27) -> 0 | AE12: =$H12*SUM(AE13:AE27) -> 0 | AF12: =$H12*SUM(AF13:AF27) -> 0 | AG12: =$H12*SUM(AG13:AG27) -> 0 | AH12: =$H12*SUM(AH13:AH27) -> 0 | AI12: =$H12*SUM(AI13:AI27) -> 0 | AK12: =$H12*SUM(AK13:AK27) -> 0 | AL12: =$H12*SUM(AL13:AL27) -> 0 | AM12: =$H12*SUM(AM13:AM27) -> 0 | AN12: =$H12*SUM(AN13:AN27)*(1+Gewinn)*(1+SicherheitAngebot) -> 0 | AO12: =$H12*SUM(AO13:AO27)*(1+Gewinn)*(1+SicherheitAngebot) -> 0 | AP12: =$H12*SUM(AP13:AP27)*(1+Gewinn)*(1+SicherheitAngebot) -> 0 | AQ12: =$H12*SUM(AQ13:AQ27)*(1+Gewinn)*(1+SicherheitAngebot) -> 0 | AR12: =$H12*SUM(AR13:AR27)*(1+Gewinn)*(1+SicherheitAngebot) -> 0 | AT12: =((W12+AD12)*$W$7+(X12+AE12)*$X$7+(Y12+Z12+AF12+AG12)*$Z$7+(AA12+AH12)*$AA$7+(AB12+AI12)*$AB$7)*Zuschläge_IBN -> 0 | AV12: =AK12*$AK$7+AL12*$AL$7+AM12*$AM$7+SUM(AN12:AR12)+AT12/Zuschläge_IBN+AT12 -> 0 | AX12: =U12+AV12 -> 149396 | AZ12: =IF(H12>0,U12/(1+SicherheitAngebot)*(1+Sicherheit),0) -> 132791.42 | BB12: =IF(H12>0,AV12/(1+SicherheitAngebot)*(1+Sicherheit),0) -> 0 | BD12: =AZ12+BB12 -> 132791.42
C13: Cable supply on Coil | G13: Zukaufteil + Softwareschnittstelle (Kabelabwickler RAMA 800 / 18 Firma Metzner) | J13: 25 | K13: 15 | L13: 15 | M13: 20 | N13: 10 | O13: 20 | P13: 200 | Q13: 35000 | R13: =P13*(1+Gewinn)*(1+SicherheitAngebot) -> 200 | S13: =Q13*(1+MGKZ)*(1+Gewinn)*(1+SicherheitAngebot) -> 38500 | U13: =I13*$I$7+J13*$J$7+K13*$K$7+L13*$L$7+M13*$M$7+N13*$N$7+O13*$O$7+R13+S13 -> 48715 | AT13: =((W13+AD13)*$W$7+(X13+AE13)*$X$7+(Y13+Z13+AF13+AG13)*$Z$7+(AA13+AH13)*$AA$7+(AB13+AI13)*$AB$7)*Zuschläge_IBN -> 0 | AV13: =AK13*$AK$7+AL13*$AL$7+AM13*$AM$7+SUM(AN13:AR13)*(1+Gewinn)*(1+SicherheitAngebot)+AT13/Zuschläge_IBN+AT13 -> 0 | AX13: =U13+AV13 -> 48715 | AZ13: =U13/(1+SicherheitAngebot)*(1+Sicherheit) -> 43300.584 | BB13: =AV13/(1+SicherheitAngebot)*(1+Sicherheit) -> 0 | BD13: =AZ13+BB13 -> 43300.584
C14: Cutting Unit | J14: 100 | K14: 30 | L14: 30 | M14: 40 | N14: 20 | O14: 50 | P14: 2500 | Q14: 5000 | R14: =P14*(1+Gewinn)*(1+SicherheitAngebot) -> 2500 | S14: =Q14*(1+MGKZ)*(1+Gewinn)*(1+SicherheitAngebot) -> 5500 | U14: =I14*$I$7+J14*$J$7+K14*$K$7+L14*$L$7+M14*$M$7+N14*$N$7+O14*$O$7+R14+S14 -> 33850 | AT14: =((W14+AD14)*$W$7+(X14+AE14)*$X$7+(Y14+Z14+AF14+AG14)*$Z$7+(AA14+AH14)*$AA$7+(AB14+AI14)*$AB$7)*Zuschläge_IBN -> 0 | AV14: =AK14*$AK$7+AL14*$AL$7+AM14*$AM$7+SUM(AN14:AR14)*(1+Gewinn)*(1+SicherheitAngebot)+AT14/Zuschläge_IBN+AT14 -> 0 | AX14: =U14+AV14 -> 33850 | AZ14: =U14/(1+SicherheitAngebot)*(1+Sicherheit) -> 30087.75 | BB14: =AV14/(1+SicherheitAngebot)*(1+Sicherheit) -> 0 | BD14: =AZ14+BB14 -> 30087.75
