Workbook
Name Angebotsnummer: Übersicht!$C$5
Name Anlage: Übersicht!$C$4
Name Bearbeiter: Übersicht!$E$5
Name Datum: Übersicht!$D$5
Name Dokumentation: Grafik!$F$12
Name Elektrik: Grafik!$F$20
Name Fertigung: Grafik!$F$19
Name Gesamtpreis: Übersicht!$V$41
Name Gewinn: Grafik!$D$6
Name Hardware: Grafik!$F$13
Name INB: Grafik!$F$15
Name Konstruktion: Grafik!$F$11
Name Kunde: Übersicht!$C$3
Name MGKZ: Grafik!$D$5
Name Montage: Grafik!$F$18
Name Projektleitung: Grafik!$F$17
Name Sicherheit: Grafik!$E$7
Name Software: Grafik!$F$14
Name Verhandlungsspielraum: Grafik!$D$7

Sheet Übersicht
C2: Preisübersicht
C3: BMW Leipzig | E3: Pascal Böhme
C4: Schulung Hochlaufunterstützung
C5: A07614700 | D5: 45642 | E5: Harald Waas | G5: M-Konstruktion | I5: E-Konstruktion | K5: Software | M5: Inbetriebnahme | O5: SSB/Installation | Q5: Montage | S5: Fertigung | U5: Material | V5: Summe (VK) | X5: Angebotspreis
B6: Benennung | F6: Stück | G6: Std | H6: € | I6: Std | J6: € | K6: Std | L6: € | M6: Std | N6: € | O6: Std | P6: € | Q6: Std | R6: € | S6: Std | T6: € | U6: VK / €
B8: 1 | F8: 1 | G8: =IF(F8=0,"0",'1'!$D$6) -> 0 | H8: =IF(F8=0,"0",'1'!$F$6) -> 0 | I8: =IF(F8=0,"0",'1'!$L$6) -> 0 | J8: =IF(F8=0,"0",'1'!$O$6) -> 0 | K8: =IF(F8=0,"0",'1'!$L$7) -> 0 | L8: =IF(F8=0,"0",'1'!$O$7) -> 0 | M8: =F8*'1'!$L$8 -> 0 | N8: =F8*'1'!$O$8 -> 0 | O8: =F8*'1'!$L$9 -> 0 | P8: =F8*'1'!$O$9 -> 0 | Q8: =F8*'1'!$D$7 -> 0 | R8: =F8*'1'!$F$7 -> 0 | S8: =F8*'1'!$D$8 -> 0 | T8: =F8*'1'!$F$8 -> 0 | U8: =F8*'1'!$F$9 -> 0 | V8: =H8+J8+L8+N8+P8+R8+T8+U8 -> 0 | X8: =IF(F8>0,V8,0) -> 0
B9: 2 | F9: 0 | G9: =IF(F9=0,"0",'2'!$D$6) -> 0 | H9: =IF(F9=0,"0",'2'!$F$6) -> 0 | I9: =IF(F9=0,"0",'2'!$L$6) -> 0 | J9: =IF(F9=0,"0",'2'!$O$6) -> 0 | K9: =IF(F9=0,"0",'2'!$L$7) -> 0 | L9: =IF(F9=0,"0",'2'!$O$7) -> 0 | M9: =F9*'2'!$L$8 -> 0 | N9: =F9*'2'!$O$8 -> 0 | O9: =F9*'2'!$L$9 -> 0 | P9: =F9*'2'!$O$9 -> 0 | Q9: =F9*'2'!$D$7 -> 0 | R9: =F9*'2'!$F$7 -> 0 | S9: =F9*'2'!$D$8 -> 0 | T9: =F9*'2'!$F$8 -> 0 | U9: =F9*'2'!$F$9 -> 0 | V9: =H9+J9+L9+N9+P9+R9+T9+U9 -> 0 | X9: =IF(F9>0,V9,0) -> 0
B10: 3 | F10: 1 | G10: =IF(F10=0,"0",'3'!$D$6) -> 0 | H10: =IF(F10=0,"0",'3'!$F$6) -> 0 | I10: =IF(F10=0,"0",'3'!$L$6) -> 0 | J10: =IF(F10=0,"0",'3'!$O$6) -> 0 | K10: =IF(F10=0,"0",'3'!$L$7) -> 0 | L10: =IF(F10=0,"0",'3'!$O$7) -> 0 | M10: =F10*'3'!$L$8 -> 0 | N10: =F10*'3'!$O$8 -> 0 | O10: =F10*'3'!$L$9 -> 0 | P10: =F10*'3'!$O$9 -> 0 | Q10: =F10*'3'!$D$7 -> 0 | R10: =F10*'3'!$F$7 -> 0 | S10: =F10*'3'!$D$8 -> 0 | T10: =F10*'3'!$F$8 -> 0 | U10: =F10*'3'!$F$9 -> 0 | V10: =H10+J10+L10+N10+P10+R10+T10+U10 -> 0 | X10: =IF(F10>0,V10,0) -> 0
B11: 4 | C11: Modul 04 leer | F11: 1 | G11: =IF(F11=0,"0",'4'!$D$6) -> 0 | H11: =IF(F11=0,"0",'4'!$F$6) -> 0 | I11: =IF(F11=0,"0",'4'!$L$6) -> 0 | J11: =IF(F11=0,"0",'4'!$O$6) -> 0 | K11: =IF(F11=0,"0",'4'!$L$7) -> 0 | L11: =IF(F11=0,"0",'4'!$O$7) -> 0 | M11: =F11*'4'!$L$8 -> 0 | N11: =F11*'4'!$O$8 -> 0 | O11: =F11*'4'!$L$9 -> 0 | P11: =F11*'4'!$O$9 -> 0 | Q11: =F11*'4'!$D$7 -> 0 | R11: =F11*'4'!$F$7 -> 0 | S11: =F11*'4'!$D$8 -> 0 | T11: =F11*'4'!$F$8 -> 0 | U11: =F11*'4'!$F$9 -> 0 | V11: =H11+J11+L11+N11+P11+R11+T11+U11 -> 0 | X11: =IF(F11>0,V11,0) -> 0
B12: 5 | C12: Modul 05 leer | F12: 1 | G12: =IF(F12=0,"0",'5'!$D$6) -> 0 | H12: =IF(F12=0,"0",'5'!$F$6) -> 0 | I12: =IF(F12=0,"0",'5'!$L$6) -> 0 | J12: =IF(F12=0,"0",'5'!$O$6) -> 0 | K12: =IF(F12=0,"0",'5'!$L$7) -> 0 | L12: =IF(F12=0,"0",'5'!$O$7) -> 0 | M12: =F12*'5'!$L$8 -> 0 | N12: =F12*'5'!$O$8 -> 0 | O12: =F12*'5'!$L$9 -> 0 | P12: =F12*'5'!$O$9 -> 0 | Q12: =F12*'5'!$D$7 -> 0 | R12: =F12*'5'!$F$7 -> 0 | S12: =F12*'5'!$D$8 -> 0 | T12: =F12*'5'!$F$8 -> 0 | U12: =F12*'5'!$F$9 -> 0 | V12: =H12+J12+L12+N12+P12+R12+T12+U12 -> 0 | X12: =IF(F12>0,V12,0) -> 0
B13: 6 | C13: Modul 06 leer | F13: 1 | G13: =IF(F13=0,"0",'6'!$D$6) -> 0 | H13: =IF(F13=0,"0",'6'!$F$6) -> 0 | I13: =IF(F13=0,"0",'6'!$L$6) -> 0 | J13: =IF(F13=0,"0",'6'!$O$6) -> 0 | K13: =IF(F13=0,"0",'6'!$L$7) -> 0 | L13: =IF(F13=0,"0",'6'!$O$7) -> 0 | M13: =F13*'6'!$L$8 -> 0 | N13: =F13*'6'!$O$8 -> 0 | O13: =F13*'6'!$L$9 -> 0 | P13: =F13*'6'!$O$9 -> 0 | Q13: =F13*'6'!$D$7 -> 0 | R13: =F13*'6'!$F$7 -> 0 | S13: =F13*'6'!$D$8 -> 0 | T13: =F13*'6'!$F$8 -> 0 | U13: =F13*'6'!$F$9 -> 0 | V13: =H13+J13+L13+N13+P13+R13+T13+U13 -> 0 | X13: =IF(F13>0,V13,0) -> 0
B14: 7 | C14: Modul 07 leer | F14: 1 | G14: =IF(F14=0,"0",'7'!$D$6) -> 0 | H14: =IF(F14=0,"0",'7'!$F$6) -> 0 | I14: =IF(F14=0,"0",'7'!$L$6) -> 0 | J14: =IF(F14=0,"0",'7'!$O$6) -> 0 | K14: =IF(F14=0,"0",'7'!$L$7) -> 0 | L14: =IF(F14=0,"0",'7'!$O$7) -> 0 | M14: =F14*'7'!$L$8 -> 0 | N14: =F14*'7'!$O$8 -> 0 | O14: =F14*'7'!$L$9 -> 0 | P14: =F14*'7'!$O$9 -> 0 | Q14: =F14*'7'!$D$7 -> 0 | R14: =F14*'7'!$F$7 -> 0 | S14: =F14*'7'!$D$8 -> 0 | T14: =F14*'7'!$F$8 -> 0 | U14: =F14*'7'!$F$9 -> 0 | V14: =H14+J14+L14+N14+P14+R14+T14+U14 -> 0 | X14: =IF(F14>0,V14,0) -> 0
B15: 8 | C15: Modul 08 leer | F15: 1 | G15: =IF(F15=0,"0",'8'!$D$6) -> 0 | H15: =IF(F15=0,"0",'8'!$F$6) -> 0 | I15: =IF(F15=0,"0",'8'!$L$6) -> 0 | J15: =IF(F15=0,"0",'8'!$O$6) -> 0 | K15: =IF(F15=0,"0",'8'!$L$7) -> 0 | L15: =IF(F15=0,"0",'8'!$O$7) -> 0 | M15: =F15*'8'!$L$8 -> 0 | N15: =F15*'8'!$O$8 -> 0 | O15: =F15*'8'!$L$9 -> 0 | P15: =F15*'8'!$O$9 -> 0 | Q15: =F15*'8'!$D$7 -> 0 | R15: =F15*'8'!$F$7 -> 0 | S15: =F15*'8'!$D$8 -> 0 | T15: =F15*'8'!$F$8 -> 0 | U15: =F15*'8'!$F$9 -> 0 | V15: =H15+J15+L15+N15+P15+R15+T15+U15 -> 0 | X15: =IF(F15>0,V15,0) -> 0
B16: 9 | C16: Modul 09 leer | F16: 1 | G16: =IF(F16=0,"0",'9'!$D$6) -> 0 | H16: =IF(F16=0,"0",'9'!$F$6) -> 0 | I16: =IF(F16=0,"0",'9'!$L$6) -> 0 | J16: =IF(F16=0,"0",'9'!$O$6) -> 0 | K16: =IF(F16=0,"0",'9'!$L$7) -> 0 | L16: =IF(F16=0,"0",'9'!$O$7) -> 0 | M16: =F16*'9'!$L$8 -> 0 | N16: =F16*'9'!$O$8 -> 0 | O16: =F16*'9'!$L$9 -> 0 | P16: =F16*'9'!$O$9 -> 0 | Q16: =F16*'9'!$D$7 -> 0 | R16: =F16*'9'!$F$7 -> 0 | S16: =F16*'9'!$D$8 -> 0 | T16: =F16*'9'!$F$8 -> 0 | U16: =F16*'9'!$F$9 -> 0 | V16: =H16+J16+L16+N16+P16+R16+T16+U16 -> 0 | X16: =IF(F16>0,V16,0) -> 0
B17: 10 | C17: Modul 10 leer | F17: 1 | G17: =IF(F17=0,"0",'10'!$D$6) -> 0 | H17: =IF(F17=0,"0",'10'!$F$6) -> 0 | I17: =IF(F17=0,"0",'10'!$L$6) -> 0 | J17: =IF(F17=0,"0",'10'!$O$6) -> 0 | K17: =IF(F17=0,"0",'10'!$L$7) -> 0 | L17: =IF(F17=0,"0",'10'!$O$7) -> 0 | M17: =F17*'10'!$L$8 -> 0 | N17: =F17*'10'!$O$8 -> 0 | O17: =F17*'10'!$L$9 -> 0 | P17: =F17*'10'!$O$9 -> 0 | Q17: =F17*'10'!$D$7 -> 0 | R17: =F17*'10'!$F$7 -> 0 | S17: =F17*'10'!$D$8 -> 0 | T17: =F17*'10'!$F$8 -> 0 | U17: =F17*'10'!$F$9 -> 0 | V17: =H17+J17+L17+N17+P17+R17+T17+U17 -> 0 | X17: =IF(F17>0,V17,0) -> 0
B18: 11 | C18: Modul 11 leer | F18: 1 | G18: =IF(F18=0,"0",'11'!$D$6) -> 0 | H18: =IF(F18=0,"0",'11'!$F$6) -> 0 | I18: =IF(F18=0,"0",'11'!$L$6) -> 0 | J18: =IF(F18=0,"0",'11'!$O$6) -> 0 | K18: =IF(F18=0,"0",'11'!$L$7) -> 0 | L18: =IF(F18=0,"0",'11'!$O$7) -> 0 | M18: =F18*'11'!$L$8 -> 0 | N18: =F18*'11'!$O$8 -> 0 | O18: =F18*'11'!$L$9 -> 0 | P18: =F18*'11'!$O$9 -> 0 | Q18: =F18*'11'!$D$7 -> 0 | R18: =F18*'11'!$F$7 -> 0 | S18: =F18*'11'!$D$8 -> 0 | T18: =F18*'11'!$F$8 -> 0 | U18: =F18*'11'!$F$9 -> 0 | V18: =H18+J18+L18+N18+P18+R18+T18+U18 -> 0 | X18: =IF(F18>0,V18,0) -> 0
B19: 12 | C19: Modul 12 leer | F19: 1 | G19: =IF(F19=0,"0",'12'!$D$6) -> 0 | H19: =IF(F19=0,"0",'12'!$F$6) -> 0 | I19: =IF(F19=0,"0",'12'!$L$6) -> 0 | J19: =IF(F19=0,"0",'12'!$O$6) -> 0 | K19: =IF(F19=0,"0",'12'!$L$7) -> 0 | L19: =IF(F19=0,"0",'12'!$O$7) -> 0 | M19: =F19*'12'!$L$8 -> 0 | N19: =F19*'12'!$O$8 -> 0 | O19: =F19*'12'!$L$9 -> 0 | P19: =F19*'12'!$O$9 -> 0 | Q19: =F19*'12'!$D$7 -> 0 | R19: =F19*'12'!$F$7 -> 0 | S19: =F19*'12'!$D$8 -> 0 | T19: =F19*'12'!$F$8 -> 0 | U19: =F19*'12'!$F$9 -> 0 | V19: =H19+J19+L19+N19+P19+R19+T19+U19 -> 0 | X19: =IF(F19>0,V19,0) -> 0
B20: 13 | C20: Modul 13 leer | F20: 1 | G20: =IF(F20=0,"0",'13'!$D$6) -> 0 | H20: =IF(F20=0,"0",'13'!$F$6) -> 0 | I20: =IF(F20=0,"0",'13'!$L$6) -> 0 | J20: =IF(F20=0,"0",'13'!$O$6) -> 0 | K20: =IF(F20=0,"0",'13'!$L$7) -> 0 | L20: =IF(F20=0,"0",'13'!$O$7) -> 0 | M20: =F20*'13'!$L$8 -> 0 | N20: =F20*'13'!$O$8 -> 0 | O20: =F20*'13'!$L$9 -> 0 | P20: =F20*'13'!$O$9 -> 0 | Q20: =F20*'13'!$D$7 -> 0 | R20: =F20*'13'!$F$7 -> 0 | S20: =F20*'13'!$D$8 -> 0 | T20: =F20*'13'!$F$8 -> 0 | U20: =F20*'13'!$F$9 -> 0 | V20: =H20+J20+L20+N20+P20+R20+T20+U20 -> 0 | X20: =IF(F20>0,V20,0) -> 0
B21: 14 | C21: Modul 14 leer | F21: 1 | G21: =IF(F21=0,"0",'14'!$D$6) -> 0 | H21: =IF(F21=0,"0",'14'!$F$6) -> 0 | I21: =IF(F21=0,"0",'14'!$L$6) -> 0 | J21: =IF(F21=0,"0",'14'!$O$6) -> 0 | K21: =IF(F21=0,"0",'14'!$L$7) -> 0 | L21: =IF(F21=0,"0",'14'!$O$7) -> 0 | M21: =F21*'14'!$L$8 -> 0 | N21: =F21*'14'!$O$8 -> 0 | O21: =F21*'14'!$L$9 -> 0 | P21: =F21*'14'!$O$9 -> 0 | Q21: =F21*'14'!$D$7 -> 0 | R21: =F21*'14'!$F$7 -> 0 | S21: =F21*'14'!$D$8 -> 0 | T21: =F21*'14'!$F$8 -> 0 | U21: =F21*'14'!$F$9 -> 0 | V21: =H21+J21+L21+N21+P21+R21+T21+U21 -> 0 | X21: =IF(F21>0,V21,0) -> 0
B22: 15 | C22: Modul 15 leer | F22: 1 | G22: =IF(F22=0,"0",'15'!$D$6) -> 0 | H22: =IF(F22=0,"0",'15'!$F$6) -> 0 | I22: =IF(F22=0,"0",'15'!$L$6) -> 0 | J22: =IF(F22=0,"0",'15'!$O$6) -> 0 | K22: =IF(F22=0,"0",'15'!$L$7) -> 0 | L22: =IF(F22=0,"0",'15'!$O$7) -> 0 | M22: =F22*'15'!$L$8 -> 0 | N22: =F22*'15'!$O$8 -> 0 | O22: =F22*'15'!$L$9 -> 0 | P22: =F22*'15'!$O$9 -> 0 | Q22: =F22*'15'!$D$7 -> 0 | R22: =F22*'15'!$F$7 -> 0 | S22: =F22*'15'!$D$8 -> 0 | T22: =F22*'15'!$F$8 -> 0 | U22: =F22*'15'!$F$9 -> 0 | V22: =H22+J22+L22+N22+P22+R22+T22+U22 -> 0 | X22: =IF(F22>0,V22,0) -> 0
B23: 16 | C23: Modul 16 leer | F23: 1 | G23: =IF(F23=0,"0",'16'!$D$6) -> 0 | H23: =IF(F23=0,"0",'16'!$F$6) -> 0 | I23: =IF(F23=0,"0",'16'!$L$6) -> 0 | J23: =IF(F23=0,"0",'16'!$O$6) -> 0 | K23: =IF(F23=0,"0",'16'!$L$7) -> 0 | L23: =IF(F23=0,"0",'16'!$O$7) -> 0 | M23: =F23*'16'!$L$8 -> 0 | N23: =F23*'16'!$O$8 -> 0 | O23: =F23*'16'!$L$9 -> 0 | P23: =F23*'16'!$O$9 -> 0 | Q23: =F23*'16'!$D$7 -> 0 | R23: =F23*'16'!$F$7 -> 0 | S23: =F23*'16'!$D$8 -> 0 | T23: =F23*'16'!$F$8 -> 0 | U23: =F23*'16'!$F$9 -> 0 | V23: =H23+J23+L23+N23+P23+R23+T23+U23 -> 0 | X23: =IF(F23>0,V23,0) -> 0
B24: 17 | C24: Modul 17 leer | F24: 1 | G24: =IF(F24=0,"0",'17'!$D$6) -> 0 | H24: =IF(F24=0,"0",'17'!$F$6) -> 0 | I24: =IF(F24=0,"0",'17'!$L$6) -> 0 | J24: =IF(F24=0,"0",'17'!$O$6) -> 0 | K24: =IF(F24=0,"0",'17'!$L$7) -> 0 | L24: =IF(F24=0,"0",'17'!$O$7) -> 0 | M24: =F24*'17'!$L$8 -> 0 | N24: =F24*'17'!$O$8 -> 0 | O24: =F24*'17'!$L$9 -> 0 | P24: =F24*'17'!$O$9 -> 0 | Q24: =F24*'17'!$D$7 -> 0 | R24: =F24*'17'!$F$7 -> 0 | S24: =F24*'17'!$D$8 -> 0 | T24: =F24*'17'!$F$8 -> 0 | U24: =F24*'17'!$F$9 -> 0 | V24: =H24+J24+L24+N24+P24+R24+T24+U24 -> 0 | X24: =IF(F24>0,V24,0) -> 0
B25: 18 | C25: Modul 18 leer | F25: 1 | G25: =IF(F25=0,"0",'18'!$D$6) -> 0 | H25: =IF(F25=0,"0",'18'!$F$6) -> 0 | I25: =IF(F25=0,"0",'18'!$L$6) -> 0 | J25: =IF(F25=0,"0",'18'!$O$6) -> 0 | K25: =IF(F25=0,"0",'18'!$L$7) -> 0 | L25: =IF(F25=0,"0",'18'!$O$7) -> 0 | M25: =F25*'18'!$L$8 -> 0 | N25: =F25*'18'!$O$8 -> 0 | O25: =F25*'18'!$L$9 -> 0 | P25: =F25*'18'!$O$9 -> 0 | Q25: =F25*'18'!$D$7 -> 0 | R25: =F25*'18'!$F$7 -> 0 | S25: =F25*'18'!$D$8 -> 0 | T25: =F25*'18'!$F$8 -> 0 | U25: =F25*'18'!$F$9 -> 0 | V25: =H25+J25+L25+N25+P25+R25+T25+U25 -> 0 | X25: =IF(F25>0,V25,0) -> 0
A26: 19 | B26: 19 | C26: Modul 19 leer | F26: 1 | G26: =IF(F26=0,"0",'19'!$D$6) -> 0 | H26: =IF(F26=0,"0",'19'!$F$6) -> 0 | I26: =IF(F26=0,"0",'19'!$L$6) -> 0 | J26: =IF(F26=0,"0",'19'!$O$6) -> 0 | K26: =IF(F26=0,"0",'19'!$L$7) -> 0 | L26: =IF(F26=0,"0",'19'!$O$7) -> 0 | M26: =F26*'19'!$L$8 -> 0 | N26: =F26*'19'!$O$8 -> 0 | O26: =F26*'19'!$L$9 -> 0 | P26: =F26*'19'!$O$9 -> 0 | Q26: =F26*'19'!$D$7 -> 0 | R26: =F26*'19'!$F$7 -> 0 | S26: =F26*'19'!$D$8 -> 0 | T26: =F26*'19'!$F$8 -> 0 | U26: =F26*'19'!$F$9 -> 0 | V26: =H26+J26+L26+N26+P26+R26+T26+U26 -> 0 | X26: =IF(F26>0,V26,0) -> 0
B27: 20 | C27: Modul 20 leer | F27: 1 | G27: =IF(F27=0,"0",'20'!$D$6) -> 0 | H27: =IF(F27=0,"0",'20'!$F$6) -> 0 | I27: =IF(F27=0,"0",'20'!$L$6) -> 0 | J27: =IF(F27=0,"0",'20'!$O$6) -> 0 | K27: =IF(F27=0,"0",'20'!$L$7) -> 0 | L27: =IF(F27=0,"0",'20'!$O$7) -> 0 | M27: =F27*'20'!$L$8 -> 0 | N27: =F27*'20'!$O$8 -> 0 | O27: =F27*'20'!$L$9 -> 0 | P27: =F27*'20'!$O$9 -> 0 | Q27: =F27*'20'!$D$7 -> 0 | R27: =F27*'20'!$F$7 -> 0 | S27: =F27*'20'!$D$8 -> 0 | T27: =F27*'20'!$F$8 -> 0 | U27: =F27*'20'!$F$9 -> 0 | V27: =H27+J27+L27+N27+P27+R27+T27+U27 -> 0 | X27: =IF(F27>0,V27,0) -> 0
B29: Summen | G29: =SUM(G8:G28) -> 0 | H29: =G29*Konstruktion -> 0 | I29: =SUM(I8:I28) -> 0 | J29: =I29*Hardware -> 0 | K29: =SUM(K8:K28) -> 0 | L29: =K29*Software -> 0 | M29: =SUM(M8:M28) -> 0 | N29: =SUM(N8:N28) -> 0 | O29: =SUM(O8:O28) -> 0 | P29: =SUM(P8:P28) -> 0 | Q29: =SUM(Q8:Q28) -> 0 | R29: =SUM(R8:R28) -> 0 | S29: =SUM(S8:S28) -> 0 | T29: =SUM(T8:T28) -> 0 | ... V29: =SUM(V8:V28) -> 0 | X29: =SUM(X8:X27) -> 0
B31: Pr | C31: =PM!$D$3 -> Projektmanagement - Umfänge im Haus | F31: 1 | G31: =PM!$Q$15*F31 -> 0 | K31: =PM!$Q$14*F31 -> 0 | N31: Std. Projektierung | O31: =PM!$Q$16*F31 -> 0 | V31: =G31*Konstruktion+K31*Software+O31*Projektleitung -> 0 | X31: =IF(F31>0,V31,0) -> 0
B32: Dok | C32: =Dok!$D$3 -> Erstellung der Dokumentation | F32: 1 | G32: =Dok!$U$17 -> 0 | I32: =Dok!$U$18 -> 0 | K32: =Dok!$U$19 -> 0 | N32: Std. Dokumentation | O32: =Dok!$U$16*F32 -> 0 | T32: Auswärts | U32: =Dok!T20 -> 0 | V32: =G32*Konstruktion+I32*Hardware+K32*Software+O32*Dokumentation+U32 -> 0 | X32: =IF(F32>0,V32,0) -> 0
B33: Ve | C33: =Ve!$D$3 -> Verpackung Versand | F33: 1 | Q33: Verpackungskosten | R33: =Ve!$Q$12*F33 -> 0 | S33: Versandkosten | U33: =Ve!$Q$13*F33 -> 0 | V33: =R33+U33 -> 0 | X33: =IF(F33>0,V33,0) -> 0
N34: Arbeitskosten | R34: Reisekosten | T34: Reisezeit | U34: Zuschläge
B35: IB1 | C35: Anwenderschulung 3x 1 Tag | F35: 1 | N35: =IBN!J$21 -> 1087.7061 | R35: =IBN!J$36 -> 764.115 | U35: =IBN!J$38 -> 139.79831 | V35: =IBN!J$5 -> 1991.6194 | X35: =IF(F35>0,V35,0) -> 1991.6194
B36: IB2 | C36: Instandhaltung 3x 1 Tag | F36: 1 | N36: =IBN!P$21 -> 1087.7061 | R36: =IBN!P$36 -> 764.115 | U36: =IBN!P$38 -> 139.79831 | V36: =IBN!P$5 -> 1991.6194 | X36: =IF(F36>0,V36,0) -> 1991.6194
B37: IB3 | C37: Hochlaufbegleitung | F37: 1 | N37: =IBN!V$21 -> 17227.32 | R37: =IBN!V$36 -> 4584.69 | U37: =IBN!V$38 -> 1750.518 | V37: =IBN!V$5 -> 23562.528 | X37: =IF(F37>0,V37,0) -> 23562.528
B38: IB4 | F38: 0 | N38: =IBN!AB$21 -> 0 | R38: =IBN!AB$36 -> 0 | U38: =IBN!AB$38 -> 0 | V38: =IBN!AB$5 -> 0 | X38: =IF(F38>0,V38,0) -> 0
B39: IB5 | F39: 0 | N39: =IBN!AH$21 -> 0 | R39: =IBN!AH$36 -> 0 | U39: =IBN!AH$38 -> 0 | V39: =IBN!AH$5 -> 0 | X39: =IF(F39>0,V39,0) -> 0
U41: Gesamt | V41: =SUM(V29:V39) -> 27545.767 | X41: =SUM(X29:X39) -> 27545.767

Sheet TP
B2: =Angebotsnummer -> A07614700 | G2: Terminübersicht | U2: =Anlage -> Schulung Hochlaufunterstützung
B3: =Kunde -> BMW Leipzig
B4: Datum | E4: =Datum -> 45642 | I4: =Bearbeiter -> Harald Waas
U5: 2024 | BC5: 2025 | FC5: 2026
V6: September | AD6: Oktober | AN6: November | AU6: Dezember | BC6: Januar | BJ6: Februar | BT6: März | CC6: April | CL6: Mai | CV6: Juni | DE6: Juli | DL6: August | DU6: September | ED6: Oktober | EM6: November | EU6: Dezember | FC6: Januar | FM6: Februar | FU6: März | GD6: April | GM6: Mai | GU6: Juni | HC6: Juli | HL6: August | HU6: September | ID6: Oktober | IM6: November | IU6: Dezember
N7: Vorgaben | T7: KW | U7: 36 | W7: 37 | Y7: 38 | AA7: 39 | AC7: 40 | AE7: 41 | AG7: 42 | AI7: 43 | AK7: 44 | AM7: 45 | AO7: 46 | AQ7: 47 | AS7: 48 | AU7: 49 | AW7: 50 | AY7: 51 | BA7: 52 | BC7: 1 | BE7: 2 | BG7: 3 | BI7: 4 | BK7: 5 | BM7: 6 | BO7: 7 | BQ7: 8 | BS7: 9 | BU7: 10 | BW7: 11 | BY7: 12 | CA7: 13 | CC7: 14 | CE7: 15 | CG7: 16 | CI7: 17 | CK7: 18 | CM7: 19 | CO7: 20 | CQ7: 21 | CS7: 22 | CU7: 23 | CW7: 24 | CY7: 25 | DA7: 26 | DC7: 27 | DE7: 28 | DG7: 29 | DI7: 30 | DK7: 31 | DM7: 32 | DO7: 33 | DQ7: 34 | DS7: 35 | DU7: 36 | DW7: 37 | DY7: 38 | EA7: 39 | EC7: 40 | EE7: 41 | EG7: 42 | EI7: 43 | EK7: 44 | EM7: 45 | EO7: 46 | EQ7: 47 | ES7: 48 | EU7: 49 | EW7: 50 | EY7: 51 | FA7: 52 | FC7: 1 | FE7: 2 | FG7: 3 | FI7: 4 | FK7: 5 | FM7: 6 | FO7: 7 | FQ7: 8 | FS7: 9 | FU7: 10 | FW7: 11 | FY7: 12 | GA7: 13 | GC7: 14 | GE7: 15 | GG7: 16 | GI7: 17 | GK7: 18 | GM7: 19 | GO7: 20 | GQ7: 21 | GS7: 22 | GU7: 23 | GW7: 24 | GY7: 25 | HA7: 26 | HC7: 27 | HE7: 28 | HG7: 29 | HI7: 30 | HK7: 31 | HM7: 32 | HO7: 33 | HQ7: 34 | HS7: 35 | HU7: 36 | HW7: 37 | HY7: 38 | IA7: 39 | IC7: 40 | IE7: 41 | IG7: 42 | II7: 43 | IK7: 44 | IM7: 45 | IO7: 46 | IQ7: 47 | IS7: 48 | IU7: 49 | IW7: 50 | IY7: 51 | JA7: 52
B9: Projektmanagement | N9: =Übersicht!$O$31 -> 0
B10: Mechanik-Konstruktion | N10: =Grafik!H6 -> 0
B11: Elektro-Konstruktion | N11: =Grafik!J6 -> 0
B12: Kaufteile/Beistellungen | N12: =Grafik!$O$6 -> 0
B13: Teilefertigung | N13: =Grafik!$M$7 -> 0
B14: Montage mechanisch | N14: =Grafik!$M$6 -> 0
B15: Montage elektrisch | N15: =Grafik!$N$6 -> 0
B16: Software | N16: =Grafik!$K$6 -> 0
B17: Inbetriebnahme im Haus | N17: =Grafik!K7 -> 0
B18: Verpacken/Verladen/Transport | N18: =Übersicht!V$33 -> 0
B19: Wiederaufbau und Inbetriebnahme | N19: Sw | O19: =IBN!AJ14 -> 135 | P19: Mo | Q19: =IBN!AJ8 -> 0 | R19: El | S19: =IBN!AJ11 -> 0
H21: MK
H22: EKo TF Kaufteile (o. MGZ)
H23: SW Mo El
H24: Inb im Haus

Sheet AP+
B2: =Kunde -> BMW Leipzig | C2: Projektvorgabewerte zur Eingabe in AP+ | J2: Angebot/Auftrag
B3: =Übersicht!C4 -> Schulung Hochlaufunterstützung | C3: =Anlage -> Schulung Hochlaufunterstützung | J3: =Angebotsnummer -> A07614700
B7: M-Konstruktion | C7: 10 | D7: =VK!F8 -> 0 | G7: Kaufteile | H7: *KT | I7: =VK!G21 -> 0
B9: Dokumentation | C9: 20 | D9: =VK!F9 -> 0 | G9: Auslösen | H9: 1-000006 | I9: =IBN!AK19/(1+Gewinn)/(1+Sicherheit) -> 884
B11: Teilefertigung | C11: 50 | D11: =VK!F18 -> 0 | G11: Übernachtung / Hotel | H11: 1-000007 | I11: =IBN!AK20/(1+Gewinn)/(1+Sicherheit) -> 1700
B13: Montage | C13: 110 | D13: =VK!F17 -> 0 | G13: Kilometer Firmen-PKW | H13: 1-000008 | I13: =IBN!AK29/(1+Gewinn)/(1+Sicherheit) -> 1920
B15: Montage IBN | C15: 150 | D15: =IBN!AJ8 -> 0 | G15: Taxi | H15: 1-000009 | I15: =IBN!AK32/(1+Gewinn)/(1+Sicherheit) -> 0
B17: E-Konstruktion | C17: 170 | D17: =VK!F11 -> 0 | G17: Leihauto | H17: 1-000010 | I17: =IBN!AK33/(1+Gewinn)/(1+Sicherheit) -> 0
B19: Software | C19: 180 | D19: =VK!F12 -> 0 | G19: Bus/Zug/Fähre | H19: 1-000011 | I19: =IBN!AK34/(1+Gewinn)/(1+Sicherheit) -> 0
B21: Software-IBN/Schulung im Haus | C21: 190 | D21: =VK!F13 -> 0 | G21: Flüge | H21: 1-000012 | I21: =IBN!AK31/(1+Gewinn)/(1+Sicherheit) -> 0
B23: Elektro-Ing IBN-Kunde | C23: 200 | D23: =IBN!AJ14 -> 135 | G23: Sonstiges | H23: 1-000013 | I23: =IBN!AK35/(1+Gewinn)/(1+Sicherheit) -> 0
B25: Elektrik im Haus | C25: 230 | D25: =VK!F19 -> 0 | G25: Zuschläge 25% Arbeits+Reisezeiten | H25: 1-001921 | I25: =VK!G30 -> 1753.5
B27: Elektro-Monteur IBN-Kunde | C27: 260 | D27: =IBN!AJ11 -> 0 | G27: Verpackung und Transport | H27: 1-000537 | I27: =VK!H22 -> 0
B29: Projektleiter intern | C29: 270 | D29: =Grafik!L6 -> 0 | G29: Dokumentation auswärts | H29: 1-000555 | I29: =VK!D9 -> 0
B31: Montage Reisezeiten | C31: 340 | D31: =IBN!AJ24 -> 0
B33: SW+E-Ko Reisezeiten | C33: 350 | D33: =IBN!AJ26 -> 32 | G33: Kalkuliert Netto | I33: =VK!H31 -> 23792.5
B35: Elektro Monteur Reisezeiten | C35: 360 | D35: =IBN!AJ25 -> 0 | G35: Gewinn | I35: =Gewinn -> 0.1
B37: Projektleiter Reisezeiten | C37: 380 | D37: =IBN!AJ27 -> 0 | G37: Sicherheit | I37: =Sicherheit -> 0.0525
B39: Projektleiter IBN-Kunde | C39: 390 | D39: =IBN!AJ17 -> 0 | G39: Angebotspreis | I39: =VK!H36 -> 27545.767
H43: Bearbeiter | I43: =Bearbeiter -> Harald Waas
I45: =Datum -> 45642

Sheet VK
B2: =Kunde -> BMW Leipzig | C2: Projektvorgabewerte - VK | I2: Angebot/Auftrag
B3: =Übersicht!E3 -> Pascal Böhme | C3: =Anlage -> Schulung Hochlaufunterstützung | I3: =Angebotsnummer -> A07614700
B5: Kostenstelle | E5: Stundensatz o.Gewinn | F5: Vorgaben
F6: Std. VK | H6: Summe
B7: Konstruktion Mechanik
B8: Konstruktion | E8: =Grafik!D11 -> 100 | F8: =Grafik!H6 -> 0 | G8: =E8*F8 -> 0 | H8: =G8 -> 0 | J8: 10
B9: Dokumentation | C9: auswärts: | D9: =Grafik!I7 -> 0 | E9: =Grafik!D12 -> 100 | F9: =Grafik!I6 -> 0 | G9: =E9*F9 -> 0 | H9: =G9+D9 -> 0 | J9: 1-000555, 20
B10: Konstruktion Elektrik
B11: E-Konstruktion | E11: =Grafik!D13 -> 92 | F11: =Grafik!J6 -> 0 | G11: =E11*F11 -> 0 | H11: =G11+G12+G13 -> 0 | J11: 170
B12: Software | E12: =Grafik!D14 -> 105 | F12: =Grafik!K6 -> 0 | G12: =E12*F12 -> 0 | J12: 180
B13: Inbetriebnahme/Schulung | E13: =Grafik!D15 -> 105 | F13: =Grafik!K7 -> 0 | G13: =E13*F13 -> 0 | J13: 190
B14: Projektmanagement
B15: Aus Projektierung | E15: =Grafik!D17 -> 110 | F15: =Grafik!L6 -> 0 | H15: =E15*F15 -> 0 | J15: 270
B16: Fertigung
B17: Montage | E17: =Grafik!D18 -> 82 | F17: =Grafik!M6 -> 0 | G17: =E17*F17 -> 0 | H17: =G17+G18+G19 -> 0 | J17: 110
B18: Teilefertigung | E18: =Grafik!D19 -> 85 | F18: =Grafik!M7 -> 0 | G18: =E18*F18 -> 0 | J18: 50
B19: Elektrik | E19: =Grafik!D20 -> 82 | F19: =Grafik!N6 -> 0 | G19: =E19*F19 -> 0 | J19: 230
B20: Materialkosten | F20: MGZ | G20: kalkuliert | H20: inkl. MGZ
B21: Kaufteile | F21: =MGKZ -> 0.1 | G21: =Grafik!O6 -> 0 | H21: =G21*(1+$F$21) -> 0 | J21: *KT
B22: Versandkosten | F22: 0 | G22: =Grafik!P6+Grafik!P7 -> 0 | H22: =G22*(1+$F$22) -> 0 | J22: 1-000537
B23: Inbetriebnahme Kunde | F23: Std.VK | G23: Betrag in €
B24: Software | E24: =Grafik!D14 -> 105 | F24: =IBN!AJ14 -> 135 | G24: =E24*F24 -> 14175 | H24: =SUM(G24:G30) -> 23792.5 | J24: 200
B25: Montage | E25: =Grafik!D18 -> 82 | F25: =IBN!AJ8 -> 0 | G25: =E25*F25 -> 0 | J25: 150
B26: Elektrik | E26: =Grafik!D20 -> 82 | F26: =IBN!AJ11 -> 0 | G26: =E26*F26 -> 0 | J26: 260
B27: Projektierung (PL) | E27: =Grafik!D17 -> 110 | F27: =IBN!AJ17 -> 0 | G27: =E27*F27 -> 0 | J27: 390
B28: Reisekosten (Zeiten) | G28: =SUM(IBN!AK24:AK27)/(1+Gewinn)/(1+Sicherheit) -> 3360 | J28: 340,350,360,380
B29: Auslöse, Hotel, Flüge, Transfer, sonstiges | G29: =SUM(IBN!AK19:AK20,IBN!AK29,IBN!AK31:AK35)/(1+Gewinn)/(1+Sicherheit) -> 4504 | J29: 1-000006,7,12,9,10,11,13
B30: Zuschlag pauschal auf Arbeits-/Reisezeiten | G30: =IBN!AK38/(1+Gewinn)/(1+Sicherheit) -> 1753.5 | J30: 1-001921
F31: Kalkuliert inkl. Nachträge | H31: =SUM(H7:H30) -> 23792.5
F32: Gewinn | G32: =Gewinn -> 0.1 | H32: =H31*G32 -> 2379.25
F33: Angebotspreis mit Gewinn | H33: =H31+H32 -> 26171.75 | J33: Verhandlungsspielraum
D34: Bearbeiter | F34: Sicherheit | G34: =Sicherheit -> 0.0525 | H34: =H33*G34 -> 1374.0169 | J34: =Verhandlungsspielraum -> 0.05
D35: =Bearbeiter -> Harald Waas | F35: Angebotspreis kalkuliert | H35: =H33+H34 -> 27545.767
D36: =Datum -> 45642 | F36: Angebotspreis Abgabe | H36: =Übersicht!X41 -> 27545.767

Sheet Grafik
C2: =Kunde -> BMW Leipzig | D2: Auswertungen zur Gesamtkalkulation der Baugruppen | N2: Bearbeiter | P2: Datum | Q2: Angebot
C3: =Übersicht!C4 -> Schulung Hochlaufunterstützung | D3: =Anlage -> Schulung Hochlaufunterstützung | N3: =Bearbeiter -> Harald Waas | P3: =Datum -> 45642 | Q3: =Angebotsnummer -> A07614700
C4: Zuschläge | H4: inkl. Dok+PM | J4: inkl. Dok | K4: inkl. Dok+PM | O4: Werte für VK ohne Gewinn, ohne MGKZ
C5: MGKZ | D5: 0.1 | H5: M-Konstr. | I5: Doku | J5: E-Konstr. | K5: SW/INB | L5: PM | M5: MO/TF | N5: Elektrik | O5: Kaufteile | P5: VP/Vers. | Q5: INB
C6: Gewinn | D6: 0.1 | E6: Sicherheit | H6: =Übersicht!$G$29+Übersicht!$G$31+Übersicht!$G$32 -> 0 | I6: =Übersicht!$O$32 -> 0 | J6: =Übersicht!$I$29+Übersicht!I32 -> 0 | K6: =Übersicht!$K$29+Übersicht!$K$31+Übersicht!$K$32 -> 0 | L6: =Übersicht!$O$31 -> 0 | M6: =Übersicht!$Q$29 -> 0 | N6: =Übersicht!$O$29 -> 0 | O6: =Übersicht!$U$29/(1+Sicherheit)/(1+Gewinn)/(1+MGKZ) -> 0 | P6: =Übersicht!$R$33/(1+Sicherheit)/(1+Gewinn) -> 0 | Q6: =VK!H24 -> 23792.5
C7: Verhandlungsspielraum | D7: 0.05 | E7: =D7*D7+D7 -> 0.0525 | I7: =Dok!T20/(1+Sicherheit)/(1+Gewinn) -> 0 | K7: =Übersicht!$M$29 -> 0 | M7: =Übersicht!$S$29 -> 0 | P7: =Übersicht!$U$33/(1+Sicherheit)/(1+Gewinn) -> 0
C9: Gesamtpreis VK | D9: =SUM(D22:D33) -> 27545.767 | F9: =SUM(F22:F33) -> 1
C10: Stundensätze | D10: Netto | E10: mit Gewinn | F10: mit Sicherheit
C11: M-Konstruktion | D11: 100 | E11: =D11*(1+Gewinn) -> 110 | F11: =E11*(1+Sicherheit) -> 115.775
C12: Dokumentation | D12: 100 | E12: =D12*(1+Gewinn) -> 110 | F12: =E12*(1+Sicherheit) -> 115.775
C13: E-Konstruktion | D13: 92 | E13: =D13*(1+Gewinn) -> 101.2 | F13: =E13*(1+Sicherheit) -> 106.513
C14: Software | D14: 105 | E14: =D14*(1+Gewinn) -> 115.5 | F14: =E14*(1+Sicherheit) -> 121.56375
C15: Inbetriebnahme | D15: 105 | E15: =D15*(1+Gewinn) -> 115.5 | F15: =E15*(1+Sicherheit) -> 121.56375
C16: Projektmanagement KO | D16: 100 | E16: =D16*(1+Gewinn) -> 110 | F16: =E16*(1+Sicherheit) -> 115.775
C17: Projektleitung | D17: 110 | E17: =D17*(1+Gewinn) -> 121 | F17: =E17*(1+Sicherheit) -> 127.3525
C18: Montage | D18: 82 | E18: =D18*(1+Gewinn) -> 90.2 | F18: =E18*(1+Sicherheit) -> 94.9355
C19: Teilefertigung mechanisch | D19: 85 | E19: =D19*(1+Gewinn) -> 93.5 | F19: =E19*(1+Sicherheit) -> 98.40875
C20: Elektrik SSB, Installation | D20: 82 | E20: =D20*(1+Gewinn) -> 90.2 | F20: =E20*(1+Sicherheit) -> 94.9355
C21: Kostenaufteilung
C22: M-Konstruktion | D22: =Übersicht!H29 -> 0 | F22: =IF(Gesamtpreis<>0,D22/Gesamtpreis,0) -> 0
C23: Dokumentation | D23: =Übersicht!V32 -> 0 | F23: =IF(Gesamtpreis<>0,D23/Gesamtpreis,0) -> 0
C24: E-Konstruktion | D24: =Übersicht!J29 -> 0 | F24: =IF(Gesamtpreis<>0,D24/Gesamtpreis,0) -> 0
C25: Software | D25: =Übersicht!L29 -> 0 | F25: =IF(Gesamtpreis<>0,D25/Gesamtpreis,0) -> 0
C26: Inbetriebnahme | D26: =Übersicht!N29 -> 0 | F26: =IF(Gesamtpreis<>0,D26/Gesamtpreis,0) -> 0
C27: Projektmanagement | D27: =Übersicht!V31 -> 0 | F27: =IF(Gesamtpreis<>0,D27/Gesamtpreis,0) -> 0
C28: Montage | D28: =Übersicht!R29 -> 0 | F28: =IF(Gesamtpreis<>0,D28/Gesamtpreis,0) -> 0
C29: Teilefertigung mechanisch | D29: =Übersicht!T29 -> 0 | F29: =IF(Gesamtpreis<>0,D29/Gesamtpreis,0) -> 0
C30: Elektrik SSB, Installation | D30: =Übersicht!P29 -> 0 | F30: =IF(Gesamtpreis<>0,D30/Gesamtpreis,0) -> 0
C31: Kaufteile | D31: =Übersicht!U29 -> 0 | F31: =IF(Gesamtpreis<>0,D31/Gesamtpreis,0) -> 0
C32: Verpackung/Versand | D32: =Übersicht!V33 -> 0 | F32: =IF(Gesamtpreis<>0,D32/Gesamtpreis,0) -> 0
C33: Inbetriebnahme Kunde | D33: =SUM(Übersicht!V35:V39) -> 27545.767 | F33: =IF(Gesamtpreis<>0,D33/Gesamtpreis,0) -> 1
C36: MS-F_Rev.:7 / 18.09.2024 / Ulrich Radlbeck

Sheet PM
B2: PM | C2: =Kunde -> BMW Leipzig | D2: =Anlage -> Schulung Hochlaufunterstützung | M2: Datum | O2: Bearbeiter | P2: Angebot
C3: Kalkulation | D3: Projektmanagement - Umfänge im Haus | M3: =Datum -> 45642 | O3: =Bearbeiter -> Harald Waas | P3: =Angebotsnummer -> A07614700
B6: Pos | C6: Bezeichnung | G6: Bemerkung | J6: SW | K6: MK | L6: Pl | M6: Summe | O6: Benötigte Gesamtzahl | Q6: =Übersicht!F31 -> 1
B8: 1 | M8: =J8*Software+L8*Projektleitung+K8*Konstruktion -> 0
B9: =B8+1 -> 2 | M9: =J9*Software+L9*Projektleitung+K9*Konstruktion -> 0 | O9: Gesamtkosten (VK)/Stück
B10: =B9+1 -> 3 | M10: =J10*Software+L10*Projektleitung+K10*Konstruktion -> 0 | O10: =SUM(M8:M32) -> 0
B11: =B10+1 -> 4 | M11: =J11*Software+L11*Projektleitung+K11*Konstruktion -> 0
B12: =B11+1 -> 5 | M12: =J12*Software+L12*Projektleitung+K12*Konstruktion -> 0
B13: =B12+1 -> 6 | M13: =J13*Software+L13*Projektleitung+K13*Konstruktion -> 0 | O13: Projektmanagement | Q13: Stunden
B14: =B13+1 -> 7 | M14: =J14*Software+L14*Projektleitung+K14*Konstruktion -> 0 | O14: aus Software | Q14: =SUM(J8:J32) -> 0
B15: =B14+1 -> 8 | M15: =J15*Software+L15*Projektleitung+K15*Konstruktion -> 0 | O15: aus Konstruktion | Q15: =SUM(K8:K32) -> 0
B16: =B15+1 -> 9 | M16: =J16*Software+L16*Projektleitung+K16*Konstruktion -> 0 | O16: aus Projektierung | Q16: =SUM(L8:L32) -> 0
B17: =B16+1 -> 10 | M17: =J17*Software+L17*Projektleitung+K17*Konstruktion -> 0
B18: =B17+1 -> 11 | M18: =J18*Software+L18*Projektleitung+K18*Konstruktion -> 0
B19: =B18+1 -> 12 | M19: =J19*Software+L19*Projektleitung+K19*Konstruktion -> 0 | O19: Alle Werte mit Gewinn und Sicherheit (VK)
B20: =B19+1 -> 13 | M20: =J20*Software+L20*Projektleitung+K20*Konstruktion -> 0
B21: =B20+1 -> 14 | M21: =J21*Software+L21*Projektleitung+K21*Konstruktion -> 0
B22: =B21+1 -> 15 | M22: =J22*Software+L22*Projektleitung+K22*Konstruktion -> 0
B23: =B22+1 -> 16 | M23: =J23*Software+L23*Projektleitung+K23*Konstruktion -> 0
B24: =B23+1 -> 17 | M24: =J24*Software+L24*Projektleitung+K24*Konstruktion -> 0
B25: =B24+1 -> 18 | M25: =J25*Software+L25*Projektleitung+K25*Konstruktion -> 0
B26: =B25+1 -> 19 | M26: =J26*Software+L26*Projektleitung+K26*Konstruktion -> 0
B27: =B26+1 -> 20 | M27: =J27*Software+L27*Projektleitung+K27*Konstruktion -> 0
B28: =B27+1 -> 21 | M28: =J28*Software+L28*Projektleitung+K28*Konstruktion -> 0
B29: =B28+1 -> 22 | M29: =J29*Software+L29*Projektleitung+K29*Konstruktion -> 0
B30: =B29+1 -> 23 | M30: =J30*Software+L30*Projektleitung+K30*Konstruktion -> 0
B31: =B30+1 -> 24 | M31: =J31*Software+L31*Projektleitung+K31*Konstruktion -> 0
B32: =B31+1 -> 25 | M32: =J32*Software+L32*Projektleitung+K32*Konstruktion -> 0

Sheet Dok
B2: Doku | C2: =Kunde -> BMW Leipzig | D2: =Anlage -> Schulung Hochlaufunterstützung | Q2: Datum | S2: Bearbeiter | T2: Angebot
C3: Kalkulation | D3: Erstellung der Dokumentation | Q3: =Datum -> 45642 | S3: =Bearbeiter -> Harald Waas | T3: =Angebotsnummer -> A07614700
B6: Pos | C6: Bezeichnung | G6: Bemerkung | J6: Doku | K6: M-Ko | L6: E-Ko | M6: SW | N6: Stück | O6: €/Stück | P6: Material | Q6: Summe | S6: Benötigte Gesamtzahl | U6: =Übersicht!F32 -> 1
B8: 1 | P8: =N8*O8*(1+Gewinn)*(1+Sicherheit) -> 0 | Q8: =J8*Dokumentation+K8*Konstruktion+L8*Hardware+M8*Software+P8 -> 0 | S8: Gesamtkosten (VK)/Stück
B9: =B8+1 -> 2 | C9: Zeichnungen, Stücklisten ausdrucken | G9: Dokumentation | J9: 0 | K9: 0 | L9: 0 | M9: 0 | N9: 0 | P9: =N9*O9*(1+Gewinn)*(1+Sicherheit) -> 0 | Q9: =J9*Dokumentation+K9*Konstruktion+L9*Hardware+M9*Software+P9 -> 0 | S9: =T11+T12 -> 0
B10: =B9+1 -> 3 | C10: CD Brennen | G10: Dokumentation | P10: =N10*O10*(1+Gewinn)*(1+Sicherheit) -> 0 | Q10: =J10*Dokumentation+K10*Konstruktion+L10*Hardware+M10*Software+P10 -> 0
B11: =B10+1 -> 4 | C11: Dokumentationsordner erstellen inkl. Zubehördokumentation | G11: Dokumentation | P11: =N11*O11*(1+Gewinn)*(1+Sicherheit) -> 0 | Q11: =J11*Dokumentation+K11*Konstruktion+L11*Hardware+M11*Software+P11 -> 0 | S11: Mechanik | T11: =SUM(J8:J32)*Dokumentation+SUM(K8:K32)*Konstruktion+SUM(P8:P32) -> 0
B12: =B11+1 -> 5 | P12: =N12*O12*(1+Gewinn)*(1+Sicherheit) -> 0 | Q12: =J12*Dokumentation+K12*Konstruktion+L12*Hardware+M12*Software+P12 -> 0 | S12: Elektrik | T12: =SUM(L8:L32)*Hardware+SUM(M8:M32)*Software -> 0
B13: =B12+1 -> 6 | C13: Beschreibung der Bedienfunktionen (Kapitel 4 Bedienung) | G13: Softwareabteilung | P13: =N13*O13*(1+Gewinn)*(1+Sicherheit) -> 0 | Q13: =J13*Dokumentation+K13*Konstruktion+L13*Hardware+M13*Software+P13 -> 0
B14: =B13+1 -> 7 | C14: Beschreibung der Geräteeinstellungen (Kapitel 5 Bedienung) | G14: Softwareabteilung | P14: =N14*O14*(1+Gewinn)*(1+Sicherheit) -> 0 | Q14: =J14*Dokumentation+K14*Konstruktion+L14*Hardware+M14*Software+P14 -> 0
B15: =B14+1 -> 8 | C15: Erstellen und in Form bringen der Betriebsanleitung | G15: Doku (H.Körner) | P15: =N15*O15*(1+Gewinn)*(1+Sicherheit) -> 0 | Q15: =J15*Dokumentation+K15*Konstruktion+L15*Hardware+M15*Software+P15 -> 0 | U15: Stunden
B16: =B15+1 -> 9 | P16: =N16*O16*(1+Gewinn)*(1+Sicherheit) -> 0 | Q16: =J16*Dokumentation+K16*Konstruktion+L16*Hardware+M16*Software+P16 -> 0 | S16: Dokumentation | U16: =SUM(J8:J32) -> 0
B17: =B16+1 -> 10 | C17: Elektroplan inkl. Stücklisten ausdrucken (1x Papier) | G17: E-Konstruktion | P17: =N17*O17*(1+Gewinn)*(1+Sicherheit) -> 0 | Q17: =J17*Dokumentation+K17*Konstruktion+L17*Hardware+M17*Software+P17 -> 0 | S17: M-Konstruktion | U17: =SUM(K8:K32) -> 0
B18: =B17+1 -> 11 | C18: Alle Unterlagen im Ornder Dokumentation am Server ablegen | G18: E-Konstruktion | P18: =N18*O18*(1+Gewinn)*(1+Sicherheit) -> 0 | Q18: =J18*Dokumentation+K18*Konstruktion+L18*Hardware+M18*Software+P18 -> 0 | S18: E-Konstruktion | U18: =SUM(L8:L32) -> 0
B19: =B18+1 -> 12 | P19: =N19*O19*(1+Gewinn)*(1+Sicherheit) -> 0 | Q19: =J19*Dokumentation+K19*Konstruktion+L19*Hardware+M19*Software+P19 -> 0 | S19: Software | U19: =SUM(M8:M32) -> 0
B20: =B19+1 -> 13 | C20: Erstellen Risikoanalyse | G20: M-Konstruktion | P20: =N20*O20*(1+Gewinn)*(1+Sicherheit) -> 0 | Q20: =J20*Dokumentation+K20*Konstruktion+L20*Hardware+M20*Software+P20 -> 0 | S20: Auswärts Doku | T20: =SUM(P8:P32) -> 0
B21: =B20+1 -> 14 | C21: Erstellen Wartungspläne | G21: M-Konstruktion | P21: =N21*O21*(1+Gewinn)*(1+Sicherheit) -> 0 | Q21: =J21*Dokumentation+K21*Konstruktion+L21*Hardware+M21*Software+P21 -> 0
B22: =B21+1 -> 15 | P22: =N22*O22*(1+Gewinn)*(1+Sicherheit) -> 0 | Q22: =J22*Dokumentation+K22*Konstruktion+L22*Hardware+M22*Software+P22 -> 0 | S22: Werte mit Gewinn und Sicherheit (VK)
B23: =B22+1 -> 16 | P23: =N23*O23*(1+Gewinn)*(1+Sicherheit) -> 0 | Q23: =J23*Dokumentation+K23*Konstruktion+L23*Hardware+M23*Software+P23 -> 0
B24: =B23+1 -> 17 | C24: Übersetzungkosten 1x Englisch, 1x Spanisch | P24: =N24*O24*(1+Gewinn)*(1+Sicherheit) -> 0 | Q24: =J24*Dokumentation+K24*Konstruktion+L24*Hardware+M24*Software+P24 -> 0
B25: =B24+1 -> 18 | P25: =N25*O25*(1+Gewinn)*(1+Sicherheit) -> 0 | Q25: =J25*Dokumentation+K25*Konstruktion+L25*Hardware+M25*Software+P25 -> 0
B26: =B25+1 -> 19 | P26: =N26*O26*(1+Gewinn)*(1+Sicherheit) -> 0 | Q26: =J26*Dokumentation+K26*Konstruktion+L26*Hardware+M26*Software+P26 -> 0
B27: =B26+1 -> 20 | C27: Achtung: Zeiten für Doku HW und Software werden nicht separat | P27: =N27*O27*(1+Gewinn)*(1+Sicherheit) -> 0 | Q27: =J27*Dokumentation+K27*Konstruktion+L27*Hardware+M27*Software+P27 -> 0
B28: =B27+1 -> 21 | C28: gestempelt (E-Konstr.= Kostenstelle 151, Software = Kostenstelle 152) | P28: =N28*O28*(1+Gewinn)*(1+Sicherheit) -> 0 | Q28: =J28*Dokumentation+K28*Konstruktion+L28*Hardware+M28*Software+P28 -> 0
B29: =B28+1 -> 22 | P29: =N29*O29*(1+Gewinn)*(1+Sicherheit) -> 0 | Q29: =J29*Dokumentation+K29*Konstruktion+L29*Hardware+M29*Software+P29 -> 0
B30: =B29+1 -> 23 | P30: =N30*O30*(1+Gewinn)*(1+Sicherheit) -> 0 | Q30: =J30*Dokumentation+K30*Konstruktion+L30*Hardware+M30*Software+P30 -> 0
B31: =B30+1 -> 24 | P31: =N31*O31*(1+Gewinn)*(1+Sicherheit) -> 0 | Q31: =J31*Dokumentation+K31*Konstruktion+L31*Hardware+M31*Software+P31 -> 0
B32: =B31+1 -> 25 | P32: =N32*O32*(1+Gewinn)*(1+Sicherheit) -> 0 | Q32: =J32*Dokumentation+K32*Konstruktion+L32*Hardware+M32*Software+P32 -> 0

Sheet Ve
B2: Versand | C2: =Kunde -> BMW Leipzig | D2: =Anlage -> Schulung Hochlaufunterstützung | N2: Datum | P2: Bearbeiter | Q2: Angebot
C3: Kalkulation | D3: Verpackung Versand | N3: =Datum -> 45642 | P3: =Bearbeiter -> Harald Waas | Q3: =Angebotsnummer -> A07614700
B6: Pos | C6: Bezeichnung | E6: Bemerkung | H6: Stück | I6: €/Stück | J6: Verpackung | K6: Stück | L6: €/Stück | M6: Versand | N6: Summe | P6: Benötigte Gesamtzahl | R6: =Übersicht!F33 -> 1
B8: 1 | C8: Kiste mit seem. Verpackung 280x240x290cm Tara 600kg | I8: 862 | J8: =H8*I8*(1+Gewinn)*(1+Sicherheit) -> 0 | M8: =K8*L8*(1+Gewinn)*(1+Sicherheit) -> 0 | N8: =J8+M8 -> 0
B9: =B8+1 -> 2 | C9: Kiste mit seem. Verpackung350x240x285cm Tara 900kg | I9: 1260 | J9: =H9*I9*(1+Gewinn)*(1+Sicherheit) -> 0 | M9: =K9*L9*(1+Gewinn)*(1+Sicherheit) -> 0 | N9: =J9+M9 -> 0 | P9: Gesamtkosten (VK)/Stück
B10: =B9+1 -> 3 | C10: Kiste mit seem. Verpackung 410x240x290cm Tara 1000kg | I10: 1434 | J10: =H10*I10*(1+Gewinn)*(1+Sicherheit) -> 0 | M10: =K10*L10*(1+Gewinn)*(1+Sicherheit) -> 0 | N10: =J10+M10 -> 0 | P10: =SUM(Q12:Q13) -> 0
B11: =B10+1 -> 4 | C11: Frachtkosten für Anlieferung 2-3 Kisten | I11: 500 | J11: =H11*I11*(1+Gewinn)*(1+Sicherheit) -> 0 | M11: =K11*L11*(1+Gewinn)*(1+Sicherheit) -> 0 | N11: =J11+M11 -> 0
B12: =B11+1 -> 5 | C12: HDEV5 SL 16 nach ChP (5645) 6 Kisten + Frachtkostenp.750,-- | E12: 5645 | I12: 10006 | J12: =H12*I12*(1+Gewinn)*(1+Sicherheit) -> 0 | M12: =K12*L12*(1+Gewinn)*(1+Sicherheit) -> 0 | N12: =J12+M12 -> 0 | P12: Verpackung | Q12: =SUM(J8:J32) -> 0
B13: =B12+1 -> 6 | C13: Kiste mit seem. Verpackung270x235x290cm Tara 750kg | E13: 5814 | I13: 1049 | J13: =H13*I13*(1+Gewinn)*(1+Sicherheit) -> 0 | M13: =K13*L13*(1+Gewinn)*(1+Sicherheit) -> 0 | N13: =J13+M13 -> 0 | P13: Versand | Q13: =SUM(M8:M32) -> 0
B14: =B13+1 -> 7 | C14: Kiste mit seem. Verpackung430x240x285cm Tara 1050kg | E14: 5903 | I14: 1470 | J14: =H14*I14*(1+Gewinn)*(1+Sicherheit) -> 0 | M14: =K14*L14*(1+Gewinn)*(1+Sicherheit) -> 0 | N14: =J14+M14 -> 0
B15: =B14+1 -> 8 | J15: =H15*I15*(1+Gewinn)*(1+Sicherheit) -> 0 | M15: =K15*L15*(1+Gewinn)*(1+Sicherheit) -> 0 | N15: =J15+M15 -> 0
B16: =B15+1 -> 9 | C16: Versand Inland bis 300km | E16: 1 LKW | J16: =H16*I16*(1+Gewinn)*(1+Sicherheit) -> 0 | L16: 500 | M16: =K16*L16*(1+Gewinn)*(1+Sicherheit) -> 0 | N16: =J16+M16 -> 0
B17: =B16+1 -> 10 | C17: Versand Inland bis 600km | E17: 1 LKW | J17: =H17*I17*(1+Gewinn)*(1+Sicherheit) -> 0 | L17: 600 | M17: =K17*L17*(1+Gewinn)*(1+Sicherheit) -> 0 | N17: =J17+M17 -> 0
B18: =B17+1 -> 11 | J18: =H18*I18*(1+Gewinn)*(1+Sicherheit) -> 0 | M18: =K18*L18*(1+Gewinn)*(1+Sicherheit) -> 0 | N18: =J18+M18 -> 0
B19: =B18+1 -> 12 | C19: Verpackungsmaterial (Holzbalken, Folie, ...) | I19: 500 | J19: =H19*I19*(1+Gewinn)*(1+Sicherheit) -> 0 | M19: =K19*L19*(1+Gewinn)*(1+Sicherheit) -> 0 | N19: =J19+M19 -> 0
B20: =B19+1 -> 13 | J20: =H20*I20*(1+Gewinn)*(1+Sicherheit) -> 0 | M20: =K20*L20*(1+Gewinn)*(1+Sicherheit) -> 0 | N20: =J20+M20 -> 0
B21: =B20+1 -> 14 | J21: =H21*I21*(1+Gewinn)*(1+Sicherheit) -> 0 | M21: =K21*L21*(1+Gewinn)*(1+Sicherheit) -> 0 | N21: =J21+M21 -> 0
B22: =B21+1 -> 15 | J22: =H22*I22*(1+Gewinn)*(1+Sicherheit) -> 0 | M22: =K22*L22*(1+Gewinn)*(1+Sicherheit) -> 0 | N22: =J22+M22 -> 0
B23: =B22+1 -> 16 | J23: =H23*I23*(1+Gewinn)*(1+Sicherheit) -> 0 | M23: =K23*L23*(1+Gewinn)*(1+Sicherheit) -> 0 | N23: =J23+M23 -> 0
B24: =B23+1 -> 17 | J24: =H24*I24*(1+Gewinn)*(1+Sicherheit) -> 0 | M24: =K24*L24*(1+Gewinn)*(1+Sicherheit) -> 0 | N24: =J24+M24 -> 0
B25: =B24+1 -> 18 | J25: =H25*I25*(1+Gewinn)*(1+Sicherheit) -> 0 | M25: =K25*L25*(1+Gewinn)*(1+Sicherheit) -> 0 | N25: =J25+M25 -> 0
B26: =B25+1 -> 19 | J26: =H26*I26*(1+Gewinn)*(1+Sicherheit) -> 0 | M26: =K26*L26*(1+Gewinn)*(1+Sicherheit) -> 0 | N26: =J26+M26 -> 0
B27: =B26+1 -> 20 | J27: =H27*I27*(1+Gewinn)*(1+Sicherheit) -> 0 | M27: =K27*L27*(1+Gewinn)*(1+Sicherheit) -> 0 | N27: =J27+M27 -> 0
B28: =B27+1 -> 21 | J28: =H28*I28*(1+Gewinn)*(1+Sicherheit) -> 0 | M28: =K28*L28*(1+Gewinn)*(1+Sicherheit) -> 0 | N28: =J28+M28 -> 0
B29: =B28+1 -> 22 | J29: =H29*I29*(1+Gewinn)*(1+Sicherheit) -> 0 | M29: =K29*L29*(1+Gewinn)*(1+Sicherheit) -> 0 | N29: =J29+M29 -> 0
B30: =B29+1 -> 23 | J30: =H30*I30*(1+Gewinn)*(1+Sicherheit) -> 0 | M30: =K30*L30*(1+Gewinn)*(1+Sicherheit) -> 0 | N30: =J30+M30 -> 0
B31: =B30+1 -> 24 | J31: =H31*I31*(1+Gewinn)*(1+Sicherheit) -> 0 | M31: =K31*L31*(1+Gewinn)*(1+Sicherheit) -> 0 | N31: =J31+M31 -> 0
B32: =B31+1 -> 25 | J32: =H32*I32*(1+Gewinn)*(1+Sicherheit) -> 0 | M32: =K32*L32*(1+Gewinn)*(1+Sicherheit) -> 0 | N32: =J32+M32 -> 0

Sheet IBN
B1: IBN | C1: =Kunde -> BMW Leipzig | F1: =Anlage -> Schulung Hochlaufunterstützung | AB1: Datum | AD1: Bearbeiter | AG1: Angebot
C2: Kalkulation | F2: IBN - Dienstleistung beim Kunden | AB2: =Datum -> 45642 | AD2: =Bearbeiter -> Harald Waas | AG2: =Angebotsnummer -> A07614700
F4: =Übersicht!$C35 -> Anwenderschulung 3x 1 Tag | L4: =Übersicht!$C36 -> Instandhaltung 3x 1 Tag | R4: Hochlaufunterstüzung | X4: =Übersicht!$C38 -> 0 | AD4: =Übersicht!$C39 -> 0 | AJ4: Summen
F5: Benötige Anzahl: | I5: =Übersicht!$F35 -> 1 | J5: =J21+J36+J38 -> 1991.6194 | L5: Benötige Anzahl: | O5: =Übersicht!$F36 -> 1 | P5: =P21+P36+P38 -> 1991.6194 | R5: Benötige Anzahl: | U5: =Übersicht!$F37 -> 1 | V5: =V21+V36+V38 -> 23562.528 | X5: Benötige Anzahl: | AA5: =Übersicht!$F38 -> 0 | AB5: =AB21+AB36+AB38 -> 0 | AD5: Benötige Anzahl: | AG5: =Übersicht!$F39 -> 0 | AH5: =AH21+AH36+AH38 -> 0 | AK5: =SUM(J5,P5,V5,AB5,AH5) -> 27545.767
B7: Arbeitskosten | D7: netto | E7: brutto | F7: Mann | G7: Tag | H7: Std. | I7: Summe | J7: Summe | L7: Mann | M7: Tag | N7: Std. | O7: Summe | P7: Summe | R7: Mann | S7: Tag | T7: Std. | U7: Summe | V7: Summe | X7: Mann | Y7: Tag | Z7: Std. | AA7: Summe | AB7: Summe | AD7: Mann | AE7: Tag | AF7: Std. | AG7: Summe | AH7: Summe
B8: Mechanik-Monteur | D8: =Grafik!D18 -> 82 | E8: =D8*(1+Sicherheit)*(1+Gewinn) -> 94.9355 | F8: 0 | G8: 0 | H8: 0 | I8: =$I$5*F8*G8*H8 -> 0 | J8: =I8*$E$8 -> 0 | L8: 0 | M8: 0 | N8: 0 | O8: =$O$5*L8*M8*N8 -> 0 | P8: =O8*$E$8 -> 0 | R8: 0 | S8: 0 | T8: 0 | U8: =$U$5*R8*S8*T8 -> 0 | V8: =U8*$E$8 -> 0 | X8: 0 | Y8: 0 | Z8: 0 | AA8: =$AA$5*X8*Y8*Z8 -> 0 | AB8: =AA8*$E$8 -> 0 | AD8: 0 | AE8: 0 | AF8: 0 | AG8: =$AG$5*AD8*AE8*AF8 -> 0 | AH8: =AG8*$E$8 -> 0 | AJ8: =SUM(I8:I10,O8:O10,U8:U10,AA8:AA10,AG8:AG10) -> 0 | AK8: =SUM(J8:J10,P8:P10,V8:V10,AB8:AB10,AH8:AH10) -> 0
F9: 0 | G9: 0 | H9: 0 | I9: =$I$5*F9*G9*H9 -> 0 | J9: =I9*$E$8 -> 0 | L9: 0 | M9: 0 | N9: 0 | O9: =$O$5*L9*M9*N9 -> 0 | P9: =O9*$E$8 -> 0 | R9: 0 | S9: 0 | T9: 0 | U9: =$U$5*R9*S9*T9 -> 0 | V9: =U9*$E$8 -> 0 | X9: 0 | Y9: 0 | Z9: 0 | AA9: =$AA$5*X9*Y9*Z9 -> 0 | AB9: =AA9*$E$8 -> 0 | AD9: 0 | AE9: 0 | AF9: 0 | AG9: =$AG$5*AD9*AE9*AF9 -> 0 | AH9: =AG9*$E$8 -> 0
F10: 0 | G10: 0 | H10: 0 | I10: =$I$5*F10*G10*H10 -> 0 | J10: =I10*$E$8 -> 0 | L10: 0 | M10: 0 | N10: 0 | O10: =$O$5*L10*M10*N10 -> 0 | P10: =O10*$E$8 -> 0 | R10: 0 | S10: 0 | T10: 0 | U10: =$U$5*R10*S10*T10 -> 0 | V10: =U10*$E$8 -> 0 | X10: 0 | Y10: 0 | Z10: 0 | AA10: =$AA$5*X10*Y10*Z10 -> 0 | AB10: =AA10*$E$8 -> 0 | AD10: 0 | AE10: 0 | AF10: 0 | AG10: =$AG$5*AD10*AE10*AF10 -> 0 | AH10: =AG10*$E$8 -> 0
B11: Elektro-Monteur | D11: =Grafik!D20 -> 82 | E11: =D11*(1+Sicherheit)*(1+Gewinn) -> 94.9355 | F11: 0 | G11: 0 | H11: 0 | I11: =$I$5*F11*G11*H11 -> 0 | J11: =I11*$E$11 -> 0 | L11: 0 | M11: 0 | N11: 0 | O11: =$O$5*L11*M11*N11 -> 0 | P11: =O11*$E$11 -> 0 | R11: 0 | S11: 0 | T11: 0 | U11: =$U$5*R11*S11*T11 -> 0 | V11: =U11*$E$11 -> 0 | X11: 0 | Y11: 0 | Z11: 0 | AA11: =$AA$5*X11*Y11*Z11 -> 0 | AB11: =AA11*$E$11 -> 0 | AD11: 0 | AE11: 0 | AF11: 0 | AG11: =$AG$5*AD11*AE11*AF11 -> 0 | AH11: =AG11*$E$11 -> 0 | AJ11: =SUM(I11:I13,O11:O13,U11:U13,AA11:AA13,AG11:AG13) -> 0 | AK11: =SUM(J11:J13,P11:P13,V11:V13,AB11:AB13,AH11:AH13) -> 0
F12: 0 | G12: 0 | H12: 0 | I12: =$I$5*F12*G12*H12 -> 0 | J12: =I12*$E$11 -> 0 | L12: 0 | M12: 0 | N12: 0 | O12: =$O$5*L12*M12*N12 -> 0 | P12: =O12*$E$11 -> 0 | R12: 0 | S12: 0 | T12: 0 | U12: =$U$5*R12*S12*T12 -> 0 | V12: =U12*$E$11 -> 0 | X12: 0 | Y12: 0 | Z12: 0 | AA12: =$AA$5*X12*Y12*Z12 -> 0 | AB12: =AA12*$E$11 -> 0 | AD12: 0 | AE12: 0 | AF12: 0 | AG12: =$AG$5*AD12*AE12*AF12 -> 0 | AH12: =AG12*$E$11 -> 0
F13: 0 | G13: 0 | H13: 0 | I13: =$I$5*F13*G13*H13 -> 0 | J13: =I13*$E$11 -> 0 | L13: 0 | M13: 0 | N13: 0 | O13: =$O$5*L13*M13*N13 -> 0 | P13: =O13*$E$11 -> 0 | R13: 0 | S13: 0 | T13: 0 | U13: =$U$5*R13*S13*T13 -> 0 | V13: =U13*$E$11 -> 0 | X13: 0 | Y13: 0 | Z13: 0 | AA13: =$AA$5*X13*Y13*Z13 -> 0 | AB13: =AA13*$E$11 -> 0 | AD13: 0 | AE13: 0 | AF13: 0 | AG13: =$AG$5*AD13*AE13*AF13 -> 0 | AH13: =AG13*$E$11 -> 0
B14: Elektro-Ing | D14: =Grafik!D14 -> 105 | E14: =D14*(1+Sicherheit)*(1+Gewinn) -> 121.56375 | F14: 1 | G14: 1 | H14: 5 | I14: =$I$5*F14*G14*H14 -> 5 | J14: =I14*$E$14 -> 607.81875 | L14: 1 | M14: 1 | N14: 5 | O14: =$O$5*L14*M14*N14 -> 5 | P14: =O14*$E$14 -> 607.81875 | R14: 1 | S14: 15 | T14: 8 | U14: =$U$5*R14*S14*T14 -> 120 | V14: =U14*$E$14 -> 14587.65 | X14: 0 | Y14: 0 | Z14: 0 | AA14: =$AA$5*X14*Y14*Z14 -> 0 | AB14: =AA14*$E$14 -> 0 | AD14: 0 | AE14: 0 | AF14: 0 | AG14: =$AG$5*AD14*AE14*AF14 -> 0 | AH14: =AG14*$E$14 -> 0 | AJ14: =SUM(I14:I16,O14:O16,U14:U16,AA14:AA16,AG14:AG16) -> 135 | AK14: =SUM(J14:J16,P14:P16,V14:V16,AB14:AB16,AH14:AH16) -> 16411.106
F15: 1 | G15: 1 | H15: 2.5 | I15: =$I$5*F15*G15*H15 -> 2.5 | J15: =I15*$E$14 -> 303.90938 | L15: 1 | M15: 1 | N15: 2.5 | O15: =$O$5*L15*M15*N15 -> 2.5 | P15: =O15*$E$14 -> 303.90938 | R15: 0 | S15: 0 | T15: 0 | U15: =$U$5*R15*S15*T15 -> 0 | V15: =U15*$E$14 -> 0 | X15: 0 | Y15: 0 | Z15: 0 | AA15: =$AA$5*X15*Y15*Z15 -> 0 | AB15: =AA15*$E$14 -> 0 | AD15: 0 | AE15: 0 | AF15: 0 | AG15: =$AG$5*AD15*AE15*AF15 -> 0 | AH15: =AG15*$E$14 -> 0
F16: 0 | G16: 0 | H16: 0 | I16: =$I$5*F16*G16*H16 -> 0 | J16: =I16*$E$14 -> 0 | L16: 0 | M16: 0 | N16: 0 | O16: =$O$5*L16*M16*N16 -> 0 | P16: =O16*$E$14 -> 0 | R16: 0 | S16: 0 | T16: 0 | U16: =$U$5*R16*S16*T16 -> 0 | V16: =U16*$E$14 -> 0 | X16: 0 | Y16: 0 | Z16: 0 | AA16: =$AA$5*X16*Y16*Z16 -> 0 | AB16: =AA16*$E$14 -> 0 | AD16: 0 | AE16: 0 | AF16: 0 | AG16: =$AG$5*AD16*AE16*AF16 -> 0 | AH16: =AG16*$E$14 -> 0
B17: Projektleiter | D17: =Grafik!D17 -> 110 | E17: =D17*(1+Sicherheit)*(1+Gewinn) -> 127.3525 | F17: 0 | G17: 0 | H17: 0 | I17: =$I$5*F17*G17*H17 -> 0 | J17: =I17*$E17 -> 0 | L17: 0 | M17: 0 | N17: 0 | O17: =$O$5*L17*M17*N17 -> 0 | P17: =O17*$E17 -> 0 | R17: 0 | S17: 0 | T17: 0 | U17: =$U$5*R17*S17*T17 -> 0 | V17: =U17*$E17 -> 0 | X17: 0 | Y17: 0 | Z17: 0 | AA17: =$AA$5*X17*Y17*Z17 -> 0 | AB17: =AA17*$E17 -> 0 | AD17: 0 | AE17: 0 | AF17: 0 | AG17: =$AG$5*AD17*AE17*AF17 -> 0 | AH17: =AG17*$E17 -> 0 | AJ17: =SUM(I17,O17,U17,AA17,AG17) -> 0 | AK17: =SUM(J17,P17,V17,AB17,AH17) -> 0
F18: Mann | G18: Tag | J18: Summe | L18: Mann | M18: Tag | P18: Summe | R18: Mann | S18: Tag | V18: Summe | X18: Mann | Y18: Tag | AB18: Summe | AD18: Mann | AE18: Tag | AH18: Summe
B19: Auslöse | D19: 52 | E19: =D19*(1+Sicherheit)*(1+Gewinn) -> 60.203 | F19: 1 | G19: 1 | J19: =$I$5*$E19*F19*G19 -> 60.203 | L19: 1 | M19: 1 | P19: =$O$5*$E19*L19*M19 -> 60.203 | R19: 1 | S19: 15 | V19: =$U$5*$E19*R19*S19 -> 903.045 | X19: 0 | Y19: 0 | AB19: =$AA$5*$E19*X19*Y19 -> 0 | AD19: 0 | AE19: 0 | AH19: =$AG$5*$E19*AD19*AE19 -> 0 | AK19: =SUM(J19,P19,V19,AB19,AH19) -> 1023.451
B20: Übernachtung | D20: 100 | E20: =D20*(1+Sicherheit)*(1+Gewinn) -> 115.775 | F20: 1 | G20: 1 | J20: =$I$5*$E20*F20*G20 -> 115.775 | L20: 1 | M20: 1 | P20: =$O$5*$E20*L20*M20 -> 115.775 | R20: 1 | S20: 15 | V20: =$U$5*$E20*R20*S20 -> 1736.625 | X20: 0 | Y20: 0 | AB20: =$AA$5*$E20*X20*Y20 -> 0 | AD20: 0 | AE20: 0 | AH20: =$AG$5*$E20*AD20*AE20 -> 0 | AK20: =SUM(J20,P20,V20,AB20,AH20) -> 1968.175
B21: Summe Arbeitskosten | J21: =SUM(J8:J20) -> 1087.7061 | P21: =SUM(P8:P20) -> 1087.7061 | V21: =SUM(V8:V20) -> 17227.32 | AB21: =SUM(AB8:AB20) -> 0 | AH21: =SUM(AH8:AH20) -> 0 | AK21: =SUM(J21,P21,V21,AB21,AH21) -> 19402.732
B23: Reisekosten | E23: brutto | F23: Mann | G23: Tag | H23: Std. | J23: Summe | L23: Mann | M23: Tag | N23: Std. | P23: Summe | R23: Mann | S23: Tag | T23: Std. | V23: Summe | X23: Mann | Y23: Tag | Z23: Std. | AB23: Summe | AD23: Mann | AE23: Tag | AF23: Std. | AH23: Summe
B24: Mechanik-Monteur | E24: =E8 -> 94.9355 | F24: 0 | G24: 0 | H24: 0 | I24: =$I$5*F24*G24*H24 -> 0 | J24: =$E24*I24 -> 0 | L24: 0 | M24: 0 | N24: 0 | O24: =$O$5*L24*M24*N24 -> 0 | P24: =$E24*O24 -> 0 | R24: 0 | S24: 0 | T24: 0 | U24: =$U$5*R24*S24*T24 -> 0 | V24: =$E24*U24 -> 0 | X24: 0 | Y24: 0 | Z24: 0 | AA24: =$AA$5*X24*Y24*Z24 -> 0 | AB24: =$E24*AA24 -> 0 | AD24: 0 | AE24: 0 | AF24: 0 | AG24: =$AG$5*AD24*AE24*AF24 -> 0 | AH24: =$E24*AG24 -> 0 | AJ24: =SUM(I24,O24,U24,AA24,AG24) -> 0 | AK24: =SUM(J24,P24,V24,AB24,AH24) -> 0
B25: Elektro-Monteur | E25: =E11 -> 94.9355 | F25: 0 | G25: 0 | H25: 0 | I25: =$I$5*F25*G25*H25 -> 0 | J25: =$E25*I25 -> 0 | L25: 0 | M25: 0 | N25: 0 | O25: =$O$5*L25*M25*N25 -> 0 | P25: =$E25*O25 -> 0 | R25: 0 | S25: 0 | T25: 0 | U25: =$U$5*R25*S25*T25 -> 0 | V25: =$E25*U25 -> 0 | X25: 0 | Y25: 0 | Z25: 0 | AA25: =$AA$5*X25*Y25*Z25 -> 0 | AB25: =$E25*AA25 -> 0 | AD25: 0 | AE25: 0 | AF25: 0 | AG25: =$AG$5*AD25*AE25*AF25 -> 0 | AH25: =$E25*AG25 -> 0 | AJ25: =SUM(I25,O25,U25,AA25,AG25) -> 0 | AK25: =SUM(J25,P25,V25,AB25,AH25) -> 0
B26: Elektro-Ing | E26: =E14 -> 121.56375 | F26: 1 | G26: 1 | H26: 4 | I26: =$I$5*F26*G26*H26 -> 4 | J26: =$E26*I26 -> 486.255 | L26: 1 | M26: 1 | N26: 4 | O26: =$O$5*L26*M26*N26 -> 4 | P26: =$E26*O26 -> 486.255 | R26: 1 | S26: 6 | T26: 4 | U26: =$U$5*R26*S26*T26 -> 24 | V26: =$E26*U26 -> 2917.53 | X26: 0 | Y26: 0 | Z26: 0 | AA26: =$AA$5*X26*Y26*Z26 -> 0 | AB26: =$E26*AA26 -> 0 | AD26: 0 | AE26: 0 | AF26: 0 | AG26: =$AG$5*AD26*AE26*AF26 -> 0 | AH26: =$E26*AG26 -> 0 | AJ26: =SUM(I26,O26,U26,AA26,AG26) -> 32 | AK26: =SUM(J26,P26,V26,AB26,AH26) -> 3890.04
B27: Projektleiter | E27: =E17 -> 127.3525 | F27: 0 | G27: 0 | H27: 0 | I27: =$I$5*F27*G27*H27 -> 0 | J27: =$E27*I27 -> 0 | L27: 0 | M27: 0 | N27: 0 | O27: =$O$5*L27*M27*N27 -> 0 | P27: =$E27*O27 -> 0 | R27: 0 | S27: 0 | T27: 0 | U27: =$U$5*R27*S27*T27 -> 0 | V27: =$E27*U27 -> 0 | X27: 0 | Y27: 0 | Z27: 0 | AA27: =$AA$5*X27*Y27*Z27 -> 0 | AB27: =$E27*AA27 -> 0 | AD27: 0 | AE27: 0 | AF27: 0 | AG27: =$AG$5*AD27*AE27*AF27 -> 0 | AH27: =$E27*AG27 -> 0 | AJ27: =SUM(I27,O27,U27,AA27,AG27) -> 0 | AK27: =SUM(J27,P27,V27,AB27,AH27) -> 0
E28: €/km | F28: km | J28: Summe | L28: km | P28: Summe | R28: km | V28: Summe | X28: km | AB28: Summe | AD28: km | AH28: Summe
B29: KM Firmen-PKW | D29: 0.6 | E29: =D29*(1+Sicherheit)*(1+Gewinn) -> 0.69465 | F29: 400 | J29: =$I$5*$E29*F29 -> 277.86 | L29: 400 | P29: =$O$5*$E29*L29 -> 277.86 | R29: 2400 | V29: =$U$5*$E29*R29 -> 1667.16 | X29: 0 | AB29: =$AA$5*$E29*X29 -> 0 | AD29: 0 | AH29: =$AG$5*$E29*AD29 -> 0 | AK29: =SUM(J29,P29,V29,AB29,AH29) -> 2222.88
F30: Anzahl | L30: Anzahl | R30: Anzahl | X30: Anzahl | AD30: Anzahl
B31: Flüge | F31: 0 | G31: 500 | J31: =$I$5*F31*G31*(1+Sicherheit)*(1+Gewinn) -> 0 | L31: 0 | M31: 0 | P31: =$O$5*L31*M31*(1+Sicherheit)*(1+Gewinn) -> 0 | R31: 0 | S31: 0 | V31: =$U$5*R31*S31*(1+Sicherheit)*(1+Gewinn) -> 0 | X31: 0 | Y31: 0 | AB31: =$AA$5*X31*Y31*(1+Sicherheit)*(1+Gewinn) -> 0 | AD31: 0 | AE31: 0 | AH31: =$AG$5*AD31*AE31*(1+Sicherheit)*(1+Gewinn) -> 0 | AK31: =SUM(J31,P31,V31,AB31,AH31) -> 0
B32: Taxi | F32: 0 | G32: 0 | J32: =$I$5*F32*G32*(1+Sicherheit)*(1+Gewinn) -> 0 | L32: 0 | M32: 0 | P32: =$O$5*L32*M32*(1+Sicherheit)*(1+Gewinn) -> 0 | R32: 0 | S32: 0 | V32: =$U$5*R32*S32*(1+Sicherheit)*(1+Gewinn) -> 0 | X32: 0 | Y32: 0 | AB32: =$AA$5*X32*Y32*(1+Sicherheit)*(1+Gewinn) -> 0 | AD32: 0 | AE32: 0 | AH32: =$AG$5*AD32*AE32*(1+Sicherheit)*(1+Gewinn) -> 0 | AK32: =SUM(J32,P32,V32,AB32,AH32) -> 0
B33: Leihauto | F33: 0 | G33: 0 | J33: =$I$5*F33*G33*(1+Sicherheit)*(1+Gewinn) -> 0 | L33: 0 | M33: 0 | P33: =$O$5*L33*M33*(1+Sicherheit)*(1+Gewinn) -> 0 | R33: 0 | S33: 0 | V33: =$U$5*R33*S33*(1+Sicherheit)*(1+Gewinn) -> 0 | X33: 0 | Y33: 0 | AB33: =$AA$5*X33*Y33*(1+Sicherheit)*(1+Gewinn) -> 0 | AD33: 0 | AE33: 0 | AH33: =$AG$5*AD33*AE33*(1+Sicherheit)*(1+Gewinn) -> 0 | AK33: =SUM(J33,P33,V33,AB33,AH33) -> 0
B34: Bus/Zug/Fähre | F34: 0 | G34: 0 | J34: =$I$5*F34*G34*(1+Sicherheit)*(1+Gewinn) -> 0 | L34: 0 | M34: 0 | P34: =$O$5*L34*M34*(1+Sicherheit)*(1+Gewinn) -> 0 | R34: 0 | S34: 0 | V34: =$U$5*R34*S34*(1+Sicherheit)*(1+Gewinn) -> 0 | X34: 0 | Y34: 0 | AB34: =$AA$5*X34*Y34*(1+Sicherheit)*(1+Gewinn) -> 0 | AD34: 0 | AE34: 0 | AH34: =$AG$5*AD34*AE34*(1+Sicherheit)*(1+Gewinn) -> 0 | AK34: =SUM(J34,P34,V34,AB34,AH34) -> 0
B35: sonstiges | F35: 0 | G35: 0 | J35: =$I$5*F35*G35*(1+Sicherheit)*(1+Gewinn) -> 0 | L35: 0 | M35: 0 | P35: =$O$5*L35*M35*(1+Sicherheit)*(1+Gewinn) -> 0 | R35: 0 | S35: 0 | V35: =$U$5*R35*S35*(1+Sicherheit)*(1+Gewinn) -> 0 | X35: 0 | Y35: 0 | AB35: =$AA$5*X35*Y35*(1+Sicherheit)*(1+Gewinn) -> 0 | AD35: 0 | AE35: 0 | AH35: =$AG$5*AD35*AE35*(1+Sicherheit)*(1+Gewinn) -> 0 | AK35: =SUM(J35,P35,V35,AB35,AH35) -> 0
B36: Summe Reisekosten | J36: =SUM(J24:J35) -> 764.115 | P36: =SUM(P24:P35) -> 764.115 | V36: =SUM(V24:V35) -> 4584.69 | AB36: =SUM(AB24:AB35) -> 0 | AH36: =SUM(AH24:AH35) -> 0 | AK36: =SUM(J36,P36,V36,AB36,AH36) -> 6112.92
B38: Summe Zuschläge | D38: 0.1 | E38: pauschal auf Arbeits-/Reisekosten | J38: =$D38*(SUM(J8:J17)+SUM(J24:J27)) -> 139.79831 | P38: =$D38*(SUM(P8:P17)+SUM(P24:P27)) -> 139.79831 | V38: =$D38*(SUM(V8:V17)+SUM(V24:V27)) -> 1750.518 | AB38: =$D38*(SUM(AB8:AB17)+SUM(AB24:AB27)) -> 0 | AH38: =$D38*(SUM(AH8:AH17)+SUM(AH24:AH27)) -> 0 | AK38: =SUM(J38,P38,V38,AB38,AH38) -> 2030.1146
F40: Annahme: Schulungsaufwand: 4 h pro Tag 1x Anreise jeweils 0,5h 1x Schulung Frühschicht 2h - Spätschicht 2h 1x Schulung Nachtschicht 2h 1x Rückreise jeweils 0,5h | L40: Annahme: Schulungsaufwand: 4 h pro Tag 1x Anreise 0,5h 1x Schulung Frühschicht 2h - Spätschicht 2h 1x Schulung Nachtschicht 2h 1x Rückreise 0,5h

Sheet 1
B2: M01 | C2: =Kunde -> BMW Leipzig | D2: =Anlage -> Schulung Hochlaufunterstützung
C3: Kalkulation Modul | D3: =Übersicht!C8 -> 0 | W3: =Übersicht!F8 -> 1
C4: =Angebotsnummer -> A07614700 | D4: =Datum -> 45642 | F4: =Bearbeiter -> Harald Waas | W4: =Übersicht!V8 -> 0
B6: 1 | C6: M-Konstruktion | D6: =SUM(L13,L25,L37,L49,L61,L73,L85,L97,L109,L121,L133,L145,L157,L169,L181,L193,L205,L217,L229,L241,L253,L265,L277,L289,L301,L313,L325,L337,L349,L361) -> 0 | E6: =Konstruktion -> 115.775 | F6: =D6*E6 -> 0 | H6: 5 | I6: E-Konstruktion | L6: =SUM(M13,M25,M37,M49,M61,M73,M85,M97,M109,M121,M133,M145,M157,M169,M181,M193,M205,M217,M229,M241,M253,M265,M277,M289,M301,M313,M325,M337,M349,M361) -> 0 | M6: =Hardware -> 106.513 | O6: =L6*M6 -> 0
B7: 2 | C7: Montage | D7: =SUM(Q13,Q25,Q37,Q49,Q61,Q73,Q85,Q97,Q109,Q121,Q133,Q145,Q157,Q169,Q181,Q193,Q205,Q217,Q229,Q241,Q253,Q265,Q277,Q289,Q301,Q313,Q325,Q337,Q349,Q361) -> 0 | E7: =Montage -> 94.9355 | F7: =D7*E7 -> 0 | H7: 6 | I7: Software | L7: =SUM(N13,N25,N37,N49,N61,N73,N85,N97,N109,N121,N133,N145,N157,N169,N181,N193,N205,N217,N229,N241,N253,N265,N277,N289,N301,N313,N325,N337,N349,N361) -> 0 | M7: =Software -> 121.56375 | O7: =L7*M7 -> 0
B8: 3 | C8: Fertigung | D8: =SUM(R13,R25,R37,R49,R61,R73,R85,R97,R109,R121,R133,R145,R157,R169,R181,R193,R205,R217,R229,R241,R253,R265,R277,R289,R301,R313,R325,R337,R349,R361) -> 0 | E8: =Fertigung -> 98.40875 | F8: =D8*E8 -> 0 | H8: 7 | I8: Inbetriebnahme | L8: =SUM(O13,O25,O37,O49,O61,O73,O85,O97,O109,O121,O133,O145,O157,O169,O181,O193,O205,O217,O229,O241,O253,O265,O277,O289,O301,O313,O325,O337,O349,O361) -> 0 | M8: =INB -> 121.56375 | O8: =L8*M8 -> 0
B9: 4 | C9: Materialkosten | E9: VK | F9: =SUM(U13,U25,U37,U49,U61,U73,U85,U97,U109,U121,U133,U145,U157,U169,U181,U193,U205,U217,U229,U241,U253,U265,U277,U289,U301,U313,U325,U337,U349,U361) -> 0 | H9: 8 | I9: SSB/Installation | L9: =SUM(P13,P25,P37,P49,P61,P73,P85,P97,P109,P121,P133,P145,P157,P169,P181,P193,P205,P217,P229,P241,P253,P265,P277,P289,P301,P313,P325,P337,P349,P361) -> 0 | M9: =Elektrik -> 94.9355 | O9: =L9*M9 -> 0
B11: Pos | C11: Bezeichnung | G11: Bemerkung | L11: MK | M11: EKo | N11: SW | O11: Inb | P11: El | Q11: Mo | R11: TF | S11: Stück | T11: €/Stück | U11: KT | V11: TF/€ | W11: Summe
B13: 1 | L13: =SUM(L14:L23) -> 0 | M13: =SUM(M14:M23) -> 0 | N13: =SUM(N14:N23) -> 0 | O13: =SUM(O14:O23) -> 0 | P13: =SUM(P14:P23) -> 0 | Q13: =SUM(Q14:Q23) -> 0 | R13: =SUM(R14:R23) -> 0 | S13: 1 | T13: =(S14*T14)+(S15*T15)+(S16*T16)+(S17*T17)+(S18*T18)+(S19*T19)+(S20*T20)+(S21*T21)+(S22*T22)+(S23*T23) -> 0 | U13: =S13*T13*(1+MGKZ)*(1+Gewinn)*(1+Sicherheit) -> 0 | V13: =R13*Fertigung -> 0 | W13: =L13*$E$6+M13*$M$6+N13*$M$7+O13*$M$8+P13*$E$7+Q13*$M$9+U13+V13 -> 0
U14: =S14*T14*(1+MGKZ)*(1+Gewinn)*(1+Sicherheit) -> 0 | V14: =R14*Fertigung -> 0 | W14: =L14*$E$6+M14*$M$6+N14*$M$7+O14*$M$8+P14*$E$7+Q14*$M$9+U14+V14 -> 0
U15: =S15*T15*(1+MGKZ)*(1+Gewinn)*(1+Sicherheit) -> 0 | V15: =R15*Fertigung -> 0 | W15: =L15*$E$6+M15*$M$6+N15*$M$7+O15*$M$8+P15*$E$7+Q15*$M$9+U15+V15 -> 0
U16: =S16*T16*(1+MGKZ)*(1+Gewinn)*(1+Sicherheit) -> 0 | V16: =R16*Fertigung -> 0 | W16: =L16*$E$6+M16*$M$6+N16*$M$7+O16*$M$8+P16*$E$7+Q16*$M$9+U16+V16 -> 0
U17: =S17*T17*(1+MGKZ)*(1+Gewinn)*(1+Sicherheit) -> 0 | V17: =R17*Fertigung -> 0 | W17: =L17*$E$6+M17*$M$6+N17*$M$7+O17*$M$8+P17*$E$7+Q17*$M$9+U17+V17 -> 0
U18: =S18*T18*(1+MGKZ)*(1+Gewinn)*(1+Sicherheit) -> 0 | V18: =R18*Fertigung -> 0 | W18: =L18*$E$6+M18*$M$6+N18*$M$7+O18*$M$8+P18*$E$7+Q18*$M$9+U18+V18 -> 0
U19: =S19*T19*(1+MGKZ)*(1+Gewinn)*(1+Sicherheit) -> 0 | V19: =R19*Fertigung -> 0 | W19: =L19*$E$6+M19*$M$6+N19*$M$7+O19*$M$8+P19*$E$7+Q19*$M$9+U19+V19 -> 0
U20: =S20*T20*(1+MGKZ)*(1+Gewinn)*(1+Sicherheit) -> 0 | V20: =R20*Fertigung -> 0 | W20: =L20*$E$6+M20*$M$6+N20*$M$7+O20*$M$8+P20*$E$7+Q20*$M$9+U20+V20 -> 0
U21: =S21*T21*(1+MGKZ)*(1+Gewinn)*(1+Sicherheit) -> 0 | V21: =R21*Fertigung -> 0 | W21: =L21*$E$6+M21*$M$6+N21*$M$7+O21*$M$8+P21*$E$7+Q21*$M$9+U21+V21 -> 0
U22: =S22*T22*(1+MGKZ)*(1+Gewinn)*(1+Sicherheit) -> 0 | V22: =R22*Fertigung -> 0 | W22: =L22*$E$6+M22*$M$6+N22*$M$7+O22*$M$8+P22*$E$7+Q22*$M$9+U22+V22 -> 0
U23: =S23*T23*(1+MGKZ)*(1+Gewinn)*(1+Sicherheit) -> 0 | V23: =R23*Fertigung -> 0 | W23: =L23*$E$6+M23*$M$6+N23*$M$7+O23*$M$8+P23*$E$7+Q23*$M$9+U23+V23 -> 0
B25: =B13+1 -> 2 | L25: =SUM(L26:L35) -> 0 | M25: =SUM(M26:M35) -> 0 | N25: =SUM(N26:N35) -> 0 | O25: =SUM(O26:O35) -> 0 | P25: =SUM(P26:P35) -> 0 | Q25: =SUM(Q26:Q35) -> 0 | R25: =SUM(R26:R35) -> 0 | S25: 1 | T25: =(S26*T26)+(S27*T27)+(S28*T28)+(S29*T29)+(S30*T30)+(S31*T31)+(S32*T32)+(S33*T33)+(S34*T34)+(S35*T35) -> 0 | U25: =S25*T25*(1+MGKZ)*(1+Gewinn)*(1+Sicherheit) -> 0 | V25: =R25*Fertigung -> 0 | W25: =L25*$E$6+M25*$M$6+N25*$M$7+O25*$M$8+P25*$E$7+Q25*$M$9+U25+V25 -> 0
U26: =S26*T26*(1+MGKZ)*(1+Gewinn)*(1+Sicherheit) -> 0 | V26: =R26*Fertigung -> 0 | W26: =L26*$E$6+M26*$M$6+N26*$M$7+O26*$M$8+P26*$E$7+Q26*$M$9+U26+V26 -> 0
U27: =S27*T27*(1+MGKZ)*(1+Gewinn)*(1+Sicherheit) -> 0 | V27: =R27*Fertigung -> 0 | W27: =L27*$E$6+M27*$M$6+N27*$M$7+O27*$M$8+P27*$E$7+Q27*$M$9+U27+V27 -> 0
U28: =S28*T28*(1+MGKZ)*(1+Gewinn)*(1+Sicherheit) -> 0 | V28: =R28*Fertigung -> 0 | W28: =L28*$E$6+M28*$M$6+N28*$M$7+O28*$M$8+P28*$E$7+Q28*$M$9+U28+V28 -> 0
U29: =S29*T29*(1+MGKZ)*(1+Gewinn)*(1+Sicherheit) -> 0 | V29: =R29*Fertigung -> 0 | W29: =L29*$E$6+M29*$M$6+N29*$M$7+O29*$M$8+P29*$E$7+Q29*$M$9+U29+V29 -> 0
U30: =S30*T30*(1+MGKZ)*(1+Gewinn)*(1+Sicherheit) -> 0 | V30: =R30*Fertigung -> 0 | W30: =L30*$E$6+M30*$M$6+N30*$M$7+O30*$M$8+P30*$E$7+Q30*$M$9+U30+V30 -> 0
U31: =S31*T31*(1+MGKZ)*(1+Gewinn)*(1+Sicherheit) -> 0 | V31: =R31*Fertigung -> 0 | W31: =L31*$E$6+M31*$M$6+N31*$M$7+O31*$M$8+P31*$E$7+Q31*$M$9+U31+V31 -> 0
U32: =S32*T32*(1+MGKZ)*(1+Gewinn)*(1+Sicherheit) -> 0 | V32: =R32*Fertigung -> 0 | W32: =L32*$E$6+M32*$M$6+N32*$M$7+O32*$M$8+P32*$E$7+Q32*$M$9+U32+V32 -> 0
U33: =S33*T33*(1+MGKZ)*(1+Gewinn)*(1+Sicherheit) -> 0 | V33: =R33*Fertigung -> 0 | W33: =L33*$E$6+M33*$M$6+N33*$M$7+O33*$M$8+P33*$E$7+Q33*$M$9+U33+V33 -> 0
U34: =S34*T34*(1+MGKZ)*(1+Gewinn)*(1+Sicherheit) -> 0 | V34: =R34*Fertigung -> 0 | W34: =L34*$E$6+M34*$M$6+N34*$M$7+O34*$M$8+P34*$E$7+Q34*$M$9+U34+V34 -> 0
U35: =S35*T35*(1+MGKZ)*(1+Gewinn)*(1+Sicherheit) -> 0 | V35: =R35*Fertigung -> 0 | W35: =L35*$E$6+M35*$M$6+N35*$M$7+O35*$M$8+P35*$E$7+Q35*$M$9+U35+V35 -> 0
B37: =B25+1 -> 3 | L37: =SUM(L38:L47) -> 0 | M37: =SUM(M38:M47) -> 0 | N37: =SUM(N38:N47) -> 0 | O37: =SUM(O38:O47) -> 0 | P37: =SUM(P38:P47) -> 0 | Q37: =SUM(Q38:Q47) -> 0 | R37: =SUM(R38:R47) -> 0 | S37: 1 | T37: =(S38*T38)+(S39*T39)+(S40*T40)+(S41*T41)+(S42*T42)+(S43*T43)+(S44*T44)+(S45*T45)+(S46*T46)+(S47*T47) -> 0 | U37: =S37*T37*(1+MGKZ)*(1+Gewinn)*(1+Sicherheit) -> 0 | V37: =R37*Fertigung -> 0 | W37: =L37*$E$6+M37*$M$6+N37*$M$7+O37*$M$8+P37*$E$7+Q37*$M$9+U37+V37 -> 0
U38: =S38*T38*(1+MGKZ)*(1+Gewinn)*(1+Sicherheit) -> 0 | V38: =R38*Fertigung -> 0 | W38: =L38*$E$6+M38*$M$6+N38*$M$7+O38*$M$8+P38*$E$7+Q38*$M$9+U38+V38 -> 0
U39: =S39*T39*(1+MGKZ)*(1+Gewinn)*(1+Sicherheit) -> 0 | V39: =R39*Fertigung -> 0 | W39: =L39*$E$6+M39*$M$6+N39*$M$7+O39*$M$8+P39*$E$7+Q39*$M$9+U39+V39 -> 0
U40: =S40*T40*(1+MGKZ)*(1+Gewinn)*(1+Sicherheit) -> 0 | V40: =R40*Fertigung -> 0 | W40: =L40*$E$6+M40*$M$6+N40*$M$7+O40*$M$8+P40*$E$7+Q40*$M$9+U40+V40 -> 0
U41: =S41*T41*(1+MGKZ)*(1+Gewinn)*(1+Sicherheit) -> 0 | V41: =R41*Fertigung -> 0 | W41: =L41*$E$6+M41*$M$6+N41*$M$7+O41*$M$8+P41*$E$7+Q41*$M$9+U41+V41 -> 0
U42: =S42*T42*(1+MGKZ)*(1+Gewinn)*(1+Sicherheit) -> 0 | V42: =R42*Fertigung -> 0 | W42: =L42*$E$6+M42*$M$6+N42*$M$7+O42*$M$8+P42*$E$7+Q42*$M$9+U42+V42 -> 0
