Workbook
Name HT_Fertigungsprozesse: #REF!
Name HT_Fertigungsprozesse: #REF!
Name HT_Fertigungsprozesse: #REF!
Name Text: '2. Proof'!#REF!
Name Text: '1. Supplier information'!#REF!
Name Text: '1. Supplier information'!#REF!

Sheet 0. Instruction
B2: IT-Security questionnaire for MAE - Instructions
B4: General notes
B5: Product responsibility | C5: A production planner that chooses IT-products is the product-responsible for this selection for the entire service life of the product.
B7: Scope | C7: This checklist helps assessing the IT-Security of machines, installations and production equipment or components and/or product groups. It especially supports the analysis and comparison of new MAE within the framework of the procurement process.
B8: Procedure | C8: The questionnaire asks questions about various security-relevant areas. The Bosch-Norm is used during the purchase of IT-devices or MAE. A preselection was done in order to keep the number of points in the evaluation sheet manageable. Tab 1 in the questionnaire divided into: - Processes - Hardware - Security updates - Software - Training - Maintenance - IT-Security of the organization - Backup and Recovery - Emergency planning - Remote maintenance/Remote access - Data processing Tab 2 in the questionnaire is divided into: - General - Sustainability - Hardening - Terms of a license - Authentication - Network - Wireless communication Tab 3 prompts for details of the IT-devices. This way, a comparison of the deliverabilities from tab 1 and up to the IT-device capabilities from tab 3 is made possible. Tab 4 of the questionnaire asks questions about the details of the IT-device in the context of the MAE. In the end, an inventory of the IT-devices installed in the machine should be created, which can be transferred to the CMDB and a network planning should be possible.
B9: Protection from incorrect entries | C9: Cells that should not be edited by the processor are generally protected. Sheet protection should therefore be removed only in exceptional cases.
B10: Phases of execution
B11: Notes on execution 1.
A12: 2 | B12: Notes on execution 2.
B13: Notes on execution 3.
C14: File name and versioning The IT-Security questionnaire should be named according to the following convention: Name [of the project]_inquiring operating unit [GB]_Date [Year][Month][Day]_Version[V.0.0].file extension. The main versions should be described as follows: • Version V.1.0 indicates the time after placement of order • Version V.2.0 indicates the time after project closure. Examples: • HDEV10_PS_20190228_V.1.0.xlsx = During order placement • HDEV10_PS_20190628_V.2.0.xlsx = During project closure Storage location Once the project has been finished, the completed IT security questionnaire must be stored in the following SharePoint: SharePoint: 2018_Purchasing_Guideline Select here the folder corresponding to the division.
B15: Evaluation
B16: Status | C16: Version 2.0
B17: Date | C17: 43556
B18: Author | C18: C/TED1 Holtmannspötter

Sheet 1. Supplier information
E2: IT-Security questionnaire for MAE | F2: - Self-declaration by supplier
A4: MAE-Suppliers | B4: Component suppliers | E4: Plant data
E5: Division | F5: Please select | G5: Product | H5: Text
E6: Plant | F6: Please select | G6: Product variant | H6: Text
E7: Editor: Department / Name | F7: Text
E9: Manufacturer data
E10: Manufacturer name | F10: Text
E11: Manufacturer no. at Bosch | F11: Text
E12: Editor: Department / Name | F12: Text
E13: Creation: Version [xx.yy]/ Date [dd.mm.yyyy] | F13: Text
A15: ✓ | B15: ✓ | D15: 1. | E15: 1. Processes
A16: ✓ | B16: ✓ | D16: 1.1 | E16: Are the IT-devices scanned with a virus scanner with the up-to-date patterns before the delivery? (even if only one device is not scanned => NO) | F16: Please select | G16: Text | H16: Security
A17: ✓ | B17: ✓ | D17: 1.2 | E17: Do you have a process with which the IT-devices are provided the most up-to-date patches/whitelists/patterns? | F17: Please select | H17: Security
A18: ✓ | B18: ✓ | D18: 1.3 | E18: Are software updates made available to the user after the delivery? | F18: Please select | H18: Security
A19: ✓ | B19: ✓ | D19: 1.4 | E19: |--- If YES, do you provide the documentation which describes the installation, configuration and update of the system? | F19: Please select | H19: Security
A20: ✓ | B20: x | D20: 2. | E20: 2. Hardware
A21: ✓ | B21: x | D21: 2.1 | E21: Do you use hardware from a Bosch preference list as IT-device? | F21: Please select | H21: Technology
A22: ✓ | B22: x | D22: 2.2 | E22: |--- If No, are you aware of the Bosch preference list? | F22: Please select | H22: Technology
A23: ✓ | B23: x | D23: 2.3 | E23: |--- If Yes, what are the justifications for using alternative IT-devices | G23: Text | H23: Technology
A24: ✓ | B24: ✓ | D24: 3. | E24: 3. Security updates
A25: ✓ | B25: ✓ | D25: 3.1 | E25: Do you provide regular security updates? | F25: Please select | H25: Security
A26: ✓ | B26: ✓ | D26: 3.2 | E26: Do you have a process-responsible for the release and documentation of security patches? | F26: Please select | H26: Security
A27: ✓ | B27: ✓ | D27: 3.3 | E27: |--- If Yes, please enter contact details. | G27: Text | H27: Security
A28: ✓ | B28: ✓ | D28: 3.4 | E28: Do you promptly inform your customers about current security gaps of the IT-device (max. after 3 working days)? | F28: Please select | H28: Security
A29: ✓ | B29: ✓ | D29: 3.5 | E29: |--- If Yes, how is this information made available? | G29: Text | H29: Security
A30: ✓ | B30: ✓ | D30: 3.6 | E30: |--- If Yes, is the user informed about how the update has to be installed? | F30: Please select | H30: Security
A31: ✓ | B31: ✓ | D31: 3.7 | E31: Are any compatibility tests carried out against the delivery state? | F31: Please select | H31: Security
A32: ✓ | B32: ✓ | D32: 3.8 | E32: Is it possible to install updates through remote access? | F32: Please select | H32: Security
A33: ✓ | B33: ✓ | D33: 4. | E33: 4. Software
A34: ✓ | B34: ✓ | D34: 4.1 | E34: Is the user allowed to carry out application updates? | F34: Please select | H34: Maintenance
A35: ✓ | B35: ✓ | D35: 4.2 | E35: |--- If Yes, which conditions have to be fulfilled? (Trainings, calibrations, technical knowledge, ….) Answer for each IT-device | G35: Text | H35: Maintenance
A36: ✓ | B36: ✓ | D36: 4.3 | E36: Is the user allowed to install additional software? | F36: Please select | H36: Maintenance & Documentation
A37: ✓ | B37: ✓ | D37: 4.4 | E37: |--- Virus scanner? | F37: Please select | H37: Documentation
A38: ✓ | B38: ✓ | D38: 4.5 | E38: |--- BackupAgent? | F38: Please select | H38: Documentation
A39: ✓ | B39: ✓ | D39: 4.6 | E39: |--- InventoryAgent? | F39: Please select | H39: Documentation
A40: ✓ | B40: ✓ | D40: 4.7 | E40: |--- Operating system patches? | F40: Please select | H40: Documentation
A41: ✓ | B41: ✓ | D41: 4.8 | E41: |--- Does the manufacturer's warranty remain valid? | F41: Please select | H41: Documentation
A42: ✓ | B42: ✓ | D42: 4.9 | E42: |--- Others | G42: Text | H42: Documentation
A43: ✓ | B43: ✓ | D43: 4.10 | E43: Is it permissible to create a copy/image of the entire system in order to create backup? | F43: Please select | H43: Documentation
A44: ✓ | B44: ✓ | D44: 4.11 | E44: What should not be installed? | G44: Text | H44: Documentation
...

Sheet 2. Proof
E2: IT-Security questionnaire for MAE | F2: - 2a. Evaluation
E4: Plant data
E5: Division | F5: ='1. Supplier information'!$F$5 -> Please select | G5: Product | H5: ='1. Supplier information'!$H$5 -> Text
A6: MAE-Suppliers | B6: Component suppliers | E6: Plant | F6: ='1. Supplier information'!$F$6 -> Please select | G6: Product variant | H6: ='1. Supplier information'!$H$6 -> Text
E7: MAE processor: Department / Name | F7: ='1. Supplier information'!$F$7:H7 -> Text
E9: Manufacturer data
E10: MAE type/components/product groups | F10: ='1. Supplier information'!F10:H10 -> Text
E11: MAE manufacturer/supplier | F11: ='1. Supplier information'!F11:H11 -> Text
E12: Editor: Department / Name | F12: ='1. Supplier information'!F12:H12 -> Text
E13: Creation: Status / Date | F13: ='1. Supplier information'!F13:H13 -> Text
E16: Technical question | F16: Evaluation | G16: Reason / Explanations | H16: Evaluation criteria
A17: ✓ | B17: ✓ | D17: 12. | E17: 12. General
A18: ✓ | B18: ✓ | D18: 12.1 | E18: Which manufacturer / which IT-device model do you use? | G18: => Tab 3. Planned IT-devices; Column | Manufacturer name | Manufacturer order no. | | H18: Security
A19: ✓ | B19: ✓ | D19: 12.2 | E19: Which operating system and which service pack do your IT-devices use? | G19: => Tab 3. Planned IT-devices; Column | Operating system | Service pack | | H19: Security
A20: ✓ | B20: ✓ | D20: 12.3 | E20: Has a virus scanner been installed on the IT-devices? | F20: Please select | H20: Security
A21: ✓ | B21: ✓ | D21: 12.4 | E21: |--- If Yes, which virus scanner do you use? | G21: Yes => Tab 3. Planned IT-devices; Column | Remark | | H21: Security
A22: ✓ | B22: ✓ | D22: 12.5 | E22: Has a firewall been activated and configured on the IT-device(s)? | F22: Please select | H22: Security
A23: ✓ | B23: ✓ | D23: 12.6 | E23: |---If Yes, which firewall do you use? | G23: Yes => Tab 3. Planned IT-devices; Column | Remark | | H23: Security
A24: ✓ | B24: ✓ | D24: 12.7 | E24: Is it possible for the IT-devices to synchronize through a central time server? (e.g., NTP, SNTP) | G24: Yes => Tab 3. Planned IT-devices; Column | NTP | | H24: Security
A25: ✓ | B25: ✓ | D25: 12.8 | E25: Can you show an evaluation of the Security Level according to IEC 62443-2-4:2015-06 for the used IT-devices? (SL-C) | F25: Please select | G25: Yes => Tab 3. Planned IT-devices; Column | Security-Level-C as per IEC62443 | | H25: Security
A26: ✓ | B26: ✓ | D26: 12.9 | E26: Is there an SEP for your product? | F26: Please select | G26: Yes => Tab 3. Planned IT-devices; Column | SEP | | H26: Security
A27: ✓ | B27: ✓ | D27: 13. | E27: 13. Sustainability
A28: ✓ | B28: ✓ | D28: 13.1 | E28: Is the IT-device equipped with the current operating system that is available on the market? | G28: => Tab 3. Planned IT-devices; Column | Operating system |
A29: ✓ | B29: ✓ | D29: 13.2 | E29: Which IT-devices are IPv4 or IPv6 enabled? | G29: => Tab 3. Planned IT-devices; Column | IPvx | | H29: Technology
A30: ✓ | B30: ✓ | D30: 13.3 | E30: Is it possible to operate without WINS? | F30: Please select | G30: No => Tab 3. Planned IT-devices; Column | Remark | | H30: Technology
A31: ✓ | B31: ✓ | D31: 13.4 | E31: Is an AD integration possible? | F31: Please select | G31: No => Tab 3. Planned IT-devices; Column | Remark | | H31: Technology
A32: ✓ | B32: ✓ | D32: 13.5 | E32: Is the availability of spare parts for your IT-devices ensured? | F32: Please select | G32: Yes => Tab 3. Planned IT-devices; Column | Availability of replacement units till …[year] | | H32: Technology
A33: ✓ | B33: ✓ | D33: 14. | E33: 14. Hardening
A34: ✓ | B34: x | D34: 14.1 | E34: Are the ports such as USB, SMART Card, FireWire, RJ45, etc., which are not required for maintenance, deactivated or made inaccessible? | F34: Please select | H34: Security
A35: ✓ | B35: x | D35: 14.2 | E35: |--- If No, why? | G35: No => Tab 3. Planned IT-devices; Column | Documentation | | H35: Security
A36: ✓ | B36: ✓ | D36: 14.3 | E36: Can you provide a documentation on the hardening of the IT-devices? | F36: Please select | H36: Security
A37: ✓ | B37: ✓ | D37: 14.4 | E37: Were certain network services deactivated in order to increase the security? | F37: Please select | G37: Yes => Tab 3. Planned IT-devices; Column | Documentation | | H37: Security
A38: ✓ | B38: ✓ | D38: 14.5 | E38: Were software that are not required removed from the system? | F38: Please select | G38: Yes => Tab 3. Planned IT-devices; Column | Documentation | | H38: Security
A39: ✓ | B39: ✓ | D39: 14.6 | E39: Is there a software inventory of the IT-devices? | F39: Please select | G39: Yes => Tab 3. Planned IT-devices; Column | Documentation | | H39: Security
A40: ✓ | B40: ✓ | D40: 14.7 | E40: |--- If Yes, can it be made available? ( in which format - *.txt; *.xls; *.csv, … ) | G40: Text; can also be delivered as appendix | H40: Security & Inventory
A41: ✓ | B41: ✓ | D41: 14.8 | E41: Are there documented interfaces to the IDS-/IPS-systems? (e.g. Sysmon) | F41: Please select | G41: Yes => Tab 3. Planned IT-devices; Column | Documentation | | H41: Security
A42: ✓ | B42: ✓ | D42: 15. | E42: 15. License conditions
A43: ✓ | B43: ✓ | D43: 15.1 | E43: Are software licenses necessary? | F43: Please select | H43: Inventory
A44: ✓ | B44: ✓ | D44: 15.2 | E44: |--- If Yes, which ones for which IT-devices | G44: Yes => Tab 3. Planned IT-devices; Column | Documentation | | H44: Inventory
A45: ✓ | B45: ✓ | D45: 15.3 | E45: Are continuing license fees required for the operation? | F45: Please select | G45: Yes => Tab 3. Planned IT-devices; Column | Documentation | | H45: Inventory
...

Sheet 3. Part-A Planned IT devices
C2: IT-Security questionnaire for MAE | F2: Part-A - Planned IT-devices
A3: List of IT-devices, which are likely to be used
A4: No. | B4: In the project | C4: Function / Description | D4: Manufacturer | E4: Manufacturer name | F4: Manufacturer order no. | G4: Availability of replacement units till … | H4: Security-Level-C as per IEC62443 | I4: Operating system | J4: Service pack/ Build | K4: IPvx | L4: Time server | M4: SEP | N4: Authentication | O4: Documentation | P4: Comment
A5: Example | B5: X | C5: L40 - Installation control | D5: Rexroth | E5: Rexroth IndraLogic L40 04VRS | F5: R911323261 | G5: 202x | H5: SL-C 1 | I5: VX | J5: SP1 | K5: IPV4 | L5: NTP | M5: yes | N5: For this, refer to the attached description in the appendix of the IT-Security questionnaire. | O5: Service and Support - www.boschrexroth.com
A6: 1 | C6: Text | D6: Text | E6: Text | F6: Text | G6: Text | H6: Please select | I6: Please select | J6: Please select | K6: Please select | L6: Please select | M6: Please select | N6: Text | O6: Text | P6: Text
A7: 2 | C7: Text | D7: Text | E7: Text | F7: Text | G7: Text | H7: Please select | I7: Please select | J7: Please select | K7: Please select | L7: Please select | M7: Please select | N7: Text | O7: Text | P7: Text
A8: 3 | C8: Text | D8: Text | E8: Text | F8: Text | G8: Text | H8: Please select | I8: Please select | J8: Please select | K8: Please select | L8: Please select | M8: Please select | N8: Text | O8: Text | P8: Text
A9: 4 | C9: Text | D9: Text | E9: Text | F9: Text | G9: Text | H9: Please select | I9: Please select | J9: Please select | K9: Please select | L9: Please select | M9: Please select | N9: Text | O9: Text | P9: Text
A10: 5 | C10: Text | D10: Text | E10: Text | F10: Text | G10: Text | H10: Please select | I10: Please select | J10: Please select | K10: Please select | L10: Please select | M10: Please select | N10: Text | O10: Text | P10: Text
A11: 6 | C11: Text | D11: Text | E11: Text | F11: Text | G11: Text | H11: Please select | I11: Please select | J11: Please select | K11: Please select | L11: Please select | M11: Please select | N11: Text | O11: Text | P11: Text
A12: 7 | C12: Text | D12: Text | E12: Text | F12: Text | G12: Text | H12: Please select | I12: Please select | J12: Please select | K12: Please select | L12: Please select | M12: Please select | N12: Text | O12: Text | P12: Text
A13: 8 | C13: Text | D13: Text | E13: Text | F13: Text | G13: Text | H13: Please select | I13: Please select | J13: Please select | K13: Please select | L13: Please select | M13: Please select | N13: Text | O13: Text | P13: Text
A14: 9 | C14: Text | D14: Text | E14: Text | F14: Text | G14: Text | H14: Please select | I14: Please select | J14: Please select | K14: Please select | L14: Please select | M14: Please select | N14: Text | O14: Text | P14: Text
A15: 10 | C15: Text | D15: Text | E15: Text | F15: Text | G15: Text | H15: Please select | I15: Please select | J15: Please select | K15: Please select | L15: Please select | M15: Please select | N15: Text | O15: Text | P15: Text
A16: 11 | C16: Text | D16: Text | E16: Text | F16: Text | G16: Text | H16: Please select | I16: Please select | J16: Please select | K16: Please select | L16: Please select | M16: Please select | N16: Text | O16: Text | P16: Text
A17: 12 | C17: Text | D17: Text | E17: Text | F17: Text | G17: Text | H17: Please select | I17: Please select | J17: Please select | K17: Please select | L17: Please select | M17: Please select | N17: Text | O17: Text | P17: Text
... A30: 25 | C30: Text | D30: Text | E30: Text | F30: Text | G30: Text | H30: Please select | I30: Please select | J30: Please select | K30: Please select | L30: Please select | M30: Please select | N30: Text | O30: Text | P30: Text

Sheet 4. Part B Installed IT devices
B2: IT-Security questionnaire for MAE | D2: Part B - Installed IT-devices in the MAE | N2: Part B - Installed IT-devices - Network planning for the MAE
D3: IT-device
A4: No. | B4: Classification criterion | C4: Name / Description of the machine | D4: Description of IPC, HMI, IC | E4: Serial number | F4: Safety comp. | G4: Network connections | H4: Networking | I4: MAC address | J4: Configuration ports | K4: Communication ports | L4: Server connection | M4: No. | N4: Classification criterion | O4: Description of IPC, HMI, IC | P4: Server connection IP address | Q4: Host name | R4: IP address | S4: Subnet mask | T4: Gateway | U4: Comment
A6: Example | B6: Line 1, Station 20 | C6: Dispensing housing covers | D6: mPad | E6: xxxx.xxxx.xxx | F6: No | G6: LAN | H6: only reachable from Bosch network | M6: Exa. | N6: Line 1, Station 20 | O6: mPad | Q6: H10_L1STA20_1_WE120 | R6: xxx.xxx.xxx.xxx | S6: 255.255.xxx.xxx | T6: xxx.xxx.xxx.xxx | U6: Hall 10; Line 1; Station 20; Device_1; Workshop 120
A7: Example | B7: Line 1, Station 20 | C7: Dispensing housing covers | D7: VPB40 | E7: xxxx.xxxx.xxx | F7: No | G7: LAN | H7: internal machine network and reachable from the Bosch network | I7: 00:00:00:00:00:00 | K7: 1065 | L7: Server connection to the MES | M7: Exa. | N7: Line 1, Station 20 | O7: VPB40 | P7: IP 10.103.xxx.xxx | Q7: H10_L1STA20_2_WE120 | R7: xxx.xxx.xxx.xxx | S7: 255.255.xxx.xxx | T7: xxx.xxx.xxx.xxx | U7: Hall 10; Line 1; Station 20; Device_2; Workshop 120
A8: 1 | B8: Text | C8: Text | D8: Please select | E8: Text | F8: Please select | G8: Please select | H8: Please select | I8: Text | J8: Text | K8: Text | L8: Text | M8: =A8 -> 1 | N8: =B8 -> Text | O8: =D8 -> Please select | P8: Text | Q8: Text | R8: Text | S8: Text | T8: Text | U8: Text
A9: 2 | B9: Text | C9: Text | D9: Please select | E9: Text | F9: Please select | G9: Please select | H9: Please select | I9: Text | J9: Text | K9: Text | L9: Text | M9: =A9 -> 2 | N9: =B9 -> Text | O9: =D9 -> Please select | P9: Text | Q9: Text | R9: Text | S9: Text | T9: Text | U9: Text
A10: 3 | B10: Text | C10: Text | D10: Please select | E10: Text | F10: Please select | G10: Please select | H10: Please select | I10: Text | J10: Text | K10: Text | L10: Text | M10: =A10 -> 3 | N10: =B10 -> Text | O10: =D10 -> Please select | P10: Text | Q10: Text | R10: Text | S10: Text | T10: Text | U10: Text
A11: 4 | B11: Text | C11: Text | D11: Please select | E11: Text | F11: Please select | G11: Please select | H11: Please select | I11: Text | J11: Text | K11: Text | L11: Text | M11: =A11 -> 4 | N11: =B11 -> Text | O11: =D11 -> Please select | P11: Text | Q11: Text | R11: Text | S11: Text | T11: Text | U11: Text
A12: 5 | B12: Text | C12: Text | D12: Please select | E12: Text | F12: Please select | G12: Please select | H12: Please select | I12: Text | J12: Text | K12: Text | L12: Text | M12: =A12 -> 5 | N12: =B12 -> Text | O12: =D12 -> Please select | P12: Text | Q12: Text | R12: Text | S12: Text | T12: Text | U12: Text
A13: 6 | B13: Text | C13: Text | D13: Please select | E13: Text | F13: Please select | G13: Please select | H13: Please select | I13: Text | J13: Text | K13: Text | L13: Text | M13: =A13 -> 6 | N13: =B13 -> Text | O13: =D13 -> Please select | P13: Text | Q13: Text | R13: Text | S13: Text | T13: Text | U13: Text
A14: 7 | B14: Text | C14: Text | D14: Please select | E14: Text | F14: Please select | G14: Please select | H14: Please select | I14: Text | J14: Text | K14: Text | L14: Text | M14: =A14 -> 7 | N14: =B14 -> Text | O14: =D14 -> Please select | P14: Text | Q14: Text | R14: Text | S14: Text | T14: Text | U14: Text
A15: 8 | B15: Text | C15: Text | D15: Please select | E15: Text | F15: Please select | G15: Please select | H15: Please select | I15: Text | J15: Text | K15: Text | L15: Text | M15: =A15 -> 8 | N15: =B15 -> Text | O15: =D15 -> Please select | P15: Text | Q15: Text | R15: Text | S15: Text | T15: Text | U15: Text
A16: 9 | B16: Text | C16: Text | D16: Please select | E16: Text | F16: Please select | G16: Please select | H16: Please select | I16: Text | J16: Text | K16: Text | L16: Text | M16: =A16 -> 9 | N16: =B16 -> Text | O16: =D16 -> Please select | P16: Text | Q16: Text | R16: Text | S16: Text | T16: Text | U16: Text
A17: 10 | B17: Text | C17: Text | D17: Please select | E17: Text | F17: Please select | G17: Please select | H17: Please select | I17: Text | J17: Text | K17: Text | L17: Text | M17: =A17 -> 10 | N17: =B17 -> Text | O17: =D17 -> Please select | P17: Text | Q17: Text | R17: Text | S17: Text | T17: Text | U17: Text
A18: 11 | B18: Text | C18: Text | D18: Please select | E18: Text | F18: Please select | G18: Please select | H18: Please select | I18: Text | J18: Text | K18: Text | L18: Text | M18: =A18 -> 11 | N18: =B18 -> Text | O18: =D18 -> Please select | P18: Text | Q18: Text | R18: Text | S18: Text | T18: Text | U18: Text
A19: 12 | B19: Text | C19: Text | D19: Please select | E19: Text | F19: Please select | G19: Please select | H19: Please select | I19: Text | J19: Text | K19: Text | L19: Text | M19: =A19 -> 12 | N19: =B19 -> Text | O19: =D19 -> Please select | P19: Text | Q19: Text | R19: Text | S19: Text | T19: Text | U19: Text
... A32: 25 | B32: Text | C32: Text | D32: Please select | E32: Text | F32: Please select | G32: Please select | H32: Please select | I32: Text | J32: Text | K32: Text | L32: Text | M32: =A32 -> 25 | N32: =B32 -> Text | O32: =D32 -> Please select | P32: Text | Q32: Text | R32: Text | S32: Text | T32: Text | U32: Text

Sheet Glossary
B1: ='0. Instruction'!B2:C2 -> IT-Security questionnaire for MAE - Instructions | C1: Glossary
A3: No. | B3: Short term / abbreviation: | C3: Description: | D3: Source:
A4: 1 | B4: AD | C4: Such a directory refers to an allocation map similar to, e.g., in a telephone directory, which allocates telephone numbers to the respective connections (owners). | D4: Wikipedia
A5: 2 | B5: Delivery state | C5: Condition of the component at the time of dispatch; condition at the time of delivery | D5: internal
A6: 3 | B6: IACS | C6: Automation Industrial Control System | D6: IEC 62443
A7: 4 | B7: IDS | C7: Intrusion Detection Systems | D7: internal
A8: 5 | B8: Internal machine network | C8: describes an IT-device, which only has the machine-internal network | D8: internal
A9: 6 | B9: Internal machine network and reachable from the Bosch network | C9: describes an IT-device, which has a machine-internal network and can be reached from the Bosch network | D9: internal
A10: 7 | B10: IPS | C10: Intrusion Protection Systems | D10: internal
A11: 8 | B11: IT-device IT-devices, which fulfil at least one of the following properties, should be inventoried: | C11: • An IP address has been allocated to the IT-device • The IT-device can be reached through a network • The IT-device processes data, which can be exchanged through an accessible data interface (e.g., Bluetooth, Ethernet, mobile mass storage such as USB-Stick, SD-Card or CD/DVD-drive, serial interface etc.). Examples: computers, controls, active display panels, cameras, robot controls, process controls, welding controls, power screwdrivers etc. | D11: internal
A12: 9 | B12: IT-Incident Management | C12: Typically includes the entire organizational and technical process of reacting to recognized or assumed security incidents and/or incidents in the IT area as well as measures and processes prepared for the same. Here, the spectrum of possible incidents spreads from technical problems and weak spots up to concrete attacks on the IT infrastructure. In the stricter sense, IT-Incident Management should also consider organizational as well as legal and technical technicalities. | D12: Wikipedia
A13: 10 | B13: LifeCycle (ALM) | C13: Application Lifecycle Management (ALM) is a combination of the development and support of applications (user software) through their entire lifecycle. This also includes a comprehensive user support and the further development of the software. | D13: Wikipedia
A14: 11 | B14: MAE | C14: Machines Installations and Equipment (Maschinen Anlagen und Einrichtungen) | D14: internal
A15: 12 | B15: Emergency planning | C15: The term Disaster Recovery (also called Katastrophenwiederherstellung or Notfallwiederherstellung in German) refers to measures, which are introduced in the information technology after a component has failed. This also includes data recovery as well as the replacement of infrastructure, hardware and organization that can no longer be used. The term Business Continuity is more inclusive. It does not refer to the recovery of IT-services, but brings uninterrupted business processes in the foreground. | D15: Wikipedia
... A39: 35 | B39: Normal operation | C39: describes the regular operation of an IT-device/MAE under usual load | D39: internal
B93: Drop Down:
B95: Network of the machine Column E, Part B | C95: Operating system | D95: Service Pack
B96: Please select | C96: Please select | D96: Please select
B97: internal machine network | C97: Firmware | D97: SP1
B98: internal machine network and reachable from the Bosch network | C98: Linux | D98: SP2 | E98: SL-C | F98: Divisions | G98: Plants
B99: reachable only from the Bosch network | C99: VX | D99: SP3 | E99: Please select | F99: Please select | G99: Please select
C100: Win95 | D100: SP4 | E100: SL-C 0 | F100: AA | G100: AdP
C101: WinCE | D101: SP5 | E101: SL-C 1 | F101: AE | G101: AfP
C102: WinNT | D102: SP6 | E102: SL-C 2 | F102: AS | G102: AguP
C103: WinXP | D103: SP7 | E103: SL-C 3 | F103: BSH | G103: AhmP
C104: WinVista | D104: SP8 | E104: SL-C 4 | F104: CC | G104: AiP
C105: Win7embeded | D105: SP9 | E105: n.a. | F105: CM | G105: Aj
C106: Win7 | D106: SP10 | F106: DC | G106: Alf
B107: Select yes;no - Main choice | C107: Win10embeded | D107: SP11 | F107: ED | G107: Alv
B108: Please select | C108: Win10 | D108: SP12 | F108: PS | G108: Ama
B109: yes | D109: SP13 | E109: Time server | F109: PT | G109: AmaP
B110: no | D110: SP14 | E110: Please select | F110: ST | G110: AmaP
D111: SP15 | E111: NTP | F111: TT | G111: Andr
B112: Communication type | D112: SP16 | E112: SNTP | F112: C | G112: AnP
B113: Please select | D113: SP17 | E113: n.a. | G113: AnP
B114: LAN | D114: SP18 | G114: ArP
B115: Wi-Fi | C115: Support - Period [Years] - Question 6.3 | D115: SP19 | G115: Atb
B116: Bluetooth | C116: Please select | D116: SP20 | E116: Frage 11.3 | G116: Atc
B117: NFC | C117: 0 | D117: SP21 | E117: Please select | G117: Auc
B118: 3G | C118: 1 | D118: SP22 | E118: yes | G118: Av
...

Sheet Version
B2: ='0. Instruction'!B2 -> IT-Security questionnaire for MAE - Instructions | C2: Version
B4: Status | C4: Version 1.0
B5: Date | C5: 41640
B6: Changes | C6: First version with basic pattern and evaluation
B7: Author | C7: PA-ATMO1/ITM Voeth
B8: Status | C8: Version 2.0
B9: Date | C9: 43556
B10: Changes | C10: second version for recording and for network planning; should be used during the project phases Purchase, Preliminary inspection, Network planning, Final inspection.
B11: Author | C11: C/TED1 Holtmannspötter
B12: Status
B13: Date
B14: Changes
B15: Author
B16: Status
B17: Date
B18: Changes
B19: Author
B20: Status
B21: Date
B22: Changes
B23: Author
... B27: Author
